package com.KMOD.HeavenGens;

import java.util.Random;

import net.minecraft.block.Block;
import net.minecraft.init.Blocks;
import net.minecraft.util.BlockPos;
import net.minecraft.world.World;
import net.minecraft.world.chunk.IChunkProvider;
import net.minecraft.world.gen.feature.WorldGenerator;
import net.minecraftforge.fml.common.IWorldGenerator;

import com.KMOD.Core.KCore;
import com.KMOD.Entities.EntityFireElemental;

public class GenFireDungeon extends WorldGenerator implements IWorldGenerator
{

	public GenFireDungeon() { }
	
	public World worldObj;
	
	public BlockPos Pos;

	@Override
	public void generate(Random random, int chunkX, int chunkZ, World world, IChunkProvider chunkGenerator, IChunkProvider chunkProvider) { }

	public void setBlock(World world, int x, int y, int z, Block block, int metadata)
	{
		world.setBlockState(new BlockPos(x, y, z),  block.getDefaultState());
	}
	
	@Override
	public boolean generate(World worldIn, Random p_180709_2_, BlockPos pos)
	{
		Pos = pos;
		worldObj = worldIn;
		this.generate(worldIn, p_180709_2_, pos.getX(), pos.getY(), pos.getZ());
		return true;
	}
	
	public boolean locationIsValidSpawn(World world, int i, int j, int k)
	{
		BlockPos pos = new BlockPos(i, j, k);
		
		return world.isAirBlock(pos);
	}

	public boolean generate(World world, Random rand, int i, int j, int k)
	{
		if(!locationIsValidSpawn(world, i, j, k) || !locationIsValidSpawn(world, i + 37, j, k) || !locationIsValidSpawn(world, i + 37, j, k + 27) || !locationIsValidSpawn(world, i, j, k + 27))
		{
			return false;
		}
		k = k - 10;
		i = i - 10;

		this.setBlock(world, i + 0, j + 0, k + 12, KCore.VolcanicBrick, 0);
		this.setBlock(world, i + 0, j + 0, k + 13, KCore.VolcanicRock, 0);
		this.setBlock(world, i + 0, j + 0, k + 14, KCore.VolcanicRock, 0);
		this.setBlock(world, i + 0, j + 0, k + 15, KCore.VolcanicBrick, 0);
		this.setBlock(world, i + 0, j + 1, k + 12, KCore.VolcanicBrick, 0);
		this.setBlock(world, i + 0, j + 1, k + 15, KCore.VolcanicBrick, 0);
		this.setBlock(world, i + 0, j + 2, k + 12, KCore.VolcanicBrick, 0);
		this.setBlock(world, i + 0, j + 2, k + 15, KCore.VolcanicBrick, 0);
		this.setBlock(world, i + 1, j + 0, k + 12, KCore.VolcanicBrick, 0);
		this.setBlock(world, i + 1, j + 0, k + 13, KCore.VolcanicRock, 0);
		this.setBlock(world, i + 1, j + 0, k + 14, KCore.VolcanicRock, 0);
		this.setBlock(world, i + 1, j + 0, k + 15, KCore.VolcanicBrick, 0);
		this.setBlock(world, i + 1, j + 1, k + 12, KCore.VolcanicBrick, 0);
		this.setBlock(world, i + 1, j + 1, k + 15, KCore.VolcanicBrick, 0);
		this.setBlock(world, i + 1, j + 2, k + 12, KCore.VolcanicBrick, 0);
		this.setBlock(world, i + 1, j + 2, k + 15, KCore.VolcanicBrick, 0);
		this.setBlock(world, i + 1, j + 3, k + 13, KCore.VolcanicBrick, 0);
		this.setBlock(world, i + 1, j + 3, k + 14, KCore.VolcanicBrick, 0);
		this.setBlock(world, i + 2, j + 0, k + 12, KCore.VolcanicBrick, 0);
		this.setBlock(world, i + 2, j + 0, k + 13, KCore.VolcanicRock, 0);
		this.setBlock(world, i + 2, j + 0, k + 14, KCore.VolcanicRock, 0);
		this.setBlock(world, i + 2, j + 0, k + 15, KCore.VolcanicBrick, 0);
		this.setBlock(world, i + 2, j + 1, k + 12, KCore.VolcanicBrick, 0);
		this.setBlock(world, i + 2, j + 1, k + 15, KCore.VolcanicBrick, 0);
		this.setBlock(world, i + 2, j + 2, k + 12, KCore.VolcanicBrick, 0);
		this.setBlock(world, i + 2, j + 2, k + 15, KCore.VolcanicBrick, 0);
		this.setBlock(world, i + 2, j + 3, k + 13, KCore.VolcanicBrick, 0);
		this.setBlock(world, i + 2, j + 3, k + 14, KCore.VolcanicBrick, 0);
		this.setBlock(world, i + 3, j + 0, k + 12, KCore.VolcanicBrick, 0);
		this.setBlock(world, i + 3, j + 0, k + 13, KCore.VolcanicRock, 0);
		this.setBlock(world, i + 3, j + 0, k + 14, KCore.VolcanicRock, 0);
		this.setBlock(world, i + 3, j + 0, k + 15, KCore.VolcanicBrick, 0);
		this.setBlock(world, i + 3, j + 1, k + 12, KCore.VolcanicBrick, 0);
		this.setBlock(world, i + 3, j + 1, k + 15, KCore.VolcanicBrick, 0);
		this.setBlock(world, i + 3, j + 2, k + 12, KCore.VolcanicBrick, 0);
		this.setBlock(world, i + 3, j + 2, k + 15, KCore.VolcanicBrick, 0);
		this.setBlock(world, i + 3, j + 3, k + 13, KCore.VolcanicBrick, 0);
		this.setBlock(world, i + 3, j + 3, k + 14, KCore.VolcanicBrick, 0);
		this.setBlock(world, i + 4, j + 0, k + 12, KCore.VolcanicBrick, 0);
		this.setBlock(world, i + 4, j + 0, k + 13, KCore.VolcanicRock, 0);
		this.setBlock(world, i + 4, j + 0, k + 14, KCore.VolcanicRock, 0);
		this.setBlock(world, i + 4, j + 0, k + 15, KCore.VolcanicBrick, 0);
		this.setBlock(world, i + 4, j + 1, k + 12, KCore.VolcanicBrick, 0);
		this.setBlock(world, i + 4, j + 1, k + 15, KCore.VolcanicBrick, 0);
		this.setBlock(world, i + 4, j + 2, k + 12, KCore.VolcanicBrick, 0);
		this.setBlock(world, i + 4, j + 2, k + 15, KCore.VolcanicBrick, 0);
		this.setBlock(world, i + 4, j + 3, k + 13, KCore.VolcanicBrick, 0);
		this.setBlock(world, i + 4, j + 3, k + 14, KCore.VolcanicBrick, 0);
		this.setBlock(world, i + 5, j + 0, k + 12, KCore.VolcanicBrick, 0);
		this.setBlock(world, i + 5, j + 0, k + 13, KCore.VolcanicRock, 0);
		this.setBlock(world, i + 5, j + 0, k + 14, KCore.VolcanicRock, 0);
		this.setBlock(world, i + 5, j + 0, k + 15, KCore.VolcanicBrick, 0);
		this.setBlock(world, i + 5, j + 1, k + 12, KCore.VolcanicBrick, 0);
		this.setBlock(world, i + 5, j + 1, k + 15, KCore.VolcanicBrick, 0);
		this.setBlock(world, i + 5, j + 2, k + 12, KCore.VolcanicBrick, 0);
		this.setBlock(world, i + 5, j + 2, k + 15, KCore.VolcanicBrick, 0);
		this.setBlock(world, i + 5, j + 3, k + 13, KCore.VolcanicBrick, 0);
		this.setBlock(world, i + 5, j + 3, k + 14, KCore.VolcanicBrick, 0);
		this.setBlock(world, i + 6, j + 0, k + 12, KCore.VolcanicBrick, 0);
		this.setBlock(world, i + 6, j + 0, k + 13, KCore.VolcanicRock, 0);
		this.setBlock(world, i + 6, j + 0, k + 14, KCore.VolcanicRock, 0);
		this.setBlock(world, i + 6, j + 0, k + 15, KCore.VolcanicBrick, 0);
		this.setBlock(world, i + 6, j + 1, k + 12, KCore.VolcanicBrick, 0);
		this.setBlock(world, i + 6, j + 1, k + 15, KCore.VolcanicBrick, 0);
		this.setBlock(world, i + 6, j + 2, k + 12, KCore.VolcanicBrick, 0);
		this.setBlock(world, i + 6, j + 2, k + 15, KCore.VolcanicBrick, 0);
		this.setBlock(world, i + 6, j + 3, k + 13, KCore.VolcanicBrick, 0);
		this.setBlock(world, i + 6, j + 3, k + 14, KCore.VolcanicBrick, 0);
		this.setBlock(world, i + 7, j + 0, k + 12, KCore.VolcanicBrick, 0);
		this.setBlock(world, i + 7, j + 0, k + 13, KCore.VolcanicRock, 0);
		this.setBlock(world, i + 7, j + 0, k + 14, KCore.VolcanicRock, 0);
		this.setBlock(world, i + 7, j + 0, k + 15, KCore.VolcanicBrick, 0);
		this.setBlock(world, i + 7, j + 1, k + 12, KCore.VolcanicBrick, 0);
		this.setBlock(world, i + 7, j + 1, k + 15, KCore.VolcanicBrick, 0);
		this.setBlock(world, i + 7, j + 2, k + 12, KCore.VolcanicBrick, 0);
		this.setBlock(world, i + 7, j + 2, k + 15, KCore.VolcanicBrick, 0);
		this.setBlock(world, i + 7, j + 3, k + 13, KCore.VolcanicBrick, 0);
		this.setBlock(world, i + 7, j + 3, k + 14, KCore.VolcanicBrick, 0);
		this.setBlock(world, i + 7, j + 4, k + 13, KCore.VolcanicBrick, 0);
		this.setBlock(world, i + 7, j + 4, k + 14, KCore.VolcanicBrick, 0);
		this.setBlock(world, i + 7, j + 5, k + 13, KCore.VolcanicBrick, 0);
		this.setBlock(world, i + 7, j + 5, k + 14, KCore.VolcanicBrick, 0);
		this.setBlock(world, i + 8, j + 0, k + 11, KCore.VolcanicBrick, 0);
		this.setBlock(world, i + 8, j + 0, k + 12, KCore.VolcanicRock, 0);
		this.setBlock(world, i + 8, j + 0, k + 13, KCore.VolcanicRock, 0);
		this.setBlock(world, i + 8, j + 0, k + 14, KCore.VolcanicRock, 0);
		this.setBlock(world, i + 8, j + 0, k + 15, KCore.VolcanicRock, 0);
		this.setBlock(world, i + 8, j + 0, k + 16, KCore.VolcanicBrick, 0);
		this.setBlock(world, i + 8, j + 1, k + 11, KCore.VolcanicBrick, 0);
		this.setBlock(world, i + 8, j + 1, k + 16, KCore.VolcanicBrick, 0);
		this.setBlock(world, i + 8, j + 2, k + 11, KCore.VolcanicBrick, 0);
		this.setBlock(world, i + 8, j + 2, k + 16, KCore.VolcanicBrick, 0);
		this.setBlock(world, i + 8, j + 3, k + 11, KCore.VolcanicBrick, 0);
		this.setBlock(world, i + 8, j + 3, k + 12, KCore.VolcanicBrick, 0);
		this.setBlock(world, i + 8, j + 3, k + 15, KCore.VolcanicBrick, 0);
		this.setBlock(world, i + 8, j + 4, k + 11, KCore.VolcanicBrick, 0);
		this.setBlock(world, i + 8, j + 4, k + 12, KCore.VolcanicBrick, 0);
		this.setBlock(world, i + 8, j + 4, k + 15, KCore.VolcanicBrick, 0);
		this.setBlock(world, i + 8, j + 5, k + 12, KCore.VolcanicBrick, 0);
		this.setBlock(world, i + 8, j + 5, k + 15, KCore.VolcanicBrick, 0);
		this.setBlock(world, i + 8, j + 6, k + 13, KCore.VolcanicBrick, 0);
		this.setBlock(world, i + 8, j + 6, k + 14, KCore.VolcanicBrick, 0);
		this.setBlock(world, i + 9, j + 0, k + 11, KCore.VolcanicBrick, 0);
		this.setBlock(world, i + 9, j + 0, k + 12, KCore.VolcanicRock, 0);
		this.setBlock(world, i + 9, j + 0, k + 13, KCore.VolcanicRock, 0);
		this.setBlock(world, i + 9, j + 0, k + 14, KCore.VolcanicRock, 0);
		this.setBlock(world, i + 9, j + 0, k + 15, KCore.VolcanicRock, 0);
		this.setBlock(world, i + 9, j + 0, k + 16, KCore.VolcanicBrick, 0);
		this.setBlock(world, i + 9, j + 1, k + 11, KCore.VolcanicBrick, 0);
		this.setBlock(world, i + 9, j + 1, k + 16, KCore.VolcanicBrick, 0);
		this.setBlock(world, i + 9, j + 2, k + 11, KCore.VolcanicBrick, 0);
		this.setBlock(world, i + 9, j + 2, k + 16, KCore.VolcanicBrick, 0);
		this.setBlock(world, i + 9, j + 3, k + 11, KCore.VolcanicBrick, 0);
		this.setBlock(world, i + 9, j + 3, k + 16, KCore.VolcanicBrick, 0);
		this.setBlock(world, i + 9, j + 4, k + 11, KCore.VolcanicBrick, 0);
		this.setBlock(world, i + 9, j + 4, k + 16, KCore.VolcanicBrick, 0);
		this.setBlock(world, i + 9, j + 5, k + 12, KCore.VolcanicBrick, 0);
		this.setBlock(world, i + 9, j + 5, k + 15, KCore.VolcanicBrick, 0);
		this.setBlock(world, i + 9, j + 6, k + 13, KCore.VolcanicBrick, 0);
		this.setBlock(world, i + 9, j + 6, k + 14, KCore.VolcanicBrick, 0);
		this.setBlock(world, i + 10, j + 0, k + 10, KCore.VolcanicBrick, 0);
		this.setBlock(world, i + 10, j + 0, k + 11, KCore.VolcanicRock, 0);
		this.setBlock(world, i + 10, j + 0, k + 12, KCore.VolcanicRock, 0);
		this.setBlock(world, i + 10, j + 0, k + 13, KCore.VolcanicRock, 0);
		this.setBlock(world, i + 10, j + 0, k + 14, KCore.VolcanicRock, 0);
		this.setBlock(world, i + 10, j + 0, k + 15, KCore.VolcanicRock, 0);
		this.setBlock(world, i + 10, j + 0, k + 16, KCore.VolcanicRock, 0);
		this.setBlock(world, i + 10, j + 0, k + 17, KCore.VolcanicBrick, 0);
		this.setBlock(world, i + 10, j + 1, k + 10, KCore.VolcanicBrick, 0);
		this.setBlock(world, i + 10, j + 1, k + 17, KCore.VolcanicBrick, 0);
		this.setBlock(world, i + 10, j + 2, k + 10, KCore.VolcanicBrick, 0);
		this.setBlock(world, i + 10, j + 2, k + 17, KCore.VolcanicBrick, 0);
		this.setBlock(world, i + 10, j + 3, k + 10, KCore.VolcanicBrick, 0);
		this.setBlock(world, i + 10, j + 3, k + 17, KCore.VolcanicBrick, 0);
		this.setBlock(world, i + 10, j + 4, k + 10, KCore.VolcanicBrick, 0);
		this.setBlock(world, i + 10, j + 4, k + 17, KCore.VolcanicBrick, 0);
		this.setBlock(world, i + 10, j + 5, k + 11, KCore.VolcanicBrick, 0);
		this.setBlock(world, i + 10, j + 5, k + 16, KCore.VolcanicBrick, 0);
		this.setBlock(world, i + 10, j + 6, k + 12, KCore.VolcanicBrick, 0);
		this.setBlock(world, i + 10, j + 6, k + 15, KCore.VolcanicBrick, 0);
		this.setBlock(world, i + 10, j + 7, k + 13, KCore.VolcanicBrick, 0);
		this.setBlock(world, i + 10, j + 7, k + 14, KCore.VolcanicBrick, 0);
		this.setBlock(world, i + 11, j + 0, k + 10, KCore.VolcanicBrick, 0);
		this.setBlock(world, i + 11, j + 0, k + 11, KCore.VolcanicRock, 0);
		this.setBlock(world, i + 11, j + 0, k + 12, KCore.VolcanicRock, 0);
		this.setBlock(world, i + 11, j + 0, k + 13, KCore.VolcanicRock, 0);
		this.setBlock(world, i + 11, j + 0, k + 14, KCore.VolcanicRock, 0);
		this.setBlock(world, i + 11, j + 0, k + 15, KCore.VolcanicRock, 0);
		this.setBlock(world, i + 11, j + 0, k + 16, KCore.VolcanicRock, 0);
		this.setBlock(world, i + 11, j + 0, k + 17, KCore.VolcanicBrick, 0);
		this.setBlock(world, i + 11, j + 1, k + 10, KCore.VolcanicBrick, 0);
		this.setBlock(world, i + 11, j + 1, k + 17, KCore.VolcanicBrick, 0);
		this.setBlock(world, i + 11, j + 2, k + 10, KCore.VolcanicBrick, 0);
		this.setBlock(world, i + 11, j + 2, k + 17, KCore.VolcanicBrick, 0);
		this.setBlock(world, i + 11, j + 3, k + 10, KCore.VolcanicBrick, 0);
		this.setBlock(world, i + 11, j + 3, k + 17, KCore.VolcanicBrick, 0);
		this.setBlock(world, i + 11, j + 4, k + 10, KCore.VolcanicBrick, 0);
		this.setBlock(world, i + 11, j + 4, k + 17, KCore.VolcanicBrick, 0);
		this.setBlock(world, i + 11, j + 5, k + 11, KCore.VolcanicBrick, 0);
		this.setBlock(world, i + 11, j + 5, k + 16, KCore.VolcanicBrick, 0);
		this.setBlock(world, i + 11, j + 6, k + 12, KCore.VolcanicBrick, 0);
		this.setBlock(world, i + 11, j + 6, k + 15, KCore.VolcanicBrick, 0);
		this.setBlock(world, i + 11, j + 7, k + 13, KCore.VolcanicBrick, 0);
		this.setBlock(world, i + 11, j + 7, k + 14, KCore.VolcanicBrick, 0);
		this.setBlock(world, i + 12, j + 0, k + 9, KCore.VolcanicBrick, 0);
		this.setBlock(world, i + 12, j + 0, k + 10, KCore.VolcanicRock, 0);
		this.setBlock(world, i + 12, j + 0, k + 11, KCore.VolcanicRock, 0);
		this.setBlock(world, i + 12, j + 0, k + 12, KCore.VolcanicRock, 0);
		this.setBlock(world, i + 12, j + 0, k + 13, KCore.VolcanicRock, 0);
		this.setBlock(world, i + 12, j + 0, k + 14, KCore.VolcanicRock, 0);
		this.setBlock(world, i + 12, j + 0, k + 15, KCore.VolcanicRock, 0);
		this.setBlock(world, i + 12, j + 0, k + 16, KCore.VolcanicRock, 0);
		this.setBlock(world, i + 12, j + 0, k + 17, KCore.VolcanicRock, 0);
		this.setBlock(world, i + 12, j + 0, k + 18, KCore.VolcanicBrick, 0);
		this.setBlock(world, i + 12, j + 1, k + 9, KCore.VolcanicBrick, 0);
		this.setBlock(world, i + 12, j + 1, k + 18, KCore.VolcanicBrick, 0);
		this.setBlock(world, i + 12, j + 2, k + 9, KCore.VolcanicBrick, 0);
		this.setBlock(world, i + 12, j + 2, k + 18, KCore.VolcanicBrick, 0);
		this.setBlock(world, i + 12, j + 3, k + 9, KCore.VolcanicBrick, 0);
		this.setBlock(world, i + 12, j + 3, k + 18, KCore.VolcanicBrick, 0);
		this.setBlock(world, i + 12, j + 4, k + 9, KCore.VolcanicBrick, 0);
		this.setBlock(world, i + 12, j + 4, k + 18, KCore.VolcanicBrick, 0);
		this.setBlock(world, i + 12, j + 5, k + 10, KCore.VolcanicBrick, 0);
		this.setBlock(world, i + 12, j + 5, k + 17, KCore.VolcanicBrick, 0);
		this.setBlock(world, i + 12, j + 6, k + 11, KCore.VolcanicBrick, 0);
		this.setBlock(world, i + 12, j + 6, k + 16, KCore.VolcanicBrick, 0);
		this.setBlock(world, i + 12, j + 7, k + 12, KCore.VolcanicBrick, 0);
		this.setBlock(world, i + 12, j + 7, k + 15, KCore.VolcanicBrick, 0);
		this.setBlock(world, i + 12, j + 8, k + 13, KCore.VolcanicBrick, 0);
		this.setBlock(world, i + 12, j + 8, k + 14, KCore.VolcanicBrick, 0);
		this.setBlock(world, i + 13, j + 0, k + 9, KCore.VolcanicBrick, 0);
		this.setBlock(world, i + 13, j + 0, k + 10, KCore.VolcanicRock, 0);
		this.setBlock(world, i + 13, j + 0, k + 11, KCore.VolcanicRock, 0);
		this.setBlock(world, i + 13, j + 0, k + 12, KCore.VolcanicRock, 0);
		this.setBlock(world, i + 13, j + 0, k + 13, KCore.VolcanicRock, 0);
		this.setBlock(world, i + 13, j + 0, k + 14, KCore.VolcanicRock, 0);
		this.setBlock(world, i + 13, j + 0, k + 15, KCore.VolcanicRock, 0);
		this.setBlock(world, i + 13, j + 0, k + 16, KCore.VolcanicRock, 0);
		this.setBlock(world, i + 13, j + 0, k + 17, KCore.VolcanicRock, 0);
		this.setBlock(world, i + 13, j + 0, k + 18, KCore.VolcanicBrick, 0);
		this.setBlock(world, i + 13, j + 1, k + 9, KCore.VolcanicBrick, 0);
		this.setBlock(world, i + 13, j + 1, k + 18, KCore.VolcanicBrick, 0);
		this.setBlock(world, i + 13, j + 2, k + 9, KCore.VolcanicBrick, 0);
		this.setBlock(world, i + 13, j + 2, k + 18, KCore.VolcanicBrick, 0);
		this.setBlock(world, i + 13, j + 3, k + 9, KCore.VolcanicBrick, 0);
		this.setBlock(world, i + 13, j + 3, k + 18, KCore.VolcanicBrick, 0);
		this.setBlock(world, i + 13, j + 4, k + 9, KCore.VolcanicBrick, 0);
		this.setBlock(world, i + 13, j + 4, k + 18, KCore.VolcanicBrick, 0);
		this.setBlock(world, i + 13, j + 5, k + 10, KCore.VolcanicBrick, 0);
		this.setBlock(world, i + 13, j + 5, k + 17, KCore.VolcanicBrick, 0);
		this.setBlock(world, i + 13, j + 6, k + 11, KCore.VolcanicBrick, 0);
		this.setBlock(world, i + 13, j + 6, k + 16, KCore.VolcanicBrick, 0);
		this.setBlock(world, i + 13, j + 7, k + 12, KCore.VolcanicBrick, 0);
		this.setBlock(world, i + 13, j + 7, k + 15, KCore.VolcanicBrick, 0);
		this.setBlock(world, i + 13, j + 8, k + 13, KCore.VolcanicBrick, 0);
		this.setBlock(world, i + 13, j + 8, k + 14, KCore.VolcanicBrick, 0);
		this.setBlock(world, i + 14, j + 0, k + 8, KCore.VolcanicBrick, 0);
		this.setBlock(world, i + 14, j + 0, k + 9, KCore.VolcanicRock, 0);
		this.setBlock(world, i + 14, j + 0, k + 10, KCore.VolcanicRock, 0);
		this.setBlock(world, i + 14, j + 0, k + 11, KCore.VolcanicRock, 0);
		this.setBlock(world, i + 14, j + 0, k + 12, KCore.VolcanicRock, 0);
		this.setBlock(world, i + 14, j + 0, k + 13, KCore.VolcanicRock, 0);
		this.setBlock(world, i + 14, j + 0, k + 14, KCore.VolcanicRock, 0);
		this.setBlock(world, i + 14, j + 0, k + 15, KCore.VolcanicRock, 0);
		this.setBlock(world, i + 14, j + 0, k + 16, KCore.VolcanicRock, 0);
		this.setBlock(world, i + 14, j + 0, k + 17, KCore.VolcanicRock, 0);
		this.setBlock(world, i + 14, j + 0, k + 18, KCore.VolcanicRock, 0);
		this.setBlock(world, i + 14, j + 0, k + 19, KCore.VolcanicBrick, 0);
		this.setBlock(world, i + 14, j + 1, k + 8, KCore.VolcanicBrick, 0);
		this.setBlock(world, i + 14, j + 1, k + 19, KCore.VolcanicBrick, 0);
		this.setBlock(world, i + 14, j + 2, k + 8, KCore.VolcanicBrick, 0);
		this.setBlock(world, i + 14, j + 2, k + 19, KCore.VolcanicBrick, 0);
		this.setBlock(world, i + 14, j + 3, k + 8, KCore.VolcanicBrick, 0);
		this.setBlock(world, i + 14, j + 3, k + 19, KCore.VolcanicBrick, 0);
		this.setBlock(world, i + 14, j + 4, k + 8, KCore.VolcanicBrick, 0);
		this.setBlock(world, i + 14, j + 4, k + 19, KCore.VolcanicBrick, 0);
		this.setBlock(world, i + 14, j + 5, k + 9, KCore.VolcanicBrick, 0);
		this.setBlock(world, i + 14, j + 5, k + 18, KCore.VolcanicBrick, 0);
		this.setBlock(world, i + 14, j + 6, k + 10, KCore.VolcanicBrick, 0);
		this.setBlock(world, i + 14, j + 6, k + 17, KCore.VolcanicBrick, 0);
		this.setBlock(world, i + 14, j + 7, k + 11, KCore.VolcanicBrick, 0);
		this.setBlock(world, i + 14, j + 7, k + 16, KCore.VolcanicBrick, 0);
		this.setBlock(world, i + 14, j + 8, k + 12, KCore.VolcanicBrick, 0);
		this.setBlock(world, i + 14, j + 8, k + 15, KCore.VolcanicBrick, 0);
		this.setBlock(world, i + 14, j + 9, k + 13, KCore.VolcanicBrick, 0);
		this.setBlock(world, i + 14, j + 9, k + 14, KCore.VolcanicBrick, 0);
		this.setBlock(world, i + 15, j + 0, k + 8, KCore.VolcanicBrick, 0);
		this.setBlock(world, i + 15, j + 0, k + 9, KCore.VolcanicRock, 0);
		this.setBlock(world, i + 15, j + 0, k + 10, KCore.VolcanicRock, 0);
		this.setBlock(world, i + 15, j + 0, k + 11, KCore.VolcanicRock, 0);
		this.setBlock(world, i + 15, j + 0, k + 12, KCore.VolcanicRock, 0);
		this.setBlock(world, i + 15, j + 0, k + 13, KCore.VolcanicRock, 0);
		this.setBlock(world, i + 15, j + 0, k + 14, KCore.VolcanicRock, 0);
		this.setBlock(world, i + 15, j + 0, k + 15, KCore.VolcanicRock, 0);
		this.setBlock(world, i + 15, j + 0, k + 16, KCore.VolcanicRock, 0);
		this.setBlock(world, i + 15, j + 0, k + 17, KCore.VolcanicRock, 0);
		this.setBlock(world, i + 15, j + 0, k + 18, KCore.VolcanicRock, 0);
		this.setBlock(world, i + 15, j + 0, k + 19, KCore.VolcanicBrick, 0);
		this.setBlock(world, i + 15, j + 1, k + 8, KCore.VolcanicBrick, 0);
		this.setBlock(world, i + 15, j + 1, k + 19, KCore.VolcanicBrick, 0);
		this.setBlock(world, i + 15, j + 2, k + 8, KCore.VolcanicBrick, 0);
		this.setBlock(world, i + 15, j + 2, k + 19, KCore.VolcanicBrick, 0);
		this.setBlock(world, i + 15, j + 3, k + 8, KCore.VolcanicBrick, 0);
		this.setBlock(world, i + 15, j + 3, k + 19, KCore.VolcanicBrick, 0);
		this.setBlock(world, i + 15, j + 4, k + 8, KCore.VolcanicBrick, 0);
		this.setBlock(world, i + 15, j + 4, k + 19, KCore.VolcanicBrick, 0);
		this.setBlock(world, i + 15, j + 5, k + 9, KCore.VolcanicBrick, 0);
		this.setBlock(world, i + 15, j + 5, k + 18, KCore.VolcanicBrick, 0);
		this.setBlock(world, i + 15, j + 6, k + 10, KCore.VolcanicBrick, 0);
		this.setBlock(world, i + 15, j + 6, k + 17, KCore.VolcanicBrick, 0);
		this.setBlock(world, i + 15, j + 7, k + 11, KCore.VolcanicBrick, 0);
		this.setBlock(world, i + 15, j + 7, k + 16, KCore.VolcanicBrick, 0);
		this.setBlock(world, i + 15, j + 8, k + 12, KCore.VolcanicBrick, 0);
		this.setBlock(world, i + 15, j + 8, k + 15, KCore.VolcanicBrick, 0);
		this.setBlock(world, i + 15, j + 9, k + 13, KCore.VolcanicBrick, 0);
		this.setBlock(world, i + 15, j + 9, k + 14, KCore.VolcanicBrick, 0);
		this.setBlock(world, i + 16, j + 0, k + 7, KCore.VolcanicBrick, 0);
		this.setBlock(world, i + 16, j + 0, k + 8, KCore.VolcanicRock, 0);
		this.setBlock(world, i + 16, j + 0, k + 9, KCore.VolcanicRock, 0);
		this.setBlock(world, i + 16, j + 0, k + 10, KCore.VolcanicRock, 0);
		this.setBlock(world, i + 16, j + 0, k + 11, KCore.VolcanicRock, 0);
		this.setBlock(world, i + 16, j + 0, k + 12, KCore.VolcanicRock, 0);
		this.setBlock(world, i + 16, j + 0, k + 13, KCore.VolcanicRock, 0);
		this.setBlock(world, i + 16, j + 0, k + 14, KCore.VolcanicRock, 0);
		this.setBlock(world, i + 16, j + 0, k + 15, KCore.VolcanicRock, 0);
		this.setBlock(world, i + 16, j + 0, k + 16, KCore.VolcanicRock, 0);
		this.setBlock(world, i + 16, j + 0, k + 17, KCore.VolcanicRock, 0);
		this.setBlock(world, i + 16, j + 0, k + 18, KCore.VolcanicRock, 0);
		this.setBlock(world, i + 16, j + 0, k + 19, KCore.VolcanicRock, 0);
		this.setBlock(world, i + 16, j + 0, k + 20, KCore.VolcanicBrick, 0);
		this.setBlock(world, i + 16, j + 1, k + 7, KCore.VolcanicBrick, 0);
		this.setBlock(world, i + 16, j + 1, k + 20, KCore.VolcanicBrick, 0);
		this.setBlock(world, i + 16, j + 2, k + 7, KCore.VolcanicBrick, 0);
		this.setBlock(world, i + 16, j + 2, k + 20, KCore.VolcanicBrick, 0);
		this.setBlock(world, i + 16, j + 3, k + 7, KCore.VolcanicBrick, 0);
		this.setBlock(world, i + 16, j + 3, k + 20, KCore.VolcanicBrick, 0);
		this.setBlock(world, i + 16, j + 4, k + 7, KCore.VolcanicBrick, 0);
		this.setBlock(world, i + 16, j + 4, k + 20, KCore.VolcanicBrick, 0);
		this.setBlock(world, i + 16, j + 5, k + 8, KCore.VolcanicBrick, 0);
		this.setBlock(world, i + 16, j + 5, k + 19, KCore.VolcanicBrick, 0);
		this.setBlock(world, i + 16, j + 6, k + 9, KCore.VolcanicBrick, 0);
		this.setBlock(world, i + 16, j + 6, k + 18, KCore.VolcanicBrick, 0);
		this.setBlock(world, i + 16, j + 7, k + 10, KCore.VolcanicBrick, 0);
		this.setBlock(world, i + 16, j + 7, k + 17, KCore.VolcanicBrick, 0);
		this.setBlock(world, i + 16, j + 8, k + 11, KCore.VolcanicBrick, 0);
		this.setBlock(world, i + 16, j + 8, k + 16, KCore.VolcanicBrick, 0);
		this.setBlock(world, i + 16, j + 9, k + 12, KCore.VolcanicBrick, 0);
		this.setBlock(world, i + 16, j + 9, k + 15, KCore.VolcanicBrick, 0);
		this.setBlock(world, i + 16, j + 10, k + 13, KCore.VolcanicBrick, 0);
		this.setBlock(world, i + 16, j + 10, k + 14, KCore.VolcanicBrick, 0);
		this.setBlock(world, i + 17, j + 0, k + 0, KCore.VolcanicBrick, 0);
		this.setBlock(world, i + 17, j + 0, k + 1, KCore.VolcanicBrick, 0);
		this.setBlock(world, i + 17, j + 0, k + 2, KCore.VolcanicBrick, 0);
		this.setBlock(world, i + 17, j + 0, k + 3, KCore.VolcanicBrick, 0);
		this.setBlock(world, i + 17, j + 0, k + 4, KCore.VolcanicBrick, 0);
		this.setBlock(world, i + 17, j + 0, k + 5, KCore.VolcanicBrick, 0);
		this.setBlock(world, i + 17, j + 0, k + 6, KCore.VolcanicBrick, 0);
		this.setBlock(world, i + 17, j + 0, k + 7, KCore.VolcanicBrick, 0);
		this.setBlock(world, i + 17, j + 0, k + 8, KCore.VolcanicRock, 0);
		this.setBlock(world, i + 17, j + 0, k + 9, KCore.VolcanicRock, 0);
		this.setBlock(world, i + 17, j + 0, k + 10, KCore.VolcanicRock, 0);
		this.setBlock(world, i + 17, j + 0, k + 11, KCore.VolcanicRock, 0);
		this.setBlock(world, i + 17, j + 0, k + 12, KCore.VolcanicRock, 0);
		this.setBlock(world, i + 17, j + 0, k + 13, KCore.VolcanicRock, 0);
		this.setBlock(world, i + 17, j + 0, k + 14, KCore.VolcanicRock, 0);
		this.setBlock(world, i + 17, j + 0, k + 15, KCore.VolcanicRock, 0);
		this.setBlock(world, i + 17, j + 0, k + 16, KCore.VolcanicRock, 0);
		this.setBlock(world, i + 17, j + 0, k + 17, KCore.VolcanicRock, 0);
		this.setBlock(world, i + 17, j + 0, k + 18, KCore.VolcanicRock, 0);
		this.setBlock(world, i + 17, j + 0, k + 19, KCore.VolcanicRock, 0);
		this.setBlock(world, i + 17, j + 0, k + 20, KCore.VolcanicBrick, 0);
		this.setBlock(world, i + 17, j + 0, k + 21, KCore.VolcanicBrick, 0);
		this.setBlock(world, i + 17, j + 0, k + 22, KCore.VolcanicBrick, 0);
		this.setBlock(world, i + 17, j + 0, k + 23, KCore.VolcanicBrick, 0);
		this.setBlock(world, i + 17, j + 0, k + 24, KCore.VolcanicBrick, 0);
		this.setBlock(world, i + 17, j + 0, k + 25, KCore.VolcanicBrick, 0);
		this.setBlock(world, i + 17, j + 0, k + 26, KCore.VolcanicBrick, 0);
		this.setBlock(world, i + 17, j + 0, k + 27, KCore.VolcanicBrick, 0);
		this.setBlock(world, i + 17, j + 1, k + 0, KCore.VolcanicBrick, 0);
		this.setBlock(world, i + 17, j + 1, k + 1, KCore.VolcanicBrick, 0);
		this.setBlock(world, i + 17, j + 1, k + 2, KCore.VolcanicBrick, 0);
		this.setBlock(world, i + 17, j + 1, k + 3, KCore.VolcanicBrick, 0);
		this.setBlock(world, i + 17, j + 1, k + 4, KCore.VolcanicBrick, 0);
		this.setBlock(world, i + 17, j + 1, k + 5, KCore.VolcanicBrick, 0);
		this.setBlock(world, i + 17, j + 1, k + 6, KCore.VolcanicBrick, 0);
		this.setBlock(world, i + 17, j + 1, k + 7, KCore.VolcanicBrick, 0);
		this.setBlock(world, i + 17, j + 1, k + 20, KCore.VolcanicBrick, 0);
		this.setBlock(world, i + 17, j + 1, k + 21, KCore.VolcanicBrick, 0);
		this.setBlock(world, i + 17, j + 1, k + 22, KCore.VolcanicBrick, 0);
		this.setBlock(world, i + 17, j + 1, k + 23, KCore.VolcanicBrick, 0);
		this.setBlock(world, i + 17, j + 1, k + 24, KCore.VolcanicBrick, 0);
		this.setBlock(world, i + 17, j + 1, k + 25, KCore.VolcanicBrick, 0);
		this.setBlock(world, i + 17, j + 1, k + 26, KCore.VolcanicBrick, 0);
		this.setBlock(world, i + 17, j + 1, k + 27, KCore.VolcanicBrick, 0);
		this.setBlock(world, i + 17, j + 2, k + 0, KCore.VolcanicBrick, 0);
		this.setBlock(world, i + 17, j + 2, k + 1, KCore.VolcanicBrick, 0);
		this.setBlock(world, i + 17, j + 2, k + 2, KCore.VolcanicBrick, 0);
		this.setBlock(world, i + 17, j + 2, k + 3, KCore.VolcanicBrick, 0);
		this.setBlock(world, i + 17, j + 2, k + 4, KCore.VolcanicBrick, 0);
		this.setBlock(world, i + 17, j + 2, k + 5, KCore.VolcanicBrick, 0);
		this.setBlock(world, i + 17, j + 2, k + 6, KCore.VolcanicBrick, 0);
		this.setBlock(world, i + 17, j + 2, k + 7, KCore.VolcanicBrick, 0);
		this.setBlock(world, i + 17, j + 2, k + 20, KCore.VolcanicBrick, 0);
		this.setBlock(world, i + 17, j + 2, k + 21, KCore.VolcanicBrick, 0);
		this.setBlock(world, i + 17, j + 2, k + 22, KCore.VolcanicBrick, 0);
		this.setBlock(world, i + 17, j + 2, k + 23, KCore.VolcanicBrick, 0);
		this.setBlock(world, i + 17, j + 2, k + 24, KCore.VolcanicBrick, 0);
		this.setBlock(world, i + 17, j + 2, k + 25, KCore.VolcanicBrick, 0);
		this.setBlock(world, i + 17, j + 2, k + 26, KCore.VolcanicBrick, 0);
		this.setBlock(world, i + 17, j + 2, k + 27, KCore.VolcanicBrick, 0);
		this.setBlock(world, i + 17, j + 3, k + 7, KCore.VolcanicBrick, 0);
		this.setBlock(world, i + 17, j + 3, k + 20, KCore.VolcanicBrick, 0);
		this.setBlock(world, i + 17, j + 4, k + 7, KCore.VolcanicBrick, 0);
		this.setBlock(world, i + 17, j + 4, k + 20, KCore.VolcanicBrick, 0);
		this.setBlock(world, i + 17, j + 5, k + 8, KCore.VolcanicBrick, 0);
		this.setBlock(world, i + 17, j + 5, k + 19, KCore.VolcanicBrick, 0);
		this.setBlock(world, i + 17, j + 6, k + 9, KCore.VolcanicBrick, 0);
		this.setBlock(world, i + 17, j + 6, k + 18, KCore.VolcanicBrick, 0);
		this.setBlock(world, i + 17, j + 7, k + 10, KCore.VolcanicBrick, 0);
		this.setBlock(world, i + 17, j + 7, k + 17, KCore.VolcanicBrick, 0);
		this.setBlock(world, i + 17, j + 8, k + 11, KCore.VolcanicBrick, 0);
		this.setBlock(world, i + 17, j + 8, k + 16, KCore.VolcanicBrick, 0);
		this.setBlock(world, i + 17, j + 9, k + 12, KCore.VolcanicBrick, 0);
		this.setBlock(world, i + 17, j + 9, k + 15, KCore.VolcanicBrick, 0);
		this.setBlock(world, i + 17, j + 10, k + 13, KCore.VolcanicBrick, 0);
		this.setBlock(world, i + 17, j + 10, k + 14, KCore.VolcanicBrick, 0);
		this.setBlock(world, i + 18, j + 0, k + 0, KCore.VolcanicRock, 0);
		this.setBlock(world, i + 18, j + 0, k + 1, KCore.VolcanicRock, 0);
		this.setBlock(world, i + 18, j + 0, k + 2, KCore.VolcanicRock, 0);
		this.setBlock(world, i + 18, j + 0, k + 3, KCore.VolcanicRock, 0);
		this.setBlock(world, i + 18, j + 0, k + 4, KCore.VolcanicRock, 0);
		this.setBlock(world, i + 18, j + 0, k + 5, KCore.VolcanicRock, 0);
		this.setBlock(world, i + 18, j + 0, k + 6, KCore.VolcanicRock, 0);
		this.setBlock(world, i + 18, j + 0, k + 7, KCore.VolcanicRock, 0);
		this.setBlock(world, i + 18, j + 0, k + 8, KCore.VolcanicRock, 0);
		this.setBlock(world, i + 18, j + 0, k + 9, KCore.VolcanicRock, 0);
		this.setBlock(world, i + 18, j + 0, k + 10, KCore.VolcanicRock, 0);
		this.setBlock(world, i + 18, j + 0, k + 11, KCore.VolcanicRock, 0);
		this.setBlock(world, i + 18, j + 0, k + 12, KCore.VolcanicRock, 0);
		this.setBlock(world, i + 18, j + 0, k + 13, KCore.VolcanicRock, 0);
		this.setBlock(world, i + 18, j + 0, k + 14, KCore.VolcanicRock, 0);
		this.setBlock(world, i + 18, j + 0, k + 15, KCore.VolcanicRock, 0);
		this.setBlock(world, i + 18, j + 0, k + 16, KCore.VolcanicRock, 0);
		this.setBlock(world, i + 18, j + 0, k + 17, KCore.VolcanicRock, 0);
		this.setBlock(world, i + 18, j + 0, k + 18, KCore.VolcanicRock, 0);
		this.setBlock(world, i + 18, j + 0, k + 19, KCore.VolcanicRock, 0);
		this.setBlock(world, i + 18, j + 0, k + 20, KCore.VolcanicRock, 0);
		this.setBlock(world, i + 18, j + 0, k + 21, KCore.VolcanicRock, 0);
		this.setBlock(world, i + 18, j + 0, k + 22, KCore.VolcanicRock, 0);
		this.setBlock(world, i + 18, j + 0, k + 23, KCore.VolcanicRock, 0);
		this.setBlock(world, i + 18, j + 0, k + 24, KCore.VolcanicRock, 0);
		this.setBlock(world, i + 18, j + 0, k + 25, KCore.VolcanicRock, 0);
		this.setBlock(world, i + 18, j + 0, k + 26, KCore.VolcanicRock, 0);
		this.setBlock(world, i + 18, j + 0, k + 27, KCore.VolcanicRock, 0);

		this.setBlock(world, i + 18, j + 3, k + 1, KCore.VolcanicBrick, 0);
		this.setBlock(world, i + 18, j + 3, k + 2, KCore.VolcanicBrick, 0);
		this.setBlock(world, i + 18, j + 3, k + 3, KCore.VolcanicBrick, 0);
		this.setBlock(world, i + 18, j + 3, k + 4, KCore.VolcanicBrick, 0);
		this.setBlock(world, i + 18, j + 3, k + 5, KCore.VolcanicBrick, 0);
		this.setBlock(world, i + 18, j + 3, k + 6, KCore.VolcanicBrick, 0);
		this.setBlock(world, i + 18, j + 3, k + 7, KCore.VolcanicBrick, 0);
		this.setBlock(world, i + 18, j + 3, k + 20, KCore.VolcanicBrick, 0);
		this.setBlock(world, i + 18, j + 3, k + 21, KCore.VolcanicBrick, 0);
		this.setBlock(world, i + 18, j + 3, k + 22, KCore.VolcanicBrick, 0);
		this.setBlock(world, i + 18, j + 3, k + 23, KCore.VolcanicBrick, 0);
		this.setBlock(world, i + 18, j + 3, k + 24, KCore.VolcanicBrick, 0);
		this.setBlock(world, i + 18, j + 3, k + 25, KCore.VolcanicBrick, 0);
		this.setBlock(world, i + 18, j + 3, k + 26, KCore.VolcanicBrick, 0);
		this.setBlock(world, i + 18, j + 4, k + 7, KCore.VolcanicBrick, 0);
		this.setBlock(world, i + 18, j + 4, k + 20, KCore.VolcanicBrick, 0);
		this.setBlock(world, i + 18, j + 5, k + 8, KCore.VolcanicBrick, 0);
		this.setBlock(world, i + 18, j + 5, k + 19, KCore.VolcanicBrick, 0);
		this.setBlock(world, i + 18, j + 6, k + 9, KCore.VolcanicBrick, 0);
		this.setBlock(world, i + 18, j + 6, k + 18, KCore.VolcanicBrick, 0);
		this.setBlock(world, i + 18, j + 7, k + 10, KCore.VolcanicBrick, 0);
		this.setBlock(world, i + 18, j + 7, k + 17, KCore.VolcanicBrick, 0);
		this.setBlock(world, i + 18, j + 8, k + 11, KCore.VolcanicBrick, 0);
		this.setBlock(world, i + 18, j + 8, k + 16, KCore.VolcanicBrick, 0);
		this.setBlock(world, i + 18, j + 9, k + 12, KCore.VolcanicBrick, 0);
		this.setBlock(world, i + 18, j + 9, k + 15, KCore.VolcanicBrick, 0);
		this.setBlock(world, i + 18, j + 10, k + 13, KCore.VolcanicBrick, 0);
		this.setBlock(world, i + 18, j + 10, k + 14, KCore.VolcanicBrick, 0);
		this.setBlock(world, i + 19, j + 0, k + 0, KCore.VolcanicRock, 0);
		this.setBlock(world, i + 19, j + 0, k + 1, KCore.VolcanicRock, 0);
		this.setBlock(world, i + 19, j + 0, k + 2, KCore.VolcanicRock, 0);
		this.setBlock(world, i + 19, j + 0, k + 3, KCore.VolcanicRock, 0);
		this.setBlock(world, i + 19, j + 0, k + 4, KCore.VolcanicRock, 0);
		this.setBlock(world, i + 19, j + 0, k + 5, KCore.VolcanicRock, 0);
		this.setBlock(world, i + 19, j + 0, k + 6, KCore.VolcanicRock, 0);
		this.setBlock(world, i + 19, j + 0, k + 7, KCore.VolcanicRock, 0);
		this.setBlock(world, i + 19, j + 0, k + 8, KCore.VolcanicRock, 0);
		this.setBlock(world, i + 19, j + 0, k + 9, KCore.VolcanicRock, 0);
		this.setBlock(world, i + 19, j + 0, k + 10, KCore.VolcanicRock, 0);
		this.setBlock(world, i + 19, j + 0, k + 11, KCore.VolcanicRock, 0);
		this.setBlock(world, i + 19, j + 0, k + 12, KCore.VolcanicRock, 0);
		this.setBlock(world, i + 19, j + 0, k + 13, KCore.VolcanicRock, 0);
		this.setBlock(world, i + 19, j + 0, k + 14, KCore.VolcanicRock, 0);
		this.setBlock(world, i + 19, j + 0, k + 15, KCore.VolcanicRock, 0);
		this.setBlock(world, i + 19, j + 0, k + 16, KCore.VolcanicRock, 0);
		this.setBlock(world, i + 19, j + 0, k + 17, KCore.VolcanicRock, 0);
		this.setBlock(world, i + 19, j + 0, k + 18, KCore.VolcanicRock, 0);
		this.setBlock(world, i + 19, j + 0, k + 19, KCore.VolcanicRock, 0);
		this.setBlock(world, i + 19, j + 0, k + 20, KCore.VolcanicRock, 0);
		this.setBlock(world, i + 19, j + 0, k + 21, KCore.VolcanicRock, 0);
		this.setBlock(world, i + 19, j + 0, k + 22, KCore.VolcanicRock, 0);
		this.setBlock(world, i + 19, j + 0, k + 23, KCore.VolcanicRock, 0);
		this.setBlock(world, i + 19, j + 0, k + 24, KCore.VolcanicRock, 0);
		this.setBlock(world, i + 19, j + 0, k + 25, KCore.VolcanicRock, 0);
		this.setBlock(world, i + 19, j + 0, k + 26, KCore.VolcanicRock, 0);
		this.setBlock(world, i + 19, j + 0, k + 27, KCore.VolcanicRock, 0);

		this.setBlock(world, i + 19, j + 3, k + 1, KCore.VolcanicBrick, 0);
		this.setBlock(world, i + 19, j + 3, k + 2, KCore.VolcanicBrick, 0);
		this.setBlock(world, i + 19, j + 3, k + 3, KCore.VolcanicBrick, 0);
		this.setBlock(world, i + 19, j + 3, k + 4, KCore.VolcanicBrick, 0);
		this.setBlock(world, i + 19, j + 3, k + 5, KCore.VolcanicBrick, 0);
		this.setBlock(world, i + 19, j + 3, k + 6, KCore.VolcanicBrick, 0);
		this.setBlock(world, i + 19, j + 3, k + 7, KCore.VolcanicBrick, 0);
		this.setBlock(world, i + 19, j + 3, k + 20, KCore.VolcanicBrick, 0);
		this.setBlock(world, i + 19, j + 3, k + 21, KCore.VolcanicBrick, 0);
		this.setBlock(world, i + 19, j + 3, k + 22, KCore.VolcanicBrick, 0);
		this.setBlock(world, i + 19, j + 3, k + 23, KCore.VolcanicBrick, 0);
		this.setBlock(world, i + 19, j + 3, k + 24, KCore.VolcanicBrick, 0);
		this.setBlock(world, i + 19, j + 3, k + 25, KCore.VolcanicBrick, 0);
		this.setBlock(world, i + 19, j + 3, k + 26, KCore.VolcanicBrick, 0);
		this.setBlock(world, i + 19, j + 4, k + 7, KCore.VolcanicBrick, 0);
		this.setBlock(world, i + 19, j + 4, k + 20, KCore.VolcanicBrick, 0);
		this.setBlock(world, i + 19, j + 5, k + 8, KCore.VolcanicBrick, 0);
		this.setBlock(world, i + 19, j + 5, k + 19, KCore.VolcanicBrick, 0);
		this.setBlock(world, i + 19, j + 6, k + 9, KCore.VolcanicBrick, 0);
		this.setBlock(world, i + 19, j + 6, k + 18, KCore.VolcanicBrick, 0);
		this.setBlock(world, i + 19, j + 7, k + 10, KCore.VolcanicBrick, 0);
		this.setBlock(world, i + 19, j + 7, k + 17, KCore.VolcanicBrick, 0);
		this.setBlock(world, i + 19, j + 8, k + 11, KCore.VolcanicBrick, 0);
		this.setBlock(world, i + 19, j + 8, k + 16, KCore.VolcanicBrick, 0);
		this.setBlock(world, i + 19, j + 9, k + 12, KCore.VolcanicBrick, 0);
		this.setBlock(world, i + 19, j + 9, k + 15, KCore.VolcanicBrick, 0);
		this.setBlock(world, i + 19, j + 10, k + 13, KCore.VolcanicBrick, 0);
		this.setBlock(world, i + 19, j + 10, k + 14, KCore.VolcanicBrick, 0);
		this.setBlock(world, i + 20, j + 0, k + 0, KCore.VolcanicBrick, 0);
		this.setBlock(world, i + 20, j + 0, k + 1, KCore.VolcanicBrick, 0);
		this.setBlock(world, i + 20, j + 0, k + 2, KCore.VolcanicBrick, 0);
		this.setBlock(world, i + 20, j + 0, k + 3, KCore.VolcanicBrick, 0);
		this.setBlock(world, i + 20, j + 0, k + 4, KCore.VolcanicBrick, 0);
		this.setBlock(world, i + 20, j + 0, k + 5, KCore.VolcanicBrick, 0);
		this.setBlock(world, i + 20, j + 0, k + 6, KCore.VolcanicBrick, 0);
		this.setBlock(world, i + 20, j + 0, k + 7, KCore.VolcanicBrick, 0);
		this.setBlock(world, i + 20, j + 0, k + 8, KCore.VolcanicRock, 0);
		this.setBlock(world, i + 20, j + 0, k + 9, KCore.VolcanicRock, 0);
		this.setBlock(world, i + 20, j + 0, k + 10, KCore.VolcanicRock, 0);
		this.setBlock(world, i + 20, j + 0, k + 11, KCore.VolcanicRock, 0);
		this.setBlock(world, i + 20, j + 0, k + 12, KCore.VolcanicRock, 0);
		this.setBlock(world, i + 20, j + 0, k + 13, KCore.VolcanicRock, 0);
		this.setBlock(world, i + 20, j + 0, k + 14, KCore.VolcanicRock, 0);
		this.setBlock(world, i + 20, j + 0, k + 15, KCore.VolcanicRock, 0);
		this.setBlock(world, i + 20, j + 0, k + 16, KCore.VolcanicRock, 0);
		this.setBlock(world, i + 20, j + 0, k + 17, KCore.VolcanicRock, 0);
		this.setBlock(world, i + 20, j + 0, k + 18, KCore.VolcanicRock, 0);
		this.setBlock(world, i + 20, j + 0, k + 19, KCore.VolcanicRock, 0);
		this.setBlock(world, i + 20, j + 0, k + 20, KCore.VolcanicBrick, 0);
		this.setBlock(world, i + 20, j + 0, k + 21, KCore.VolcanicBrick, 0);
		this.setBlock(world, i + 20, j + 0, k + 22, KCore.VolcanicBrick, 0);
		this.setBlock(world, i + 20, j + 0, k + 23, KCore.VolcanicBrick, 0);
		this.setBlock(world, i + 20, j + 0, k + 24, KCore.VolcanicBrick, 0);
		this.setBlock(world, i + 20, j + 0, k + 25, KCore.VolcanicBrick, 0);
		this.setBlock(world, i + 20, j + 0, k + 26, KCore.VolcanicBrick, 0);
		this.setBlock(world, i + 20, j + 0, k + 27, KCore.VolcanicBrick, 0);
		this.setBlock(world, i + 20, j + 1, k + 0, KCore.VolcanicBrick, 0);
		this.setBlock(world, i + 20, j + 1, k + 1, KCore.VolcanicBrick, 0);
		this.setBlock(world, i + 20, j + 1, k + 2, KCore.VolcanicBrick, 0);
		this.setBlock(world, i + 20, j + 1, k + 3, KCore.VolcanicBrick, 0);
		this.setBlock(world, i + 20, j + 1, k + 4, KCore.VolcanicBrick, 0);
		this.setBlock(world, i + 20, j + 1, k + 5, KCore.VolcanicBrick, 0);
		this.setBlock(world, i + 20, j + 1, k + 6, KCore.VolcanicBrick, 0);
		this.setBlock(world, i + 20, j + 1, k + 7, KCore.VolcanicBrick, 0);
		this.setBlock(world, i + 20, j + 1, k + 20, KCore.VolcanicBrick, 0);
		this.setBlock(world, i + 20, j + 1, k + 21, KCore.VolcanicBrick, 0);
		this.setBlock(world, i + 20, j + 1, k + 22, KCore.VolcanicBrick, 0);
		this.setBlock(world, i + 20, j + 1, k + 23, KCore.VolcanicBrick, 0);
		this.setBlock(world, i + 20, j + 1, k + 24, KCore.VolcanicBrick, 0);
		this.setBlock(world, i + 20, j + 1, k + 25, KCore.VolcanicBrick, 0);
		this.setBlock(world, i + 20, j + 1, k + 26, KCore.VolcanicBrick, 0);
		this.setBlock(world, i + 20, j + 1, k + 27, KCore.VolcanicBrick, 0);
		this.setBlock(world, i + 20, j + 2, k + 0, KCore.VolcanicBrick, 0);
		this.setBlock(world, i + 20, j + 2, k + 1, KCore.VolcanicBrick, 0);
		this.setBlock(world, i + 20, j + 2, k + 2, KCore.VolcanicBrick, 0);
		this.setBlock(world, i + 20, j + 2, k + 3, KCore.VolcanicBrick, 0);
		this.setBlock(world, i + 20, j + 2, k + 4, KCore.VolcanicBrick, 0);
		this.setBlock(world, i + 20, j + 2, k + 5, KCore.VolcanicBrick, 0);
		this.setBlock(world, i + 20, j + 2, k + 6, KCore.VolcanicBrick, 0);
		this.setBlock(world, i + 20, j + 2, k + 7, KCore.VolcanicBrick, 0);
		this.setBlock(world, i + 20, j + 2, k + 20, KCore.VolcanicBrick, 0);
		this.setBlock(world, i + 20, j + 2, k + 21, KCore.VolcanicBrick, 0);
		this.setBlock(world, i + 20, j + 2, k + 22, KCore.VolcanicBrick, 0);
		this.setBlock(world, i + 20, j + 2, k + 23, KCore.VolcanicBrick, 0);
		this.setBlock(world, i + 20, j + 2, k + 24, KCore.VolcanicBrick, 0);
		this.setBlock(world, i + 20, j + 2, k + 25, KCore.VolcanicBrick, 0);
		this.setBlock(world, i + 20, j + 2, k + 26, KCore.VolcanicBrick, 0);
		this.setBlock(world, i + 20, j + 2, k + 27, KCore.VolcanicBrick, 0);
		this.setBlock(world, i + 20, j + 3, k + 7, KCore.VolcanicBrick, 0);
		this.setBlock(world, i + 20, j + 3, k + 20, KCore.VolcanicBrick, 0);
		this.setBlock(world, i + 20, j + 4, k + 7, KCore.VolcanicBrick, 0);
		this.setBlock(world, i + 20, j + 4, k + 20, KCore.VolcanicBrick, 0);
		this.setBlock(world, i + 20, j + 5, k + 8, KCore.VolcanicBrick, 0);
		this.setBlock(world, i + 20, j + 5, k + 19, KCore.VolcanicBrick, 0);
		this.setBlock(world, i + 20, j + 6, k + 9, KCore.VolcanicBrick, 0);
		this.setBlock(world, i + 20, j + 6, k + 18, KCore.VolcanicBrick, 0);
		this.setBlock(world, i + 20, j + 7, k + 10, KCore.VolcanicBrick, 0);
		this.setBlock(world, i + 20, j + 7, k + 17, KCore.VolcanicBrick, 0);
		this.setBlock(world, i + 20, j + 8, k + 11, KCore.VolcanicBrick, 0);
		this.setBlock(world, i + 20, j + 8, k + 16, KCore.VolcanicBrick, 0);
		this.setBlock(world, i + 20, j + 9, k + 12, KCore.VolcanicBrick, 0);
		this.setBlock(world, i + 20, j + 9, k + 15, KCore.VolcanicBrick, 0);
		this.setBlock(world, i + 20, j + 10, k + 13, KCore.VolcanicBrick, 0);
		this.setBlock(world, i + 20, j + 10, k + 14, KCore.VolcanicBrick, 0);
		this.setBlock(world, i + 21, j + 0, k + 7, KCore.VolcanicBrick, 0);
		this.setBlock(world, i + 21, j + 0, k + 8, KCore.VolcanicRock, 0);
		this.setBlock(world, i + 21, j + 0, k + 9, KCore.VolcanicRock, 0);
		this.setBlock(world, i + 21, j + 0, k + 10, KCore.VolcanicRock, 0);
		this.setBlock(world, i + 21, j + 0, k + 11, KCore.VolcanicRock, 0);
		this.setBlock(world, i + 21, j + 0, k + 12, KCore.VolcanicRock, 0);
		this.setBlock(world, i + 21, j + 0, k + 13, KCore.VolcanicRock, 0);
		this.setBlock(world, i + 21, j + 0, k + 14, KCore.VolcanicRock, 0);
		this.setBlock(world, i + 21, j + 0, k + 15, KCore.VolcanicRock, 0);
		this.setBlock(world, i + 21, j + 0, k + 16, KCore.VolcanicRock, 0);
		this.setBlock(world, i + 21, j + 0, k + 17, KCore.VolcanicRock, 0);
		this.setBlock(world, i + 21, j + 0, k + 18, KCore.VolcanicRock, 0);
		this.setBlock(world, i + 21, j + 0, k + 19, KCore.VolcanicRock, 0);
		this.setBlock(world, i + 21, j + 0, k + 20, KCore.VolcanicBrick, 0);
		this.setBlock(world, i + 21, j + 1, k + 7, KCore.VolcanicBrick, 0);
		this.setBlock(world, i + 21, j + 1, k + 20, KCore.VolcanicBrick, 0);
		this.setBlock(world, i + 21, j + 2, k + 7, KCore.VolcanicBrick, 0);
		this.setBlock(world, i + 21, j + 2, k + 20, KCore.VolcanicBrick, 0);
		this.setBlock(world, i + 21, j + 3, k + 7, KCore.VolcanicBrick, 0);
		this.setBlock(world, i + 21, j + 3, k + 20, KCore.VolcanicBrick, 0);
		this.setBlock(world, i + 21, j + 4, k + 7, KCore.VolcanicBrick, 0);
		this.setBlock(world, i + 21, j + 4, k + 20, KCore.VolcanicBrick, 0);
		this.setBlock(world, i + 21, j + 5, k + 8, KCore.VolcanicBrick, 0);
		this.setBlock(world, i + 21, j + 5, k + 19, KCore.VolcanicBrick, 0);
		this.setBlock(world, i + 21, j + 6, k + 9, KCore.VolcanicBrick, 0);
		this.setBlock(world, i + 21, j + 6, k + 18, KCore.VolcanicBrick, 0);
		this.setBlock(world, i + 21, j + 7, k + 10, KCore.VolcanicBrick, 0);
		this.setBlock(world, i + 21, j + 7, k + 17, KCore.VolcanicBrick, 0);
		this.setBlock(world, i + 21, j + 8, k + 11, KCore.VolcanicBrick, 0);
		this.setBlock(world, i + 21, j + 8, k + 16, KCore.VolcanicBrick, 0);
		this.setBlock(world, i + 21, j + 9, k + 12, KCore.VolcanicBrick, 0);
		this.setBlock(world, i + 21, j + 9, k + 15, KCore.VolcanicBrick, 0);
		this.setBlock(world, i + 21, j + 10, k + 13, KCore.VolcanicBrick, 0);
		this.setBlock(world, i + 21, j + 10, k + 14, KCore.VolcanicBrick, 0);
		this.setBlock(world, i + 22, j + 0, k + 8, KCore.VolcanicBrick, 0);
		this.setBlock(world, i + 22, j + 0, k + 9, KCore.VolcanicRock, 0);
		this.setBlock(world, i + 22, j + 0, k + 10, KCore.VolcanicRock, 0);
		this.setBlock(world, i + 22, j + 0, k + 11, KCore.VolcanicRock, 0);
		this.setBlock(world, i + 22, j + 0, k + 12, KCore.VolcanicRock, 0);
		this.setBlock(world, i + 22, j + 0, k + 13, KCore.VolcanicRock, 0);
		this.setBlock(world, i + 22, j + 0, k + 14, KCore.VolcanicRock, 0);
		this.setBlock(world, i + 22, j + 0, k + 15, KCore.VolcanicRock, 0);
		this.setBlock(world, i + 22, j + 0, k + 16, KCore.VolcanicRock, 0);
		this.setBlock(world, i + 22, j + 0, k + 17, KCore.VolcanicRock, 0);
		this.setBlock(world, i + 22, j + 0, k + 18, KCore.VolcanicRock, 0);
		this.setBlock(world, i + 22, j + 0, k + 19, KCore.VolcanicBrick, 0);
		this.setBlock(world, i + 22, j + 1, k + 8, KCore.VolcanicBrick, 0);
		this.setBlock(world, i + 22, j + 1, k + 19, KCore.VolcanicBrick, 0);
		this.setBlock(world, i + 22, j + 2, k + 8, KCore.VolcanicBrick, 0);
		this.setBlock(world, i + 22, j + 2, k + 19, KCore.VolcanicBrick, 0);
		this.setBlock(world, i + 22, j + 3, k + 8, KCore.VolcanicBrick, 0);
		this.setBlock(world, i + 22, j + 3, k + 19, KCore.VolcanicBrick, 0);
		this.setBlock(world, i + 22, j + 4, k + 8, KCore.VolcanicBrick, 0);
		this.setBlock(world, i + 22, j + 4, k + 19, KCore.VolcanicBrick, 0);
		this.setBlock(world, i + 22, j + 5, k + 9, KCore.VolcanicBrick, 0);
		this.setBlock(world, i + 22, j + 5, k + 18, KCore.VolcanicBrick, 0);
		this.setBlock(world, i + 22, j + 6, k + 10, KCore.VolcanicBrick, 0);
		this.setBlock(world, i + 22, j + 6, k + 17, KCore.VolcanicBrick, 0);
		this.setBlock(world, i + 22, j + 7, k + 11, KCore.VolcanicBrick, 0);
		this.setBlock(world, i + 22, j + 7, k + 16, KCore.VolcanicBrick, 0);
		this.setBlock(world, i + 22, j + 8, k + 12, KCore.VolcanicBrick, 0);
		this.setBlock(world, i + 22, j + 8, k + 15, KCore.VolcanicBrick, 0);
		this.setBlock(world, i + 22, j + 9, k + 13, KCore.VolcanicBrick, 0);
		this.setBlock(world, i + 22, j + 9, k + 14, KCore.VolcanicBrick, 0);
		this.setBlock(world, i + 23, j + 0, k + 8, KCore.VolcanicBrick, 0);
		this.setBlock(world, i + 23, j + 0, k + 9, KCore.VolcanicRock, 0);
		this.setBlock(world, i + 23, j + 0, k + 10, KCore.VolcanicRock, 0);
		this.setBlock(world, i + 23, j + 0, k + 11, KCore.VolcanicRock, 0);
		this.setBlock(world, i + 23, j + 0, k + 12, KCore.VolcanicRock, 0);
		this.setBlock(world, i + 23, j + 0, k + 13, KCore.VolcanicRock, 0);
		this.setBlock(world, i + 23, j + 0, k + 14, KCore.VolcanicRock, 0);
		this.setBlock(world, i + 23, j + 0, k + 15, KCore.VolcanicRock, 0);
		this.setBlock(world, i + 23, j + 0, k + 16, KCore.VolcanicRock, 0);
		this.setBlock(world, i + 23, j + 0, k + 17, KCore.VolcanicRock, 0);
		this.setBlock(world, i + 23, j + 0, k + 18, KCore.VolcanicRock, 0);
		this.setBlock(world, i + 23, j + 0, k + 19, KCore.VolcanicBrick, 0);
		this.setBlock(world, i + 23, j + 1, k + 8, KCore.VolcanicBrick, 0);
		this.setBlock(world, i + 23, j + 1, k + 19, KCore.VolcanicBrick, 0);
		this.setBlock(world, i + 23, j + 2, k + 8, KCore.VolcanicBrick, 0);
		this.setBlock(world, i + 23, j + 2, k + 19, KCore.VolcanicBrick, 0);
		this.setBlock(world, i + 23, j + 3, k + 8, KCore.VolcanicBrick, 0);
		this.setBlock(world, i + 23, j + 3, k + 19, KCore.VolcanicBrick, 0);
		this.setBlock(world, i + 23, j + 4, k + 8, KCore.VolcanicBrick, 0);
		this.setBlock(world, i + 23, j + 4, k + 19, KCore.VolcanicBrick, 0);
		this.setBlock(world, i + 23, j + 5, k + 9, KCore.VolcanicBrick, 0);
		this.setBlock(world, i + 23, j + 5, k + 18, KCore.VolcanicBrick, 0);
		this.setBlock(world, i + 23, j + 6, k + 10, KCore.VolcanicBrick, 0);
		this.setBlock(world, i + 23, j + 6, k + 17, KCore.VolcanicBrick, 0);
		this.setBlock(world, i + 23, j + 7, k + 11, KCore.VolcanicBrick, 0);
		this.setBlock(world, i + 23, j + 7, k + 16, KCore.VolcanicBrick, 0);
		this.setBlock(world, i + 23, j + 8, k + 12, KCore.VolcanicBrick, 0);
		this.setBlock(world, i + 23, j + 8, k + 15, KCore.VolcanicBrick, 0);
		this.setBlock(world, i + 23, j + 9, k + 13, KCore.VolcanicBrick, 0);
		this.setBlock(world, i + 23, j + 9, k + 14, KCore.VolcanicBrick, 0);
		this.setBlock(world, i + 24, j + 0, k + 9, KCore.VolcanicBrick, 0);
		this.setBlock(world, i + 24, j + 0, k + 10, KCore.VolcanicRock, 0);
		this.setBlock(world, i + 24, j + 0, k + 11, KCore.VolcanicRock, 0);
		this.setBlock(world, i + 24, j + 0, k + 12, KCore.VolcanicRock, 0);
		this.setBlock(world, i + 24, j + 0, k + 13, KCore.VolcanicRock, 0);
		this.setBlock(world, i + 24, j + 0, k + 14, KCore.VolcanicRock, 0);
		this.setBlock(world, i + 24, j + 0, k + 15, KCore.VolcanicRock, 0);
		this.setBlock(world, i + 24, j + 0, k + 16, KCore.VolcanicRock, 0);
		this.setBlock(world, i + 24, j + 0, k + 17, KCore.VolcanicRock, 0);
		this.setBlock(world, i + 24, j + 0, k + 18, KCore.VolcanicBrick, 0);
		this.setBlock(world, i + 24, j + 1, k + 9, KCore.VolcanicBrick, 0);
		this.setBlock(world, i + 24, j + 1, k + 18, KCore.VolcanicBrick, 0);
		this.setBlock(world, i + 24, j + 2, k + 9, KCore.VolcanicBrick, 0);
		this.setBlock(world, i + 24, j + 2, k + 18, KCore.VolcanicBrick, 0);
		this.setBlock(world, i + 24, j + 3, k + 9, KCore.VolcanicBrick, 0);
		this.setBlock(world, i + 24, j + 3, k + 18, KCore.VolcanicBrick, 0);
		this.setBlock(world, i + 24, j + 4, k + 9, KCore.VolcanicBrick, 0);
		this.setBlock(world, i + 24, j + 4, k + 18, KCore.VolcanicBrick, 0);
		this.setBlock(world, i + 24, j + 5, k + 10, KCore.VolcanicBrick, 0);
		this.setBlock(world, i + 24, j + 5, k + 17, KCore.VolcanicBrick, 0);
		this.setBlock(world, i + 24, j + 6, k + 11, KCore.VolcanicBrick, 0);
		this.setBlock(world, i + 24, j + 6, k + 16, KCore.VolcanicBrick, 0);
		this.setBlock(world, i + 24, j + 7, k + 12, KCore.VolcanicBrick, 0);
		this.setBlock(world, i + 24, j + 7, k + 15, KCore.VolcanicBrick, 0);
		this.setBlock(world, i + 24, j + 8, k + 13, KCore.VolcanicBrick, 0);
		this.setBlock(world, i + 24, j + 8, k + 14, KCore.VolcanicBrick, 0);
		this.setBlock(world, i + 25, j + 0, k + 9, KCore.VolcanicBrick, 0);
		this.setBlock(world, i + 25, j + 0, k + 10, KCore.VolcanicRock, 0);
		this.setBlock(world, i + 25, j + 0, k + 11, KCore.VolcanicRock, 0);
		this.setBlock(world, i + 25, j + 0, k + 12, KCore.VolcanicRock, 0);
		this.setBlock(world, i + 25, j + 0, k + 13, KCore.VolcanicRock, 0);
		this.setBlock(world, i + 25, j + 0, k + 14, KCore.VolcanicRock, 0);
		this.setBlock(world, i + 25, j + 0, k + 15, KCore.VolcanicRock, 0);
		this.setBlock(world, i + 25, j + 0, k + 16, KCore.VolcanicRock, 0);
		this.setBlock(world, i + 25, j + 0, k + 17, KCore.VolcanicRock, 0);
		this.setBlock(world, i + 25, j + 0, k + 18, KCore.VolcanicBrick, 0);
		this.setBlock(world, i + 25, j + 1, k + 9, KCore.VolcanicBrick, 0);
		this.setBlock(world, i + 25, j + 1, k + 18, KCore.VolcanicBrick, 0);
		this.setBlock(world, i + 25, j + 2, k + 9, KCore.VolcanicBrick, 0);
		this.setBlock(world, i + 25, j + 2, k + 18, KCore.VolcanicBrick, 0);
		this.setBlock(world, i + 25, j + 3, k + 9, KCore.VolcanicBrick, 0);
		this.setBlock(world, i + 25, j + 3, k + 18, KCore.VolcanicBrick, 0);
		this.setBlock(world, i + 25, j + 4, k + 9, KCore.VolcanicBrick, 0);
		this.setBlock(world, i + 25, j + 4, k + 18, KCore.VolcanicBrick, 0);
		this.setBlock(world, i + 25, j + 5, k + 10, KCore.VolcanicBrick, 0);
		this.setBlock(world, i + 25, j + 5, k + 17, KCore.VolcanicBrick, 0);
		this.setBlock(world, i + 25, j + 6, k + 11, KCore.VolcanicBrick, 0);
		this.setBlock(world, i + 25, j + 6, k + 16, KCore.VolcanicBrick, 0);
		this.setBlock(world, i + 25, j + 7, k + 12, KCore.VolcanicBrick, 0);
		this.setBlock(world, i + 25, j + 7, k + 15, KCore.VolcanicBrick, 0);
		this.setBlock(world, i + 25, j + 8, k + 13, KCore.VolcanicBrick, 0);
		this.setBlock(world, i + 25, j + 8, k + 14, KCore.VolcanicBrick, 0);
		this.setBlock(world, i + 26, j + 0, k + 10, KCore.VolcanicBrick, 0);
		this.setBlock(world, i + 26, j + 0, k + 11, KCore.VolcanicRock, 0);
		this.setBlock(world, i + 26, j + 0, k + 12, KCore.VolcanicRock, 0);
		this.setBlock(world, i + 26, j + 0, k + 13, KCore.VolcanicRock, 0);
		this.setBlock(world, i + 26, j + 0, k + 14, KCore.VolcanicRock, 0);
		this.setBlock(world, i + 26, j + 0, k + 15, KCore.VolcanicRock, 0);
		this.setBlock(world, i + 26, j + 0, k + 16, KCore.VolcanicRock, 0);
		this.setBlock(world, i + 26, j + 0, k + 17, KCore.VolcanicBrick, 0);
		this.setBlock(world, i + 26, j + 1, k + 10, KCore.VolcanicBrick, 0);
		this.setBlock(world, i + 26, j + 1, k + 17, KCore.VolcanicBrick, 0);
		this.setBlock(world, i + 26, j + 2, k + 10, KCore.VolcanicBrick, 0);
		this.setBlock(world, i + 26, j + 2, k + 17, KCore.VolcanicBrick, 0);
		this.setBlock(world, i + 26, j + 3, k + 10, KCore.VolcanicBrick, 0);
		this.setBlock(world, i + 26, j + 3, k + 17, KCore.VolcanicBrick, 0);
		this.setBlock(world, i + 26, j + 4, k + 10, KCore.VolcanicBrick, 0);
		this.setBlock(world, i + 26, j + 4, k + 17, KCore.VolcanicBrick, 0);
		this.setBlock(world, i + 26, j + 5, k + 11, KCore.VolcanicBrick, 0);
		this.setBlock(world, i + 26, j + 5, k + 16, KCore.VolcanicBrick, 0);
		this.setBlock(world, i + 26, j + 6, k + 12, KCore.VolcanicBrick, 0);
		this.setBlock(world, i + 26, j + 6, k + 15, KCore.VolcanicBrick, 0);
		this.setBlock(world, i + 26, j + 7, k + 13, KCore.VolcanicBrick, 0);
		this.setBlock(world, i + 26, j + 7, k + 14, KCore.VolcanicBrick, 0);
		this.setBlock(world, i + 27, j + 0, k + 10, KCore.VolcanicBrick, 0);
		this.setBlock(world, i + 27, j + 0, k + 11, KCore.VolcanicRock, 0);
		this.setBlock(world, i + 27, j + 0, k + 12, KCore.VolcanicRock, 0);
		this.setBlock(world, i + 27, j + 0, k + 13, KCore.VolcanicRock, 0);
		this.setBlock(world, i + 27, j + 0, k + 14, KCore.VolcanicRock, 0);
		this.setBlock(world, i + 27, j + 0, k + 15, KCore.VolcanicRock, 0);
		this.setBlock(world, i + 27, j + 0, k + 16, KCore.VolcanicRock, 0);
		this.setBlock(world, i + 27, j + 0, k + 17, KCore.VolcanicBrick, 0);
		this.setBlock(world, i + 27, j + 1, k + 10, KCore.VolcanicBrick, 0);
		this.setBlock(world, i + 27, j + 1, k + 17, KCore.VolcanicBrick, 0);
		this.setBlock(world, i + 27, j + 2, k + 10, KCore.VolcanicBrick, 0);
		this.setBlock(world, i + 27, j + 2, k + 17, KCore.VolcanicBrick, 0);
		this.setBlock(world, i + 27, j + 3, k + 10, KCore.VolcanicBrick, 0);
		this.setBlock(world, i + 27, j + 3, k + 17, KCore.VolcanicBrick, 0);
		this.setBlock(world, i + 27, j + 4, k + 10, KCore.VolcanicBrick, 0);
		this.setBlock(world, i + 27, j + 4, k + 17, KCore.VolcanicBrick, 0);
		this.setBlock(world, i + 27, j + 5, k + 11, KCore.VolcanicBrick, 0);
		this.setBlock(world, i + 27, j + 5, k + 16, KCore.VolcanicBrick, 0);
		this.setBlock(world, i + 27, j + 6, k + 12, KCore.VolcanicBrick, 0);
		this.setBlock(world, i + 27, j + 6, k + 15, KCore.VolcanicBrick, 0);
		this.setBlock(world, i + 27, j + 7, k + 13, KCore.VolcanicBrick, 0);
		this.setBlock(world, i + 27, j + 7, k + 14, KCore.VolcanicBrick, 0);
		this.setBlock(world, i + 28, j + 0, k + 11, KCore.VolcanicBrick, 0);
		this.setBlock(world, i + 28, j + 0, k + 12, KCore.VolcanicRock, 0);
		this.setBlock(world, i + 28, j + 0, k + 13, KCore.VolcanicRock, 0);
		this.setBlock(world, i + 28, j + 0, k + 14, KCore.VolcanicRock, 0);
		this.setBlock(world, i + 28, j + 0, k + 15, KCore.VolcanicRock, 0);
		this.setBlock(world, i + 28, j + 0, k + 16, KCore.VolcanicBrick, 0);
		this.setBlock(world, i + 28, j + 1, k + 11, KCore.VolcanicBrick, 0);
		this.setBlock(world, i + 28, j + 1, k + 16, KCore.VolcanicBrick, 0);
		this.setBlock(world, i + 28, j + 2, k + 11, KCore.VolcanicBrick, 0);
		this.setBlock(world, i + 28, j + 2, k + 16, KCore.VolcanicBrick, 0);
		this.setBlock(world, i + 28, j + 3, k + 11, KCore.VolcanicBrick, 0);
		this.setBlock(world, i + 28, j + 3, k + 16, KCore.VolcanicBrick, 0);
		this.setBlock(world, i + 28, j + 4, k + 11, KCore.VolcanicBrick, 0);
		this.setBlock(world, i + 28, j + 4, k + 16, KCore.VolcanicBrick, 0);
		this.setBlock(world, i + 28, j + 5, k + 12, KCore.VolcanicBrick, 0);
		this.setBlock(world, i + 28, j + 5, k + 15, KCore.VolcanicBrick, 0);
		this.setBlock(world, i + 28, j + 6, k + 13, KCore.VolcanicBrick, 0);
		this.setBlock(world, i + 28, j + 6, k + 14, KCore.VolcanicBrick, 0);
		this.setBlock(world, i + 29, j + 0, k + 11, KCore.VolcanicBrick, 0);
		this.setBlock(world, i + 29, j + 0, k + 12, KCore.VolcanicRock, 0);
		this.setBlock(world, i + 29, j + 0, k + 13, KCore.VolcanicRock, 0);
		this.setBlock(world, i + 29, j + 0, k + 14, KCore.VolcanicRock, 0);
		this.setBlock(world, i + 29, j + 0, k + 15, KCore.VolcanicRock, 0);
		this.setBlock(world, i + 29, j + 0, k + 16, KCore.VolcanicBrick, 0);
		this.setBlock(world, i + 29, j + 1, k + 11, KCore.VolcanicBrick, 0);
		this.setBlock(world, i + 29, j + 1, k + 16, KCore.VolcanicBrick, 0);
		this.setBlock(world, i + 29, j + 2, k + 11, KCore.VolcanicBrick, 0);
		this.setBlock(world, i + 29, j + 2, k + 16, KCore.VolcanicBrick, 0);
		this.setBlock(world, i + 29, j + 3, k + 11, KCore.VolcanicBrick, 0);
		this.setBlock(world, i + 29, j + 3, k + 16, KCore.VolcanicBrick, 0);
		this.setBlock(world, i + 29, j + 4, k + 11, KCore.VolcanicBrick, 0);
		this.setBlock(world, i + 29, j + 4, k + 16, KCore.VolcanicBrick, 0);
		this.setBlock(world, i + 29, j + 5, k + 12, KCore.VolcanicBrick, 0);
		this.setBlock(world, i + 29, j + 5, k + 13, KCore.VolcanicBrick, 0);
		this.setBlock(world, i + 29, j + 5, k + 14, KCore.VolcanicBrick, 0);
		this.setBlock(world, i + 29, j + 5, k + 15, KCore.VolcanicBrick, 0);
		this.setBlock(world, i + 30, j + 0, k + 12, KCore.VolcanicBrick, 0);
		this.setBlock(world, i + 30, j + 0, k + 13, KCore.VolcanicRock, 0);
		this.setBlock(world, i + 30, j + 0, k + 14, KCore.VolcanicRock, 0);
		this.setBlock(world, i + 30, j + 0, k + 15, KCore.VolcanicBrick, 0);
		this.setBlock(world, i + 30, j + 1, k + 12, KCore.VolcanicBrick, 0);
		this.setBlock(world, i + 30, j + 1, k + 15, KCore.VolcanicBrick, 0);
		this.setBlock(world, i + 30, j + 2, k + 12, KCore.VolcanicBrick, 0);
		this.setBlock(world, i + 30, j + 2, k + 15, KCore.VolcanicBrick, 0);
		this.setBlock(world, i + 30, j + 3, k + 12, KCore.VolcanicBrick, 0);
		this.setBlock(world, i + 30, j + 3, k + 13, KCore.VolcanicBrick, 0);
		this.setBlock(world, i + 30, j + 3, k + 14, KCore.VolcanicBrick, 0);
		this.setBlock(world, i + 30, j + 3, k + 15, KCore.VolcanicBrick, 0);
		this.setBlock(world, i + 30, j + 4, k + 12, KCore.VolcanicBrick, 0);
		this.setBlock(world, i + 30, j + 4, k + 13, KCore.VolcanicBrick, 0);
		this.setBlock(world, i + 30, j + 4, k + 14, KCore.VolcanicBrick, 0);
		this.setBlock(world, i + 30, j + 4, k + 15, KCore.VolcanicBrick, 0);
		this.setBlock(world, i + 31, j + 0, k + 12, KCore.VolcanicBrick, 0);
		this.setBlock(world, i + 31, j + 0, k + 13, KCore.VolcanicRock, 0);
		this.setBlock(world, i + 31, j + 0, k + 14, KCore.VolcanicRock, 0);
		this.setBlock(world, i + 31, j + 0, k + 15, KCore.VolcanicBrick, 0);
		this.setBlock(world, i + 31, j + 1, k + 12, KCore.VolcanicBrick, 0);
		this.setBlock(world, i + 31, j + 1, k + 15, KCore.VolcanicBrick, 0);
		this.setBlock(world, i + 31, j + 2, k + 12, KCore.VolcanicBrick, 0);
		this.setBlock(world, i + 31, j + 2, k + 15, KCore.VolcanicBrick, 0);
		this.setBlock(world, i + 31, j + 3, k + 13, KCore.VolcanicBrick, 0);
		this.setBlock(world, i + 31, j + 3, k + 14, KCore.VolcanicBrick, 0);
		this.setBlock(world, i + 32, j + 0, k + 12, KCore.VolcanicBrick, 0);
		this.setBlock(world, i + 32, j + 0, k + 13, KCore.VolcanicRock, 0);
		this.setBlock(world, i + 32, j + 0, k + 14, KCore.VolcanicRock, 0);
		this.setBlock(world, i + 32, j + 0, k + 15, KCore.VolcanicBrick, 0);
		this.setBlock(world, i + 32, j + 1, k + 12, KCore.VolcanicBrick, 0);
		this.setBlock(world, i + 32, j + 1, k + 15, KCore.VolcanicBrick, 0);
		this.setBlock(world, i + 32, j + 2, k + 12, KCore.VolcanicBrick, 0);
		this.setBlock(world, i + 32, j + 2, k + 15, KCore.VolcanicBrick, 0);
		this.setBlock(world, i + 32, j + 3, k + 13, KCore.VolcanicBrick, 0);
		this.setBlock(world, i + 32, j + 3, k + 14, KCore.VolcanicBrick, 0);
		this.setBlock(world, i + 33, j + 0, k + 12, KCore.VolcanicBrick, 0);
		this.setBlock(world, i + 33, j + 0, k + 13, KCore.VolcanicRock, 0);
		this.setBlock(world, i + 33, j + 0, k + 14, KCore.VolcanicRock, 0);
		this.setBlock(world, i + 33, j + 0, k + 15, KCore.VolcanicBrick, 0);
		this.setBlock(world, i + 33, j + 1, k + 12, KCore.VolcanicBrick, 0);
		this.setBlock(world, i + 33, j + 1, k + 15, KCore.VolcanicBrick, 0);
		this.setBlock(world, i + 33, j + 2, k + 12, KCore.VolcanicBrick, 0);
		this.setBlock(world, i + 33, j + 2, k + 15, KCore.VolcanicBrick, 0);
		this.setBlock(world, i + 33, j + 3, k + 13, KCore.VolcanicBrick, 0);
		this.setBlock(world, i + 33, j + 3, k + 14, KCore.VolcanicBrick, 0);
		this.setBlock(world, i + 34, j + 0, k + 12, KCore.VolcanicBrick, 0);
		this.setBlock(world, i + 34, j + 0, k + 13, KCore.VolcanicRock, 0);
		this.setBlock(world, i + 34, j + 0, k + 14, KCore.VolcanicRock, 0);
		this.setBlock(world, i + 34, j + 0, k + 15, KCore.VolcanicBrick, 0);
		this.setBlock(world, i + 34, j + 1, k + 12, KCore.VolcanicBrick, 0);
		this.setBlock(world, i + 34, j + 1, k + 15, KCore.VolcanicBrick, 0);
		this.setBlock(world, i + 34, j + 2, k + 12, KCore.VolcanicBrick, 0);
		this.setBlock(world, i + 34, j + 2, k + 15, KCore.VolcanicBrick, 0);
		this.setBlock(world, i + 34, j + 3, k + 13, KCore.VolcanicBrick, 0);
		this.setBlock(world, i + 34, j + 3, k + 14, KCore.VolcanicBrick, 0);
		this.setBlock(world, i + 35, j + 0, k + 12, KCore.VolcanicBrick, 0);
		this.setBlock(world, i + 35, j + 0, k + 13, KCore.VolcanicRock, 0);
		this.setBlock(world, i + 35, j + 0, k + 14, KCore.VolcanicRock, 0);
		this.setBlock(world, i + 35, j + 0, k + 15, KCore.VolcanicBrick, 0);
		this.setBlock(world, i + 35, j + 1, k + 12, KCore.VolcanicBrick, 0);
		this.setBlock(world, i + 35, j + 1, k + 15, KCore.VolcanicBrick, 0);
		this.setBlock(world, i + 35, j + 2, k + 12, KCore.VolcanicBrick, 0);
		this.setBlock(world, i + 35, j + 2, k + 15, KCore.VolcanicBrick, 0);
		this.setBlock(world, i + 35, j + 3, k + 13, KCore.VolcanicBrick, 0);
		this.setBlock(world, i + 35, j + 3, k + 14, KCore.VolcanicBrick, 0);
		this.setBlock(world, i + 36, j + 0, k + 12, KCore.VolcanicBrick, 0);
		this.setBlock(world, i + 36, j + 0, k + 13, KCore.VolcanicRock, 0);
		this.setBlock(world, i + 36, j + 0, k + 14, KCore.VolcanicRock, 0);
		this.setBlock(world, i + 36, j + 0, k + 15, KCore.VolcanicBrick, 0);
		this.setBlock(world, i + 36, j + 1, k + 12, KCore.VolcanicBrick, 0);
		this.setBlock(world, i + 36, j + 1, k + 15, KCore.VolcanicBrick, 0);
		this.setBlock(world, i + 36, j + 2, k + 12, KCore.VolcanicBrick, 0);
		this.setBlock(world, i + 36, j + 2, k + 15, KCore.VolcanicBrick, 0);
		this.setBlock(world, i + 36, j + 3, k + 13, KCore.VolcanicBrick, 0);
		this.setBlock(world, i + 36, j + 3, k + 14, KCore.VolcanicBrick, 0);
		this.setBlock(world, i + 37, j + 0, k + 12, KCore.VolcanicBrick, 0);
		this.setBlock(world, i + 37, j + 0, k + 13, KCore.VolcanicRock, 0);
		this.setBlock(world, i + 37, j + 0, k + 14, KCore.VolcanicRock, 0);
		this.setBlock(world, i + 37, j + 0, k + 15, KCore.VolcanicBrick, 0);
		this.setBlock(world, i + 37, j + 1, k + 12, KCore.VolcanicBrick, 0);

		this.setBlock(world, i + 37, j + 1, k + 15, KCore.VolcanicBrick, 0);
		this.setBlock(world, i + 37, j + 2, k + 12, KCore.VolcanicBrick, 0);

		this.setBlock(world, i + 37, j + 2, k + 15, KCore.VolcanicBrick, 0);
		
		
		this.setBlock(world, i + 18, j + 1, k + 13, KCore.VolcanicBrick, 2);
		this.setBlock(world, i + 18, j + 1, k + 14, KCore.VolcanicBrick, 2);
		this.setBlock(world, i + 19, j + 1, k + 13, KCore.VolcanicBrick, 2);
		this.setBlock(world, i + 19, j + 1, k + 14, KCore.VolcanicBrick, 2);
		this.setBlock(world, i + 19, j + 2, k + 14, KCore.FireElementalSpawner, 2);

		return true;
	}
	
	public void closeEscape(World world, BlockPos pos)
	{
		int i = pos.getX();
		int j = pos.getY();
		int k = pos.getZ();
		this.setBlock(world, i + 37, j + 2, k + 13, Blocks.obsidian, 0);
		this.setBlock(world, i + 37, j + 2, k + 14, Blocks.obsidian, 0);
		this.setBlock(world, i + 37, j + 1, k + 13, Blocks.obsidian, 0);
		this.setBlock(world, i + 37, j + 1, k + 14, Blocks.obsidian, 0);
		this.setBlock(world, i + 19, j + 1, k + 0, Blocks.obsidian, 0);
		this.setBlock(world, i + 19, j + 1, k + 27, Blocks.obsidian, 0);
		this.setBlock(world, i + 19, j + 2, k + 0, Blocks.obsidian, 0);
		this.setBlock(world, i + 19, j + 2, k + 27, Blocks.obsidian, 0);
		this.setBlock(world, i + 18, j + 1, k + 0, Blocks.obsidian, 0);
		this.setBlock(world, i + 18, j + 1, k + 27, Blocks.obsidian, 0);
		this.setBlock(world, i + 18, j + 2, k + 0, Blocks.obsidian, 0);
		this.setBlock(world, i + 18, j + 2, k + 27, Blocks.obsidian, 0);
		this.setBlock(world, i + 0, j + 1, k + 13, Blocks.obsidian, 0);
		this.setBlock(world, i + 0, j + 1, k + 14, Blocks.obsidian, 0);
		this.setBlock(world, i + 0, j + 2, k + 13, Blocks.obsidian, 0);
		this.setBlock(world, i + 0, j + 2, k + 14, Blocks.obsidian, 0);
	}
	
}