package com.KMOD.HeavenGens;

import java.util.Random;

import net.minecraft.init.Blocks;
import net.minecraft.world.World;

import com.KMOD.Core.KCore;

public class GenForbiddenDungeonPiece3 extends GenForbiddenDungeonMain
{
	public GenForbiddenDungeonPiece3() { }
	
	public boolean generate7(World world, Random rand, int i, int j, int k)
	{
		this.setBlock(world, i + 13, j + 8, k + 33, KCore.ForbiddenBrick, 0);
		this.setBlock(world, i + 13, j + 8, k + 34, KCore.ForbiddenBrick, 0);
		this.setBlock(world, i + 13, j + 8, k + 35, KCore.ForbiddenBrick, 0);
		this.setBlock(world, i + 13, j + 8, k + 36, KCore.ForbiddenBrick, 0);
		this.setBlock(world, i + 13, j + 8, k + 37, KCore.ForbiddenBrick, 0);
		this.setBlock(world, i + 13, j + 8, k + 38, KCore.ForbiddenBrick, 0);
		this.setBlock(world, i + 13, j + 9, k + 3, KCore.ForbiddenBrick, 0);
		this.setBlock(world, i + 13, j + 9, k + 4, KCore.ForbiddenBrick, 0);
		this.setBlock(world, i + 13, j + 9, k + 5, KCore.ForbiddenRock, 0);
		this.setBlock(world, i + 13, j + 9, k + 6, KCore.ForbiddenRock, 0);
		this.setBlock(world, i + 13, j + 9, k + 7, KCore.ForbiddenBrick, 0);
		this.setBlock(world, i + 13, j + 9, k + 8, KCore.ForbiddenBrick, 0);
		this.setBlock(world, i + 13, j + 9, k + 9, KCore.ForbiddenBrick, 0);
		this.setBlock(world, i + 13, j + 9, k + 10, KCore.ForbiddenBrick, 0);
		this.setBlock(world, i + 13, j + 9, k + 11, KCore.ForbiddenBrick, 0);
		this.setBlock(world, i + 13, j + 9, k + 12, KCore.ForbiddenBrick, 0);
		this.setBlock(world, i + 13, j + 9, k + 13, KCore.ForbiddenBrick, 0);
		this.setBlock(world, i + 13, j + 9, k + 14, KCore.ForbiddenLightBrick, 0);
		this.setBlock(world, i + 13, j + 9, k + 15, KCore.ForbiddenRock, 0);
		this.setBlock(world, i + 13, j + 9, k + 16, KCore.ForbiddenBrick, 0);
		this.setBlock(world, i + 13, j + 9, k + 17, KCore.ForbiddenBrick, 0);
		this.setBlock(world, i + 13, j + 9, k + 18, KCore.ForbiddenBrick, 0);
		this.setBlock(world, i + 13, j + 9, k + 19, KCore.ForbiddenBrick, 0);
		this.setBlock(world, i + 13, j + 9, k + 20, KCore.ForbiddenBrick, 0);
		this.setBlock(world, i + 13, j + 9, k + 21, KCore.ForbiddenBrick, 0);
		this.setBlock(world, i + 13, j + 9, k + 22, KCore.ForbiddenBrick, 0);
		this.setBlock(world, i + 13, j + 9, k + 23, KCore.ForbiddenBrick, 0);
		this.setBlock(world, i + 13, j + 9, k + 24, KCore.ForbiddenBrick, 0);
		this.setBlock(world, i + 13, j + 9, k + 28, KCore.ForbiddenBrick, 0);
		this.setBlock(world, i + 13, j + 9, k + 29, KCore.ForbiddenBrick, 0);
		this.setBlock(world, i + 13, j + 9, k + 30, KCore.ForbiddenBrick, 0);
		this.setBlock(world, i + 13, j + 9, k + 31, KCore.ForbiddenBrick, 0);
		this.setBlock(world, i + 13, j + 9, k + 32, KCore.ForbiddenBrick, 0);
		this.setBlock(world, i + 13, j + 9, k + 33, KCore.ForbiddenBrick, 0);
		this.setBlock(world, i + 13, j + 9, k + 34, KCore.ForbiddenBrick, 0);
		this.setBlock(world, i + 13, j + 9, k + 35, KCore.ForbiddenBrick, 0);
		this.setBlock(world, i + 13, j + 9, k + 36, KCore.ForbiddenBrick, 0);
		this.setBlock(world, i + 13, j + 9, k + 37, KCore.ForbiddenBrick, 0);
		this.setBlock(world, i + 13, j + 9, k + 38, KCore.ForbiddenBrick, 0);
		this.setBlock(world, i + 13, j + 10, k + 3, KCore.ForbiddenBrick, 0);
		this.setBlock(world, i + 13, j + 10, k + 4, KCore.ForbiddenBrick, 0);
		this.setBlock(world, i + 13, j + 10, k + 5, KCore.ForbiddenRock, 0);
		this.setBlock(world, i + 13, j + 10, k + 6, KCore.ForbiddenLightBrick, 0);
		this.setBlock(world, i + 13, j + 10, k + 7, KCore.ForbiddenBrick, 0);
		this.setBlock(world, i + 13, j + 10, k + 8, KCore.ForbiddenBrick, 0);
		this.setBlock(world, i + 13, j + 10, k + 9, KCore.ForbiddenBrick, 0);
		this.setBlock(world, i + 13, j + 10, k + 10, KCore.ForbiddenBrick, 0);
		this.setBlock(world, i + 13, j + 10, k + 11, KCore.ForbiddenBrick, 0);
		this.setBlock(world, i + 13, j + 10, k + 12, KCore.ForbiddenBrick, 0);
		this.setBlock(world, i + 13, j + 10, k + 13, KCore.ForbiddenBrick, 0);
		this.setBlock(world, i + 13, j + 10, k + 16, KCore.ForbiddenBrick, 0);
		this.setBlock(world, i + 13, j + 10, k + 17, KCore.ForbiddenBrick, 0);
		this.setBlock(world, i + 13, j + 10, k + 18, KCore.ForbiddenBrick, 0);
		this.setBlock(world, i + 13, j + 10, k + 19, KCore.ForbiddenBrick, 0);
		this.setBlock(world, i + 13, j + 10, k + 20, KCore.ForbiddenBrick, 0);
		this.setBlock(world, i + 13, j + 10, k + 21, KCore.ForbiddenBrick, 0);
		this.setBlock(world, i + 13, j + 10, k + 22, KCore.ForbiddenBrick, 0);
		this.setBlock(world, i + 13, j + 10, k + 23, KCore.ForbiddenBrick, 0);
		this.setBlock(world, i + 13, j + 10, k + 24, KCore.ForbiddenBrick, 0);
		this.setBlock(world, i + 13, j + 10, k + 28, KCore.ForbiddenBrick, 0);
		this.setBlock(world, i + 13, j + 10, k + 29, KCore.ForbiddenBrick, 0);
		this.setBlock(world, i + 13, j + 10, k + 30, KCore.ForbiddenBrick, 0);
		this.setBlock(world, i + 13, j + 10, k + 31, KCore.ForbiddenBrick, 0);
		this.setBlock(world, i + 13, j + 10, k + 32, KCore.ForbiddenBrick, 0);
		this.setBlock(world, i + 13, j + 10, k + 33, KCore.ForbiddenBrick, 0);
		this.setBlock(world, i + 13, j + 10, k + 34, KCore.ForbiddenBrick, 0);
		this.setBlock(world, i + 13, j + 10, k + 35, KCore.ForbiddenBrick, 0);
		this.setBlock(world, i + 13, j + 10, k + 36, KCore.ForbiddenBrick, 0);
		this.setBlock(world, i + 13, j + 10, k + 37, KCore.ForbiddenBrick, 0);
		this.setBlock(world, i + 13, j + 10, k + 38, KCore.ForbiddenBrick, 0);
		this.setBlock(world, i + 13, j + 11, k + 3, KCore.ForbiddenBrick, 0);
		this.setBlock(world, i + 13, j + 11, k + 4, KCore.ForbiddenBrick, 0);
		this.setBlock(world, i + 13, j + 11, k + 5, KCore.ForbiddenBrickStairs, 0);
		this.setBlock(world, i + 13, j + 11, k + 6, KCore.ForbiddenBrickStairs, 0);
		this.setBlock(world, i + 13, j + 11, k + 7, KCore.ForbiddenBrick, 0);
		this.setBlock(world, i + 13, j + 11, k + 8, KCore.ForbiddenBrick, 0);
		this.setBlock(world, i + 13, j + 11, k + 9, KCore.ForbiddenBrick, 0);
		this.setBlock(world, i + 13, j + 11, k + 10, KCore.ForbiddenBrick, 0);
		this.setBlock(world, i + 13, j + 11, k + 11, KCore.ForbiddenBrick, 0);
		this.setBlock(world, i + 13, j + 11, k + 12, KCore.ForbiddenBrick, 0);
		this.setBlock(world, i + 13, j + 11, k + 13, KCore.ForbiddenBrick, 0);
		this.setBlock(world, i + 13, j + 11, k + 16, KCore.ForbiddenBrick, 0);
		this.setBlock(world, i + 13, j + 11, k + 17, KCore.ForbiddenBrick, 0);
		this.setBlock(world, i + 13, j + 11, k + 18, KCore.ForbiddenBrick, 0);
		this.setBlock(world, i + 13, j + 11, k + 19, KCore.ForbiddenBrick, 0);
		this.setBlock(world, i + 13, j + 11, k + 20, KCore.ForbiddenBrick, 0);
		this.setBlock(world, i + 13, j + 11, k + 21, KCore.ForbiddenBrick, 0);
		this.setBlock(world, i + 13, j + 11, k + 22, KCore.ForbiddenBrick, 0);
		this.setBlock(world, i + 13, j + 11, k + 23, KCore.ForbiddenBrick, 0);
		this.setBlock(world, i + 13, j + 11, k + 24, KCore.ForbiddenBrick, 0);
		this.setBlock(world, i + 13, j + 11, k + 28, KCore.ForbiddenBrick, 0);
		this.setBlock(world, i + 13, j + 11, k + 29, KCore.ForbiddenBrick, 0);
		this.setBlock(world, i + 13, j + 11, k + 30, KCore.ForbiddenBrick, 0);
		this.setBlock(world, i + 13, j + 11, k + 31, KCore.ForbiddenBrick, 0);
		this.setBlock(world, i + 13, j + 11, k + 32, KCore.ForbiddenBrick, 0);
		this.setBlock(world, i + 13, j + 11, k + 33, KCore.ForbiddenBrick, 0);
		this.setBlock(world, i + 13, j + 11, k + 34, KCore.ForbiddenBrick, 0);
		this.setBlock(world, i + 13, j + 11, k + 35, KCore.ForbiddenBrick, 0);
		this.setBlock(world, i + 13, j + 11, k + 36, KCore.ForbiddenBrick, 0);
		this.setBlock(world, i + 13, j + 11, k + 37, KCore.ForbiddenBrick, 0);
		this.setBlock(world, i + 13, j + 11, k + 38, KCore.ForbiddenBrick, 0);
		this.setBlock(world, i + 13, j + 12, k + 3, KCore.ForbiddenBrick, 0);
		this.setBlock(world, i + 13, j + 12, k + 4, KCore.ForbiddenBrick, 0);
		this.setBlock(world, i + 13, j + 12, k + 7, KCore.ForbiddenBrick, 0);
		this.setBlock(world, i + 13, j + 12, k + 8, KCore.ForbiddenBrick, 0);
		this.setBlock(world, i + 13, j + 12, k + 9, KCore.ForbiddenBrick, 0);
		this.setBlock(world, i + 13, j + 12, k + 10, KCore.ForbiddenBrick, 0);
		this.setBlock(world, i + 13, j + 12, k + 11, KCore.ForbiddenBrick, 0);
		this.setBlock(world, i + 13, j + 12, k + 12, KCore.ForbiddenBrick, 0);
		this.setBlock(world, i + 13, j + 12, k + 13, KCore.ForbiddenBrick, 0);
		this.setBlock(world, i + 13, j + 12, k + 14, KCore.ForbiddenBrick, 0);
		this.setBlock(world, i + 13, j + 12, k + 15, KCore.ForbiddenBrick, 0);
		this.setBlock(world, i + 13, j + 12, k + 16, KCore.ForbiddenBrick, 0);
		this.setBlock(world, i + 13, j + 12, k + 17, KCore.ForbiddenBrick, 0);
		this.setBlock(world, i + 13, j + 12, k + 18, KCore.ForbiddenBrick, 0);
		this.setBlock(world, i + 13, j + 12, k + 19, KCore.ForbiddenBrick, 0);
		this.setBlock(world, i + 13, j + 12, k + 20, KCore.ForbiddenBrick, 0);
		this.setBlock(world, i + 13, j + 12, k + 21, KCore.ForbiddenBrick, 0);
		this.setBlock(world, i + 13, j + 12, k + 22, KCore.ForbiddenBrick, 0);
		this.setBlock(world, i + 13, j + 12, k + 23, KCore.ForbiddenBrick, 0);
		this.setBlock(world, i + 13, j + 12, k + 24, KCore.ForbiddenBrick, 0);
		this.setBlock(world, i + 13, j + 12, k + 28, KCore.ForbiddenBrick, 0);
		this.setBlock(world, i + 13, j + 12, k + 29, KCore.ForbiddenBrick, 0);
		this.setBlock(world, i + 13, j + 12, k + 30, KCore.ForbiddenBrick, 0);
		this.setBlock(world, i + 13, j + 12, k + 31, KCore.ForbiddenBrick, 0);
		this.setBlock(world, i + 13, j + 12, k + 32, KCore.ForbiddenBrick, 0);
		this.setBlock(world, i + 13, j + 12, k + 33, KCore.ForbiddenBrick, 0);
		this.setBlock(world, i + 13, j + 12, k + 34, KCore.ForbiddenBrick, 0);
		this.setBlock(world, i + 13, j + 12, k + 35, KCore.ForbiddenBrick, 0);
		this.setBlock(world, i + 13, j + 12, k + 36, KCore.ForbiddenBrick, 0);
		this.setBlock(world, i + 13, j + 12, k + 37, KCore.ForbiddenBrick, 0);
		this.setBlock(world, i + 13, j + 12, k + 38, KCore.ForbiddenBrick, 0);
		this.setBlock(world, i + 13, j + 13, k + 3, KCore.ForbiddenBrick, 0);
		this.setBlock(world, i + 13, j + 13, k + 4, KCore.ForbiddenBrick, 0);
		this.setBlock(world, i + 13, j + 13, k + 7, KCore.ForbiddenBrick, 0);
		this.setBlock(world, i + 13, j + 13, k + 15, KCore.ForbiddenBrick, 0);
		this.setBlock(world, i + 13, j + 13, k + 16, KCore.ForbiddenBrick, 0);
		this.setBlock(world, i + 13, j + 13, k + 17, KCore.ForbiddenBrick, 0);
		this.setBlock(world, i + 13, j + 13, k + 18, KCore.ForbiddenBrick, 0);
		this.setBlock(world, i + 13, j + 13, k + 19, KCore.ForbiddenBrick, 0);
		this.setBlock(world, i + 13, j + 13, k + 20, KCore.ForbiddenBrick, 0);
		this.setBlock(world, i + 13, j + 13, k + 21, KCore.ForbiddenBrick, 0);
		this.setBlock(world, i + 13, j + 13, k + 22, KCore.ForbiddenBrick, 0);
		this.setBlock(world, i + 13, j + 13, k + 23, KCore.ForbiddenBrick, 0);
		this.setBlock(world, i + 13, j + 13, k + 24, KCore.ForbiddenBrick, 0);
		this.setBlock(world, i + 13, j + 13, k + 28, KCore.ForbiddenBrick, 0);
		this.setBlock(world, i + 13, j + 13, k + 29, KCore.ForbiddenBrick, 0);
		this.setBlock(world, i + 13, j + 13, k + 30, KCore.ForbiddenBrick, 0);
		this.setBlock(world, i + 13, j + 13, k + 31, KCore.ForbiddenBrick, 0);
		this.setBlock(world, i + 13, j + 13, k + 32, KCore.ForbiddenBrick, 0);
		this.setBlock(world, i + 13, j + 13, k + 33, KCore.ForbiddenBrick, 0);
		this.setBlock(world, i + 13, j + 13, k + 34, KCore.ForbiddenBrick, 0);
		this.setBlock(world, i + 13, j + 13, k + 35, KCore.ForbiddenBrick, 0);
		this.setBlock(world, i + 13, j + 13, k + 36, KCore.ForbiddenBrick, 0);
		this.setBlock(world, i + 13, j + 13, k + 37, KCore.ForbiddenBrick, 0);
		this.setBlock(world, i + 13, j + 13, k + 38, KCore.ForbiddenBrick, 0);
		this.setBlock(world, i + 13, j + 14, k + 3, KCore.ForbiddenBrick, 0);
		this.setBlock(world, i + 13, j + 14, k + 4, KCore.ForbiddenBrick, 0);
		this.setBlock(world, i + 13, j + 14, k + 7, KCore.ForbiddenBrick, 0);
		this.setBlock(world, i + 13, j + 14, k + 15, KCore.ForbiddenBrick, 0);
		this.setBlock(world, i + 13, j + 14, k + 16, KCore.ForbiddenBrick, 0);
		this.setBlock(world, i + 13, j + 14, k + 17, KCore.ForbiddenBrick, 0);
		this.setBlock(world, i + 13, j + 14, k + 18, KCore.ForbiddenBrick, 0);
		this.setBlock(world, i + 13, j + 14, k + 19, KCore.ForbiddenBrick, 0);
		this.setBlock(world, i + 13, j + 14, k + 20, KCore.ForbiddenBrick, 0);
		this.setBlock(world, i + 13, j + 14, k + 21, KCore.ForbiddenBrick, 0);
		this.setBlock(world, i + 13, j + 14, k + 22, KCore.ForbiddenBrick, 0);
		this.setBlock(world, i + 13, j + 14, k + 23, KCore.ForbiddenBrick, 0);
		this.setBlock(world, i + 13, j + 14, k + 24, KCore.ForbiddenBrick, 0);
		this.setBlock(world, i + 13, j + 14, k + 25, KCore.ForbiddenBrick, 0);
		this.setBlock(world, i + 13, j + 14, k + 26, KCore.ForbiddenBrick, 0);
		this.setBlock(world, i + 13, j + 14, k + 27, KCore.ForbiddenBrick, 0);
		this.setBlock(world, i + 13, j + 14, k + 28, KCore.ForbiddenBrick, 0);
		this.setBlock(world, i + 13, j + 14, k + 29, KCore.ForbiddenBrick, 0);
		this.setBlock(world, i + 13, j + 14, k + 30, KCore.ForbiddenBrick, 0);
		this.setBlock(world, i + 13, j + 14, k + 31, KCore.ForbiddenBrick, 0);
		this.setBlock(world, i + 13, j + 14, k + 32, KCore.ForbiddenBrick, 0);
		this.setBlock(world, i + 13, j + 14, k + 33, KCore.ForbiddenBrick, 0);
		this.setBlock(world, i + 13, j + 14, k + 34, KCore.ForbiddenLightBrick, 0);
		this.setBlock(world, i + 13, j + 14, k + 35, KCore.ForbiddenBrick, 0);
		this.setBlock(world, i + 13, j + 14, k + 36, KCore.ForbiddenBrick, 0);
		this.setBlock(world, i + 13, j + 14, k + 37, KCore.ForbiddenBrick, 0);
		this.setBlock(world, i + 13, j + 14, k + 38, KCore.ForbiddenBrick, 0);
		this.setBlock(world, i + 13, j + 15, k + 3, KCore.ForbiddenBrick, 0);
		this.setBlock(world, i + 13, j + 15, k + 4, KCore.ForbiddenBrick, 0);
		this.setBlock(world, i + 13, j + 15, k + 5, KCore.ForbiddenBrick, 0);
		this.setBlock(world, i + 13, j + 15, k + 6, KCore.ForbiddenBrick, 0);
		this.setBlock(world, i + 13, j + 15, k + 7, KCore.ForbiddenBrick, 0);
		this.setBlock(world, i + 13, j + 15, k + 15, KCore.ForbiddenBrick, 0);
		this.setBlock(world, i + 13, j + 15, k + 36, KCore.ForbiddenBrick, 0);
		this.setBlock(world, i + 13, j + 15, k + 37, KCore.ForbiddenBrick, 0);
		this.setBlock(world, i + 13, j + 15, k + 38, KCore.ForbiddenBrick, 0);
		this.setBlock(world, i + 13, j + 16, k + 3, KCore.ForbiddenBrick, 0);
		this.setBlock(world, i + 13, j + 16, k + 4, KCore.ForbiddenBrick, 0);
		this.setBlock(world, i + 13, j + 16, k + 5, KCore.ForbiddenBrick, 0);
		this.setBlock(world, i + 13, j + 16, k + 6, KCore.ForbiddenBrick, 0);
		this.setBlock(world, i + 13, j + 16, k + 15, KCore.ForbiddenBrick, 0);
		this.setBlock(world, i + 13, j + 16, k + 36, KCore.ForbiddenBrick, 0);
		this.setBlock(world, i + 13, j + 16, k + 37, KCore.ForbiddenBrick, 0);
		this.setBlock(world, i + 13, j + 16, k + 38, KCore.ForbiddenBrick, 0);
		this.setBlock(world, i + 13, j + 17, k + 3, KCore.ForbiddenBrick, 0);
		this.setBlock(world, i + 13, j + 17, k + 4, KCore.ForbiddenBrick, 0);
		this.setBlock(world, i + 13, j + 17, k + 15, KCore.ForbiddenBrick, 0);
		this.setBlock(world, i + 13, j + 17, k + 36, KCore.ForbiddenBrick, 0);
		this.setBlock(world, i + 13, j + 17, k + 37, KCore.ForbiddenBrick, 0);
		this.setBlock(world, i + 13, j + 17, k + 38, KCore.ForbiddenBrick, 0);
		this.setBlock(world, i + 13, j + 18, k + 3, KCore.ForbiddenBrick, 0);
		this.setBlock(world, i + 13, j + 18, k + 15, KCore.ForbiddenBrick, 0);
		this.setBlock(world, i + 13, j + 18, k + 36, KCore.ForbiddenBrick, 0);
		this.setBlock(world, i + 13, j + 18, k + 37, KCore.ForbiddenBrick, 0);
		this.setBlock(world, i + 13, j + 18, k + 38, KCore.ForbiddenBrick, 0);
		this.setBlock(world, i + 13, j + 19, k + 3, KCore.ForbiddenBrick, 0);
		this.setBlock(world, i + 13, j + 19, k + 15, KCore.ForbiddenBrick, 0);
		this.setBlock(world, i + 13, j + 19, k + 36, KCore.ForbiddenBrick, 0);
		this.setBlock(world, i + 13, j + 19, k + 37, KCore.ForbiddenBrick, 0);
		this.setBlock(world, i + 13, j + 19, k + 38, KCore.ForbiddenBrick, 0);
		this.setBlock(world, i + 13, j + 20, k + 3, KCore.ForbiddenBrick, 0);
		this.setBlock(world, i + 13, j + 20, k + 15, KCore.ForbiddenBrick, 0);
		this.setBlock(world, i + 13, j + 20, k + 36, KCore.ForbiddenBrick, 0);
		this.setBlock(world, i + 13, j + 20, k + 37, KCore.ForbiddenBrick, 0);
		this.setBlock(world, i + 13, j + 20, k + 38, KCore.ForbiddenBrick, 0);
		this.setBlock(world, i + 13, j + 21, k + 3, KCore.ForbiddenBrick, 0);
		this.setBlock(world, i + 13, j + 21, k + 4, KCore.ForbiddenBrick, 0);
		this.setBlock(world, i + 13, j + 21, k + 5, KCore.ForbiddenBrick, 0);
		this.setBlock(world, i + 13, j + 21, k + 6, KCore.ForbiddenBrick, 0);
		this.setBlock(world, i + 13, j + 21, k + 7, KCore.ForbiddenBrick, 0);
		this.setBlock(world, i + 13, j + 21, k + 8, KCore.ForbiddenBrick, 0);
		this.setBlock(world, i + 13, j + 21, k + 9, KCore.ForbiddenBrick, 0);
		this.setBlock(world, i + 13, j + 21, k + 10, KCore.ForbiddenBrick, 0);
		this.setBlock(world, i + 13, j + 21, k + 11, KCore.ForbiddenBrick, 0);
		this.setBlock(world, i + 13, j + 21, k + 12, KCore.ForbiddenBrick, 0);
		this.setBlock(world, i + 13, j + 21, k + 13, KCore.ForbiddenBrick, 0);
		this.setBlock(world, i + 13, j + 21, k + 14, KCore.ForbiddenBrick, 0);
		this.setBlock(world, i + 13, j + 21, k + 15, KCore.ForbiddenBrick, 0);
		this.setBlock(world, i + 13, j + 21, k + 16, KCore.ForbiddenBrick, 0);
		this.setBlock(world, i + 13, j + 21, k + 17, KCore.ForbiddenBrick, 0);
		this.setBlock(world, i + 13, j + 21, k + 18, KCore.ForbiddenBrick, 0);
		this.setBlock(world, i + 13, j + 21, k + 19, KCore.ForbiddenBrick, 0);
		this.setBlock(world, i + 13, j + 21, k + 20, KCore.ForbiddenBrick, 0);
		this.setBlock(world, i + 13, j + 21, k + 21, KCore.ForbiddenBrick, 0);
		this.setBlock(world, i + 13, j + 21, k + 22, KCore.ForbiddenBrick, 0);
		this.setBlock(world, i + 13, j + 21, k + 23, KCore.ForbiddenBrick, 0);
		this.setBlock(world, i + 13, j + 21, k + 24, KCore.ForbiddenBrick, 0);
		this.setBlock(world, i + 13, j + 21, k + 25, KCore.ForbiddenBrick, 0);
		this.setBlock(world, i + 13, j + 21, k + 26, KCore.ForbiddenBrick, 0);
		this.setBlock(world, i + 13, j + 21, k + 27, KCore.ForbiddenBrick, 0);
		this.setBlock(world, i + 13, j + 21, k + 28, KCore.ForbiddenBrick, 0);
		this.setBlock(world, i + 13, j + 21, k + 29, KCore.ForbiddenBrick, 0);
		this.setBlock(world, i + 13, j + 21, k + 30, KCore.ForbiddenBrick, 0);
		this.setBlock(world, i + 13, j + 21, k + 31, KCore.ForbiddenBrick, 0);
		this.setBlock(world, i + 13, j + 21, k + 32, KCore.ForbiddenBrick, 0);
		this.setBlock(world, i + 13, j + 21, k + 33, KCore.ForbiddenBrick, 0);
		this.setBlock(world, i + 13, j + 21, k + 34, KCore.ForbiddenBrick, 0);
		this.setBlock(world, i + 13, j + 21, k + 35, KCore.ForbiddenBrick, 0);
		this.setBlock(world, i + 13, j + 21, k + 36, KCore.ForbiddenBrick, 0);
		this.setBlock(world, i + 13, j + 21, k + 37, KCore.ForbiddenBrick, 0);
		this.setBlock(world, i + 13, j + 21, k + 38, KCore.ForbiddenBrick, 0);
		this.setBlock(world, i + 14, j + 0, k + 0, KCore.ForbiddenRockStairs, 0);
		this.setBlock(world, i + 14, j + 0, k + 3, KCore.ForbiddenRock, 0);
		this.setBlock(world, i + 14, j + 0, k + 4, KCore.ForbiddenRock, 0);
		this.setBlock(world, i + 14, j + 0, k + 5, KCore.ForbiddenRock, 0);
		this.setBlock(world, i + 14, j + 0, k + 6, KCore.ForbiddenRock, 0);
		this.setBlock(world, i + 14, j + 0, k + 7, KCore.ForbiddenRock, 0);
		this.setBlock(world, i + 14, j + 0, k + 8, KCore.ForbiddenRock, 0);
		this.setBlock(world, i + 14, j + 0, k + 9, KCore.ForbiddenRock, 0);
		this.setBlock(world, i + 14, j + 0, k + 10, KCore.ForbiddenRock, 0);
		this.setBlock(world, i + 14, j + 0, k + 11, KCore.ForbiddenRock, 0);
		this.setBlock(world, i + 14, j + 0, k + 12, KCore.ForbiddenRock, 0);
		this.setBlock(world, i + 14, j + 0, k + 13, KCore.ForbiddenRock, 0);
		this.setBlock(world, i + 14, j + 0, k + 14, KCore.ForbiddenRock, 0);
		this.setBlock(world, i + 14, j + 0, k + 15, KCore.ForbiddenRock, 0);
		this.setBlock(world, i + 14, j + 0, k + 16, KCore.ForbiddenRock, 0);
		this.setBlock(world, i + 14, j + 0, k + 17, KCore.ForbiddenRock, 0);
		this.setBlock(world, i + 14, j + 0, k + 18, KCore.ForbiddenRock, 0);
		this.setBlock(world, i + 14, j + 0, k + 19, KCore.ForbiddenRock, 0);
		this.setBlock(world, i + 14, j + 0, k + 20, KCore.ForbiddenRock, 0);
		this.setBlock(world, i + 14, j + 0, k + 21, KCore.ForbiddenRock, 0);
		this.setBlock(world, i + 14, j + 0, k + 22, KCore.ForbiddenRock, 0);
		this.setBlock(world, i + 14, j + 0, k + 23, KCore.ForbiddenRock, 0);
		this.setBlock(world, i + 14, j + 0, k + 24, KCore.ForbiddenRock, 0);
		this.setBlock(world, i + 14, j + 0, k + 25, KCore.ForbiddenRock, 0);
		this.setBlock(world, i + 14, j + 0, k + 26, KCore.ForbiddenRock, 0);
		this.setBlock(world, i + 14, j + 0, k + 27, KCore.ForbiddenRock, 0);
		this.setBlock(world, i + 14, j + 0, k + 28, KCore.ForbiddenRock, 0);
		this.setBlock(world, i + 14, j + 0, k + 29, KCore.ForbiddenRock, 0);
		this.setBlock(world, i + 14, j + 0, k + 30, KCore.ForbiddenRock, 0);
		this.setBlock(world, i + 14, j + 0, k + 31, KCore.ForbiddenRock, 0);
		this.setBlock(world, i + 14, j + 0, k + 32, KCore.ForbiddenRock, 0);
		this.setBlock(world, i + 14, j + 0, k + 33, KCore.ForbiddenRock, 0);
		this.setBlock(world, i + 14, j + 0, k + 34, KCore.ForbiddenRock, 0);
		this.setBlock(world, i + 14, j + 0, k + 35, KCore.ForbiddenRock, 0);
		this.setBlock(world, i + 14, j + 0, k + 36, KCore.ForbiddenRock, 0);
		this.setBlock(world, i + 14, j + 0, k + 37, KCore.ForbiddenRock, 0);
		this.setBlock(world, i + 14, j + 0, k + 38, KCore.ForbiddenRock, 0);
		this.setBlock(world, i + 14, j + 1, k + 3, KCore.ForbiddenRock, 0);
		this.setBlock(world, i + 14, j + 1, k + 4, KCore.ForbiddenRock, 0);
		this.setBlock(world, i + 14, j + 1, k + 5, KCore.ForbiddenRock, 0);
		this.setBlock(world, i + 14, j + 1, k + 6, KCore.ForbiddenRock, 0);
		this.setBlock(world, i + 14, j + 1, k + 7, KCore.ForbiddenRock, 0);
		this.setBlock(world, i + 14, j + 1, k + 8, KCore.ForbiddenRock, 0);
		this.setBlock(world, i + 14, j + 1, k + 9, KCore.ForbiddenRock, 0);
		this.setBlock(world, i + 14, j + 1, k + 10, KCore.ForbiddenRock, 0);
		this.setBlock(world, i + 14, j + 1, k + 11, KCore.ForbiddenRock, 0);
		this.setBlock(world, i + 14, j + 1, k + 12, KCore.ForbiddenRock, 0);
		this.setBlock(world, i + 14, j + 1, k + 13, KCore.ForbiddenRock, 0);
		this.setBlock(world, i + 14, j + 1, k + 14, KCore.ForbiddenRock, 0);
		this.setBlock(world, i + 14, j + 1, k + 15, KCore.ForbiddenRock, 0);
		this.setBlock(world, i + 14, j + 1, k + 16, KCore.ForbiddenRock, 0);
		this.setBlock(world, i + 14, j + 1, k + 17, KCore.ForbiddenRock, 0);
		this.setBlock(world, i + 14, j + 1, k + 18, KCore.ForbiddenRock, 0);
		this.setBlock(world, i + 14, j + 1, k + 19, KCore.ForbiddenRock, 0);
		this.setBlock(world, i + 14, j + 1, k + 20, KCore.ForbiddenRock, 0);
		this.setBlock(world, i + 14, j + 1, k + 21, KCore.ForbiddenRock, 0);
		this.setBlock(world, i + 14, j + 1, k + 22, KCore.ForbiddenRock, 0);
		this.setBlock(world, i + 14, j + 1, k + 23, KCore.ForbiddenRock, 0);
		this.setBlock(world, i + 14, j + 1, k + 24, KCore.ForbiddenRock, 0);
		this.setBlock(world, i + 14, j + 1, k + 25, KCore.ForbiddenRock, 0);
		this.setBlock(world, i + 14, j + 1, k + 26, KCore.ForbiddenRock, 0);
		this.setBlock(world, i + 14, j + 1, k + 27, KCore.ForbiddenRock, 0);
		this.setBlock(world, i + 14, j + 1, k + 28, KCore.ForbiddenRock, 0);
		this.setBlock(world, i + 14, j + 1, k + 29, KCore.ForbiddenRock, 0);
		this.setBlock(world, i + 14, j + 1, k + 30, KCore.ForbiddenRock, 0);
		this.setBlock(world, i + 14, j + 1, k + 31, KCore.ForbiddenRock, 0);
		this.setBlock(world, i + 14, j + 1, k + 32, KCore.ForbiddenRock, 0);
		this.setBlock(world, i + 14, j + 1, k + 33, KCore.ForbiddenRock, 0);
		this.setBlock(world, i + 14, j + 1, k + 34, KCore.ForbiddenRock, 0);
		this.setBlock(world, i + 14, j + 1, k + 35, KCore.ForbiddenRock, 0);
		this.setBlock(world, i + 14, j + 1, k + 36, KCore.ForbiddenRock, 0);
		this.setBlock(world, i + 14, j + 1, k + 37, KCore.ForbiddenRock, 0);
		this.setBlock(world, i + 14, j + 1, k + 38, KCore.ForbiddenRock, 0);
		this.setBlock(world, i + 14, j + 2, k + 3, KCore.ForbiddenRock, 0);
		this.setBlock(world, i + 14, j + 2, k + 4, KCore.ForbiddenRock, 0);
		this.setBlock(world, i + 14, j + 2, k + 5, KCore.ForbiddenRock, 0);
		this.setBlock(world, i + 14, j + 2, k + 6, KCore.ForbiddenRock, 0);
		this.setBlock(world, i + 14, j + 2, k + 7, KCore.ForbiddenRock, 0);
		this.setBlock(world, i + 14, j + 2, k + 8, KCore.ForbiddenRock, 0);
		this.setBlock(world, i + 14, j + 2, k + 9, KCore.ForbiddenRock, 0);
		this.setBlock(world, i + 14, j + 2, k + 10, KCore.ForbiddenRock, 0);
		this.setBlock(world, i + 14, j + 2, k + 11, KCore.ForbiddenRock, 0);
		this.setBlock(world, i + 14, j + 2, k + 12, KCore.ForbiddenRock, 0);
		this.setBlock(world, i + 14, j + 2, k + 13, KCore.ForbiddenRock, 0);
		this.setBlock(world, i + 14, j + 2, k + 14, KCore.ForbiddenRock, 0);
		this.setBlock(world, i + 14, j + 2, k + 15, KCore.ForbiddenRock, 0);
		this.setBlock(world, i + 14, j + 2, k + 16, KCore.ForbiddenRock, 0);
		this.setBlock(world, i + 14, j + 2, k + 17, KCore.ForbiddenRock, 0);
		this.setBlock(world, i + 14, j + 2, k + 18, KCore.ForbiddenRock, 0);
		this.setBlock(world, i + 14, j + 2, k + 19, KCore.ForbiddenTrap, 0);
		this.setBlock(world, i + 14, j + 2, k + 20, KCore.ForbiddenRock, 0);
		this.setBlock(world, i + 14, j + 2, k + 21, KCore.ForbiddenRock, 0);
		this.setBlock(world, i + 14, j + 2, k + 22, KCore.ForbiddenTrap, 0);
		this.setBlock(world, i + 14, j + 2, k + 23, KCore.ForbiddenTrap, 0);
		this.setBlock(world, i + 14, j + 2, k + 24, KCore.ForbiddenRock, 0);
		this.setBlock(world, i + 14, j + 2, k + 25, KCore.ForbiddenTrap, 0);
		this.setBlock(world, i + 14, j + 2, k + 26, KCore.ForbiddenRock, 0);
		this.setBlock(world, i + 14, j + 2, k + 27, KCore.ForbiddenRock, 0);
		this.setBlock(world, i + 14, j + 2, k + 28, KCore.ForbiddenRock, 0);
		this.setBlock(world, i + 14, j + 2, k + 29, KCore.ForbiddenRock, 0);
		this.setBlock(world, i + 14, j + 2, k + 30, KCore.ForbiddenRock, 0);
		this.setBlock(world, i + 14, j + 2, k + 31, KCore.ForbiddenRock, 0);
		this.setBlock(world, i + 14, j + 2, k + 32, KCore.ForbiddenRock, 0);
		this.setBlock(world, i + 14, j + 2, k + 33, KCore.ForbiddenRock, 0);
		this.setBlock(world, i + 14, j + 2, k + 34, KCore.ForbiddenRock, 0);
		this.setBlock(world, i + 14, j + 2, k + 35, KCore.ForbiddenRock, 0);
		this.setBlock(world, i + 14, j + 2, k + 36, KCore.ForbiddenRock, 0);
		this.setBlock(world, i + 14, j + 2, k + 37, KCore.ForbiddenRock, 0);
		this.setBlock(world, i + 14, j + 2, k + 38, KCore.ForbiddenRock, 0);
		this.setBlock(world, i + 14, j + 3, k + 3, KCore.ForbiddenBrick, 0);
		this.setBlock(world, i + 14, j + 3, k + 6, KCore.ForbiddenBrick, 0);
		this.setBlock(world, i + 14, j + 3, k + 7, KCore.ForbiddenBrick, 0);
		this.setBlock(world, i + 14, j + 3, k + 8, KCore.ForbiddenBrick, 0);
		this.setBlock(world, i + 14, j + 3, k + 9, KCore.ForbiddenBrick, 0);
		this.setBlock(world, i + 14, j + 3, k + 10, KCore.ForbiddenBrick, 0);
		this.setBlock(world, i + 14, j + 3, k + 11, KCore.ForbiddenBrick, 0);
		this.setBlock(world, i + 14, j + 3, k + 12, KCore.ForbiddenBrick, 0);
		this.setBlock(world, i + 14, j + 3, k + 13, KCore.ForbiddenBrick, 0);
		this.setBlock(world, i + 14, j + 3, k + 14, KCore.ForbiddenBrick, 0);
		this.setBlock(world, i + 14, j + 3, k + 15, KCore.ForbiddenBrick, 0);
		this.setBlock(world, i + 14, j + 3, k + 16, KCore.ForbiddenBrick, 0);
		this.setBlock(world, i + 14, j + 3, k + 17, KCore.ForbiddenBrick, 0);
		this.setBlock(world, i + 14, j + 3, k + 27, KCore.ForbiddenBrick, 0);
		this.setBlock(world, i + 14, j + 3, k + 28, KCore.ForbiddenBrick, 0);
		this.setBlock(world, i + 14, j + 3, k + 29, KCore.ForbiddenBrick, 0);
		this.setBlock(world, i + 14, j + 3, k + 30, KCore.ForbiddenBrick, 0);
		this.setBlock(world, i + 14, j + 3, k + 31, KCore.ForbiddenBrick, 0);
		this.setBlock(world, i + 14, j + 3, k + 32, KCore.ForbiddenBrick, 0);
		this.setBlock(world, i + 14, j + 3, k + 33, KCore.ForbiddenBrick, 0);
		this.setBlock(world, i + 14, j + 3, k + 34, KCore.ForbiddenBrick, 0);
		this.setBlock(world, i + 14, j + 3, k + 35, KCore.ForbiddenBrick, 0);
		this.setBlock(world, i + 14, j + 3, k + 36, KCore.ForbiddenBrick, 0);
		this.setBlock(world, i + 14, j + 3, k + 37, KCore.ForbiddenBrick, 0);
		this.setBlock(world, i + 14, j + 3, k + 38, KCore.ForbiddenBrick, 0);
		this.setBlock(world, i + 14, j + 4, k + 3, KCore.ForbiddenBrick, 0);
		this.setBlock(world, i + 14, j + 4, k + 6, KCore.ForbiddenBrick, 0);
		this.setBlock(world, i + 14, j + 4, k + 7, KCore.ForbiddenBrick, 0);
		this.setBlock(world, i + 14, j + 4, k + 8, KCore.ForbiddenBrick, 0);
		this.setBlock(world, i + 14, j + 4, k + 9, KCore.ForbiddenBrick, 0);
		this.setBlock(world, i + 14, j + 4, k + 10, KCore.ForbiddenBrick, 0);
		this.setBlock(world, i + 14, j + 4, k + 11, KCore.ForbiddenBrick, 0);
		this.setBlock(world, i + 14, j + 4, k + 12, KCore.ForbiddenBrick, 0);
		this.setBlock(world, i + 14, j + 4, k + 13, KCore.ForbiddenBrick, 0);
		this.setBlock(world, i + 14, j + 4, k + 14, KCore.ForbiddenBrick, 0);
		this.setBlock(world, i + 14, j + 4, k + 15, KCore.ForbiddenBrick, 0);
		this.setBlock(world, i + 14, j + 4, k + 16, KCore.ForbiddenBrick, 0);
		this.setBlock(world, i + 14, j + 4, k + 17, KCore.ForbiddenBrick, 0);
		this.setBlock(world, i + 14, j + 4, k + 27, KCore.ForbiddenBrick, 0);
		this.setBlock(world, i + 14, j + 4, k + 28, KCore.ForbiddenBrick, 0);
		this.setBlock(world, i + 14, j + 4, k + 29, KCore.ForbiddenBrick, 0);
		this.setBlock(world, i + 14, j + 4, k + 30, KCore.ForbiddenBrick, 0);
		this.setBlock(world, i + 14, j + 4, k + 31, KCore.ForbiddenBrick, 0);
		this.setBlock(world, i + 14, j + 4, k + 32, KCore.ForbiddenBrick, 0);
		this.setBlock(world, i + 14, j + 4, k + 33, KCore.ForbiddenBrick, 0);
		this.setBlock(world, i + 14, j + 4, k + 34, KCore.ForbiddenBrick, 0);
		this.setBlock(world, i + 14, j + 4, k + 35, KCore.ForbiddenBrick, 0);
		this.setBlock(world, i + 14, j + 4, k + 36, KCore.ForbiddenBrick, 0);
		this.setBlock(world, i + 14, j + 4, k + 37, KCore.ForbiddenBrick, 0);
		this.setBlock(world, i + 14, j + 4, k + 38, KCore.ForbiddenBrick, 0);
		this.setBlock(world, i + 14, j + 5, k + 3, KCore.ForbiddenBrick, 0);
		this.setBlock(world, i + 14, j + 5, k + 4, KCore.ForbiddenBrick, 0);
		this.setBlock(world, i + 14, j + 5, k + 5, KCore.ForbiddenBrick, 0);
		this.setBlock(world, i + 14, j + 5, k + 6, KCore.ForbiddenBrick, 0);
		this.setBlock(world, i + 14, j + 5, k + 7, KCore.ForbiddenBrick, 0);
		this.setBlock(world, i + 14, j + 5, k + 8, KCore.ForbiddenBrick, 0);
		this.setBlock(world, i + 14, j + 5, k + 9, KCore.ForbiddenBrick, 0);
		this.setBlock(world, i + 14, j + 5, k + 10, KCore.ForbiddenBrick, 0);
		this.setBlock(world, i + 14, j + 5, k + 11, KCore.ForbiddenBrick, 0);
		this.setBlock(world, i + 14, j + 5, k + 12, KCore.ForbiddenBrick, 0);
		this.setBlock(world, i + 14, j + 5, k + 13, KCore.ForbiddenBrick, 0);
		this.setBlock(world, i + 14, j + 5, k + 14, KCore.ForbiddenBrick, 0);
		this.setBlock(world, i + 14, j + 5, k + 15, KCore.ForbiddenBrick, 0);
		this.setBlock(world, i + 14, j + 5, k + 16, KCore.ForbiddenBrick, 0);
		this.setBlock(world, i + 14, j + 5, k + 17, KCore.ForbiddenBrick, 0);
		this.setBlock(world, i + 14, j + 5, k + 27, KCore.ForbiddenBrick, 0);
		this.setBlock(world, i + 14, j + 5, k + 28, KCore.ForbiddenBrick, 0);
		this.setBlock(world, i + 14, j + 5, k + 29, KCore.ForbiddenBrick, 0);
		this.setBlock(world, i + 14, j + 5, k + 30, KCore.ForbiddenBrick, 0);
		this.setBlock(world, i + 14, j + 5, k + 31, KCore.ForbiddenBrick, 0);
		this.setBlock(world, i + 14, j + 5, k + 32, KCore.ForbiddenBrick, 0);
		this.setBlock(world, i + 14, j + 5, k + 33, KCore.ForbiddenBrick, 0);
		this.setBlock(world, i + 14, j + 5, k + 34, KCore.ForbiddenBrick, 0);
		this.setBlock(world, i + 14, j + 5, k + 35, KCore.ForbiddenBrick, 0);
		this.setBlock(world, i + 14, j + 5, k + 36, KCore.ForbiddenBrick, 0);
		this.setBlock(world, i + 14, j + 5, k + 37, KCore.ForbiddenBrick, 0);
		this.setBlock(world, i + 14, j + 5, k + 38, KCore.ForbiddenBrick, 0);
		this.setBlock(world, i + 14, j + 6, k + 3, KCore.ForbiddenBrick, 0);
		this.setBlock(world, i + 14, j + 6, k + 4, KCore.ForbiddenBrick, 0);
		this.setBlock(world, i + 14, j + 6, k + 5, KCore.ForbiddenBrick, 0);
		this.setBlock(world, i + 14, j + 6, k + 6, KCore.ForbiddenBrick, 0);
		this.setBlock(world, i + 14, j + 6, k + 7, KCore.ForbiddenBrick, 0);
		this.setBlock(world, i + 14, j + 6, k + 8, KCore.ForbiddenBrick, 0);
		this.setBlock(world, i + 14, j + 6, k + 9, KCore.ForbiddenBrick, 0);
		this.setBlock(world, i + 14, j + 6, k + 10, KCore.ForbiddenBrick, 0);
		this.setBlock(world, i + 14, j + 6, k + 11, KCore.ForbiddenBrick, 0);
		this.setBlock(world, i + 14, j + 6, k + 12, KCore.ForbiddenBrick, 0);
		this.setBlock(world, i + 14, j + 6, k + 13, KCore.ForbiddenBrick, 0);
		this.setBlock(world, i + 14, j + 6, k + 14, KCore.ForbiddenBrick, 0);
		this.setBlock(world, i + 14, j + 6, k + 15, KCore.ForbiddenBrick, 0);
		this.setBlock(world, i + 14, j + 6, k + 16, KCore.ForbiddenBrick, 0);
		this.setBlock(world, i + 14, j + 6, k + 17, KCore.ForbiddenBrick, 0);
		this.setBlock(world, i + 14, j + 6, k + 27, KCore.ForbiddenBrick, 0);
		this.setBlock(world, i + 14, j + 6, k + 28, KCore.ForbiddenBrick, 0);
		this.setBlock(world, i + 14, j + 6, k + 29, KCore.ForbiddenBrick, 0);
		this.setBlock(world, i + 14, j + 6, k + 30, KCore.ForbiddenBrick, 0);
		this.setBlock(world, i + 14, j + 6, k + 31, KCore.ForbiddenBrick, 0);
		this.setBlock(world, i + 14, j + 6, k + 32, KCore.ForbiddenBrick, 0);
		this.setBlock(world, i + 14, j + 6, k + 33, KCore.ForbiddenBrick, 0);
		this.setBlock(world, i + 14, j + 6, k + 34, KCore.ForbiddenBrick, 0);
		this.setBlock(world, i + 14, j + 6, k + 35, KCore.ForbiddenBrick, 0);
		this.setBlock(world, i + 14, j + 6, k + 36, KCore.ForbiddenBrick, 0);
		this.setBlock(world, i + 14, j + 6, k + 37, KCore.ForbiddenBrick, 0);
		this.setBlock(world, i + 14, j + 6, k + 38, KCore.ForbiddenBrick, 0);
		this.setBlock(world, i + 14, j + 7, k + 3, KCore.ForbiddenBrick, 0);
		this.setBlock(world, i + 14, j + 7, k + 4, KCore.ForbiddenBrick, 0);
		this.setBlock(world, i + 14, j + 7, k + 5, KCore.ForbiddenRock, 0);
		this.setBlock(world, i + 14, j + 7, k + 6, KCore.ForbiddenRock, 0);
		this.setBlock(world, i + 14, j + 7, k + 7, KCore.ForbiddenBrick, 0);
		this.setBlock(world, i + 14, j + 7, k + 8, KCore.ForbiddenBrick, 0);
		this.setBlock(world, i + 14, j + 7, k + 9, KCore.ForbiddenBrick, 0);
		this.setBlock(world, i + 14, j + 7, k + 10, KCore.ForbiddenBrick, 0);
		this.setBlock(world, i + 14, j + 7, k + 11, KCore.ForbiddenBrick, 0);
		this.setBlock(world, i + 14, j + 7, k + 12, KCore.ForbiddenBrick, 0);
		this.setBlock(world, i + 14, j + 7, k + 13, KCore.ForbiddenBrick, 0);
		this.setBlock(world, i + 14, j + 7, k + 16, KCore.ForbiddenBrick, 0);
		this.setBlock(world, i + 14, j + 7, k + 17, KCore.ForbiddenBrick, 0);
		this.setBlock(world, i + 14, j + 7, k + 27, KCore.ForbiddenBrick, 0);
		this.setBlock(world, i + 14, j + 7, k + 28, KCore.ForbiddenBrick, 0);
		this.setBlock(world, i + 14, j + 7, k + 29, KCore.ForbiddenBrick, 0);
		this.setBlock(world, i + 14, j + 7, k + 30, KCore.ForbiddenBrick, 0);
		this.setBlock(world, i + 14, j + 7, k + 31, KCore.ForbiddenBrick, 0);
		this.setBlock(world, i + 14, j + 7, k + 32, KCore.ForbiddenBrick, 0);
		this.setBlock(world, i + 14, j + 7, k + 33, KCore.ForbiddenBrick, 0);
		this.setBlock(world, i + 14, j + 7, k + 34, KCore.ForbiddenBrick, 0);
		this.setBlock(world, i + 14, j + 7, k + 35, KCore.ForbiddenBrick, 0);
		this.setBlock(world, i + 14, j + 7, k + 36, KCore.ForbiddenBrick, 0);
		this.setBlock(world, i + 14, j + 7, k + 37, KCore.ForbiddenBrick, 0);
		this.setBlock(world, i + 14, j + 7, k + 38, KCore.ForbiddenBrick, 0);
		this.setBlock(world, i + 14, j + 8, k + 3, KCore.ForbiddenBrick, 0);
		this.setBlock(world, i + 14, j + 8, k + 4, KCore.ForbiddenBrick, 0);
		this.setBlock(world, i + 14, j + 8, k + 5, KCore.ForbiddenRock, 0);
		this.setBlock(world, i + 14, j + 8, k + 6, KCore.ForbiddenRock, 0);
		this.setBlock(world, i + 14, j + 8, k + 7, KCore.ForbiddenBrick, 0);
		this.setBlock(world, i + 14, j + 8, k + 8, KCore.ForbiddenBrick, 0);
		this.setBlock(world, i + 14, j + 8, k + 9, KCore.ForbiddenBrick, 0);
		this.setBlock(world, i + 14, j + 8, k + 10, KCore.ForbiddenBrick, 0);
		this.setBlock(world, i + 14, j + 8, k + 11, KCore.ForbiddenBrick, 0);
		this.setBlock(world, i + 14, j + 8, k + 12, KCore.ForbiddenBrick, 0);
		this.setBlock(world, i + 14, j + 8, k + 13, KCore.ForbiddenBrick, 0);
		this.setBlock(world, i + 14, j + 8, k + 16, KCore.ForbiddenBrick, 0);
		this.setBlock(world, i + 14, j + 8, k + 17, KCore.ForbiddenBrick, 0);
		this.setBlock(world, i + 14, j + 8, k + 18, KCore.ForbiddenBrick, 0);
		this.setBlock(world, i + 14, j + 8, k + 19, KCore.ForbiddenBrick, 0);
		this.setBlock(world, i + 14, j + 8, k + 20, KCore.ForbiddenBrick, 0);
		this.setBlock(world, i + 14, j + 8, k + 21, KCore.ForbiddenBrick, 0);
		this.setBlock(world, i + 14, j + 8, k + 22, KCore.ForbiddenBrick, 0);
		this.setBlock(world, i + 14, j + 8, k + 23, KCore.ForbiddenBrick, 0);
		this.setBlock(world, i + 14, j + 8, k + 24, KCore.ForbiddenBrick, 0);
		this.setBlock(world, i + 14, j + 8, k + 25, KCore.ForbiddenBrick, 0);
		this.setBlock(world, i + 14, j + 8, k + 26, KCore.ForbiddenBrick, 0);
		this.setBlock(world, i + 14, j + 8, k + 27, KCore.ForbiddenBrick, 0);
		this.setBlock(world, i + 14, j + 8, k + 28, KCore.ForbiddenBrick, 0);
		this.setBlock(world, i + 14, j + 8, k + 29, KCore.ForbiddenBrick, 0);
		this.setBlock(world, i + 14, j + 8, k + 30, KCore.ForbiddenBrick, 0);
		this.setBlock(world, i + 14, j + 8, k + 31, KCore.ForbiddenBrick, 0);
		this.setBlock(world, i + 14, j + 8, k + 32, KCore.ForbiddenBrick, 0);
		this.setBlock(world, i + 14, j + 8, k + 33, KCore.ForbiddenBrick, 0);
		this.setBlock(world, i + 14, j + 8, k + 34, KCore.ForbiddenBrick, 0);
		this.setBlock(world, i + 14, j + 8, k + 35, KCore.ForbiddenBrick, 0);
		this.setBlock(world, i + 14, j + 8, k + 36, KCore.ForbiddenBrick, 0);
		this.setBlock(world, i + 14, j + 8, k + 37, KCore.ForbiddenBrick, 0);
		this.setBlock(world, i + 14, j + 8, k + 38, KCore.ForbiddenBrick, 0);
		this.setBlock(world, i + 14, j + 9, k + 3, KCore.ForbiddenBrick, 0);
		this.setBlock(world, i + 14, j + 9, k + 4, KCore.ForbiddenBrick, 0);
		this.setBlock(world, i + 14, j + 9, k + 5, KCore.ForbiddenRock, 0);
		this.setBlock(world, i + 14, j + 9, k + 6, KCore.ForbiddenRock, 0);
		this.setBlock(world, i + 14, j + 9, k + 7, KCore.ForbiddenBrick, 0);
		this.setBlock(world, i + 14, j + 9, k + 8, KCore.ForbiddenBrick, 0);
		this.setBlock(world, i + 14, j + 9, k + 9, KCore.ForbiddenBrick, 0);
		this.setBlock(world, i + 14, j + 9, k + 10, KCore.ForbiddenBrick, 0);
		this.setBlock(world, i + 14, j + 9, k + 11, KCore.ForbiddenBrick, 0);
		this.setBlock(world, i + 14, j + 9, k + 12, KCore.ForbiddenBrick, 0);
		this.setBlock(world, i + 14, j + 9, k + 13, KCore.ForbiddenBrick, 0);
		this.setBlock(world, i + 14, j + 9, k + 14, KCore.ForbiddenRock, 0);
		this.setBlock(world, i + 14, j + 9, k + 15, KCore.ForbiddenRock, 0);
		this.setBlock(world, i + 14, j + 9, k + 16, KCore.ForbiddenBrick, 0);
		this.setBlock(world, i + 14, j + 9, k + 28, KCore.ForbiddenBrick, 0);
		this.setBlock(world, i + 14, j + 9, k + 29, KCore.ForbiddenBrick, 0);
		this.setBlock(world, i + 14, j + 9, k + 30, KCore.ForbiddenBrick, 0);
		this.setBlock(world, i + 14, j + 9, k + 31, KCore.ForbiddenBrick, 0);
		this.setBlock(world, i + 14, j + 9, k + 32, KCore.ForbiddenBrick, 0);
		this.setBlock(world, i + 14, j + 9, k + 33, KCore.ForbiddenBrick, 0);
		this.setBlock(world, i + 14, j + 9, k + 34, KCore.ForbiddenBrick, 0);
		this.setBlock(world, i + 14, j + 9, k + 35, KCore.ForbiddenBrick, 0);
		this.setBlock(world, i + 14, j + 9, k + 36, KCore.ForbiddenBrick, 0);
		this.setBlock(world, i + 14, j + 9, k + 37, KCore.ForbiddenBrick, 0);
		this.setBlock(world, i + 14, j + 9, k + 38, KCore.ForbiddenBrick, 0);
		this.setBlock(world, i + 14, j + 10, k + 3, KCore.ForbiddenBrick, 0);
		this.setBlock(world, i + 14, j + 10, k + 4, KCore.ForbiddenBrick, 0);
		this.setBlock(world, i + 14, j + 10, k + 5, KCore.ForbiddenRock, 0);
		this.setBlock(world, i + 14, j + 10, k + 6, KCore.ForbiddenRock, 0);
		this.setBlock(world, i + 14, j + 10, k + 7, KCore.ForbiddenBrick, 0);
		this.setBlock(world, i + 14, j + 10, k + 8, KCore.ForbiddenBrick, 0);
		this.setBlock(world, i + 14, j + 10, k + 9, KCore.ForbiddenBrick, 0);
		this.setBlock(world, i + 14, j + 10, k + 10, KCore.ForbiddenBrick, 0);
		this.setBlock(world, i + 14, j + 10, k + 11, KCore.ForbiddenBrick, 0);
		this.setBlock(world, i + 14, j + 10, k + 12, KCore.ForbiddenBrick, 0);
		this.setBlock(world, i + 14, j + 10, k + 13, KCore.ForbiddenBrick, 0);
		this.setBlock(world, i + 14, j + 10, k + 16, KCore.ForbiddenBrick, 0);
		this.setBlock(world, i + 14, j + 10, k + 28, KCore.ForbiddenBrick, 0);
		this.setBlock(world, i + 14, j + 10, k + 29, KCore.ForbiddenBrick, 0);
		this.setBlock(world, i + 14, j + 10, k + 30, KCore.ForbiddenBrick, 0);
		this.setBlock(world, i + 14, j + 10, k + 31, KCore.ForbiddenBrick, 0);
		this.setBlock(world, i + 14, j + 10, k + 32, KCore.ForbiddenBrick, 0);
		this.setBlock(world, i + 14, j + 10, k + 33, KCore.ForbiddenBrick, 0);
		this.setBlock(world, i + 14, j + 10, k + 34, KCore.ForbiddenBrick, 0);
		this.setBlock(world, i + 14, j + 10, k + 35, KCore.ForbiddenBrick, 0);
		this.setBlock(world, i + 14, j + 10, k + 36, KCore.ForbiddenBrick, 0);
		this.setBlock(world, i + 14, j + 10, k + 37, KCore.ForbiddenBrick, 0);
		this.setBlock(world, i + 14, j + 10, k + 38, KCore.ForbiddenBrick, 0);
		this.setBlock(world, i + 14, j + 11, k + 3, KCore.ForbiddenBrick, 0);
		this.setBlock(world, i + 14, j + 11, k + 4, KCore.ForbiddenBrick, 0);
		this.setBlock(world, i + 14, j + 11, k + 5, KCore.ForbiddenRock, 0);
		this.setBlock(world, i + 14, j + 11, k + 6, KCore.ForbiddenRock, 0);
		this.setBlock(world, i + 14, j + 11, k + 7, KCore.ForbiddenBrick, 0);
		this.setBlock(world, i + 14, j + 11, k + 8, KCore.ForbiddenBrick, 0);
		this.setBlock(world, i + 14, j + 11, k + 9, KCore.ForbiddenBrick, 0);
		this.setBlock(world, i + 14, j + 11, k + 10, KCore.ForbiddenBrick, 0);
		this.setBlock(world, i + 14, j + 11, k + 11, KCore.ForbiddenBrick, 0);
		this.setBlock(world, i + 14, j + 11, k + 12, KCore.ForbiddenBrick, 0);
		this.setBlock(world, i + 14, j + 11, k + 13, KCore.ForbiddenBrick, 0);
		this.setBlock(world, i + 14, j + 11, k + 16, KCore.ForbiddenBrick, 0);
		this.setBlock(world, i + 14, j + 11, k + 28, KCore.ForbiddenBrick, 0);
		this.setBlock(world, i + 14, j + 11, k + 29, KCore.ForbiddenBrick, 0);
		this.setBlock(world, i + 14, j + 11, k + 30, KCore.ForbiddenBrick, 0);
		this.setBlock(world, i + 14, j + 11, k + 31, KCore.ForbiddenBrick, 0);
		this.setBlock(world, i + 14, j + 11, k + 32, KCore.ForbiddenBrick, 0);
		this.setBlock(world, i + 14, j + 11, k + 33, KCore.ForbiddenBrick, 0);
		this.setBlock(world, i + 14, j + 11, k + 34, KCore.ForbiddenBrick, 0);
		this.setBlock(world, i + 14, j + 11, k + 35, KCore.ForbiddenBrick, 0);
		this.setBlock(world, i + 14, j + 11, k + 36, KCore.ForbiddenBrick, 0);
		this.setBlock(world, i + 14, j + 11, k + 37, KCore.ForbiddenBrick, 0);
		this.setBlock(world, i + 14, j + 11, k + 38, KCore.ForbiddenBrick, 0);
		this.setBlock(world, i + 14, j + 12, k + 3, KCore.ForbiddenBrick, 0);
		this.setBlock(world, i + 14, j + 12, k + 4, KCore.ForbiddenBrick, 0);
		this.setBlock(world, i + 14, j + 12, k + 5, KCore.ForbiddenBrickStairs, 0);
		this.setBlock(world, i + 14, j + 12, k + 6, KCore.ForbiddenBrickStairs, 0);
		this.setBlock(world, i + 14, j + 12, k + 7, KCore.ForbiddenBrick, 0);
		this.setBlock(world, i + 14, j + 12, k + 8, KCore.ForbiddenBrick, 0);
		this.setBlock(world, i + 14, j + 12, k + 9, KCore.ForbiddenBrick, 0);
		this.setBlock(world, i + 14, j + 12, k + 10, KCore.ForbiddenBrick, 0);
		this.setBlock(world, i + 14, j + 12, k + 11, KCore.ForbiddenBrick, 0);
		this.setBlock(world, i + 14, j + 12, k + 12, KCore.ForbiddenBrick, 0);
		this.setBlock(world, i + 14, j + 12, k + 13, KCore.ForbiddenBrick, 0);
		this.setBlock(world, i + 14, j + 12, k + 14, KCore.ForbiddenBrick, 0);
		this.setBlock(world, i + 14, j + 12, k + 15, KCore.ForbiddenBrick, 0);
		this.setBlock(world, i + 14, j + 12, k + 16, KCore.ForbiddenBrick, 0);
		this.setBlock(world, i + 14, j + 12, k + 28, KCore.ForbiddenBrick, 0);
		this.setBlock(world, i + 14, j + 12, k + 29, KCore.ForbiddenBrick, 0);
		this.setBlock(world, i + 14, j + 12, k + 30, KCore.ForbiddenBrick, 0);
		this.setBlock(world, i + 14, j + 12, k + 31, KCore.ForbiddenBrick, 0);
		this.setBlock(world, i + 14, j + 12, k + 32, KCore.ForbiddenBrick, 0);
		this.setBlock(world, i + 14, j + 12, k + 33, KCore.ForbiddenBrick, 0);
		this.setBlock(world, i + 14, j + 12, k + 34, KCore.ForbiddenBrick, 0);
		this.setBlock(world, i + 14, j + 12, k + 35, KCore.ForbiddenBrick, 0);
		this.setBlock(world, i + 14, j + 12, k + 36, KCore.ForbiddenBrick, 0);
		this.setBlock(world, i + 14, j + 12, k + 37, KCore.ForbiddenBrick, 0);
		this.setBlock(world, i + 14, j + 12, k + 38, KCore.ForbiddenBrick, 0);
		this.setBlock(world, i + 14, j + 13, k + 3, KCore.ForbiddenBrick, 0);
		this.setBlock(world, i + 14, j + 13, k + 4, KCore.ForbiddenBrick, 0);
		this.setBlock(world, i + 14, j + 13, k + 7, KCore.ForbiddenBrick, 0);
		this.setBlock(world, i + 14, j + 13, k + 28, KCore.ForbiddenBrick, 0);
		this.setBlock(world, i + 14, j + 13, k + 29, KCore.ForbiddenBrick, 0);
		this.setBlock(world, i + 14, j + 13, k + 30, KCore.ForbiddenBrick, 0);
		this.setBlock(world, i + 14, j + 13, k + 31, KCore.ForbiddenBrick, 0);
		this.setBlock(world, i + 14, j + 13, k + 32, KCore.ForbiddenBrick, 0);
		this.setBlock(world, i + 14, j + 13, k + 33, KCore.ForbiddenBrick, 0);
		this.setBlock(world, i + 14, j + 13, k + 34, KCore.ForbiddenBrick, 0);
		this.setBlock(world, i + 14, j + 13, k + 35, KCore.ForbiddenBrick, 0);
		this.setBlock(world, i + 14, j + 13, k + 36, KCore.ForbiddenBrick, 0);
		this.setBlock(world, i + 14, j + 13, k + 37, KCore.ForbiddenBrick, 0);
		this.setBlock(world, i + 14, j + 13, k + 38, KCore.ForbiddenBrick, 0);
		this.setBlock(world, i + 14, j + 14, k + 3, KCore.ForbiddenBrick, 0);
		this.setBlock(world, i + 14, j + 14, k + 4, KCore.ForbiddenBrick, 0);
		this.setBlock(world, i + 14, j + 14, k + 7, KCore.ForbiddenBrick, 0);
		this.setBlock(world, i + 14, j + 14, k + 15, KCore.ForbiddenBrick, 0);
		this.setBlock(world, i + 14, j + 14, k + 16, KCore.ForbiddenBrick, 0);
		this.setBlock(world, i + 14, j + 14, k + 17, KCore.ForbiddenLightBrick, 0);
		this.setBlock(world, i + 14, j + 14, k + 18, KCore.ForbiddenBrick, 0);
		this.setBlock(world, i + 14, j + 14, k + 19, KCore.ForbiddenBrick, 0);
		this.setBlock(world, i + 14, j + 14, k + 20, KCore.ForbiddenBrick, 0);
		this.setBlock(world, i + 14, j + 14, k + 21, KCore.ForbiddenBrick, 0);
		this.setBlock(world, i + 14, j + 14, k + 22, KCore.ForbiddenBrick, 0);
		this.setBlock(world, i + 14, j + 14, k + 23, KCore.ForbiddenBrick, 0);
		this.setBlock(world, i + 14, j + 14, k + 24, KCore.ForbiddenBrick, 0);
		this.setBlock(world, i + 14, j + 14, k + 25, KCore.ForbiddenBrick, 0);
		this.setBlock(world, i + 14, j + 14, k + 26, KCore.ForbiddenBrick, 0);
		this.setBlock(world, i + 14, j + 14, k + 27, KCore.ForbiddenLightBrick, 0);
		this.setBlock(world, i + 14, j + 14, k + 28, KCore.ForbiddenBrick, 0);
		this.setBlock(world, i + 14, j + 14, k + 29, KCore.ForbiddenBrick, 0);
		this.setBlock(world, i + 14, j + 14, k + 30, KCore.ForbiddenBrick, 0);
		this.setBlock(world, i + 14, j + 14, k + 31, KCore.ForbiddenBrick, 0);
		this.setBlock(world, i + 14, j + 14, k + 32, KCore.ForbiddenBrick, 0);
		this.setBlock(world, i + 14, j + 14, k + 33, KCore.ForbiddenBrick, 0);
		this.setBlock(world, i + 14, j + 14, k + 34, KCore.ForbiddenBrick, 0);
		this.setBlock(world, i + 14, j + 14, k + 35, KCore.ForbiddenBrick, 0);
		this.setBlock(world, i + 14, j + 14, k + 36, KCore.ForbiddenBrick, 0);
		this.setBlock(world, i + 14, j + 14, k + 37, KCore.ForbiddenBrick, 0);
		this.setBlock(world, i + 14, j + 14, k + 38, KCore.ForbiddenBrick, 0);
		this.setBlock(world, i + 14, j + 15, k + 3, KCore.ForbiddenBrick, 0);
		this.setBlock(world, i + 14, j + 15, k + 4, KCore.ForbiddenBrick, 0);
		this.setBlock(world, i + 14, j + 15, k + 7, KCore.ForbiddenBrick, 0);
		this.setBlock(world, i + 14, j + 15, k + 15, KCore.ForbiddenBrick, 0);
		this.setBlock(world, i + 14, j + 15, k + 36, KCore.ForbiddenBrick, 0);
		this.setBlock(world, i + 14, j + 15, k + 37, KCore.ForbiddenBrick, 0);
		this.setBlock(world, i + 14, j + 15, k + 38, KCore.ForbiddenBrick, 0);
		this.setBlock(world, i + 14, j + 16, k + 3, KCore.ForbiddenBrick, 0);
		this.setBlock(world, i + 14, j + 16, k + 4, KCore.ForbiddenBrick, 0);
		this.setBlock(world, i + 14, j + 16, k + 5, KCore.ForbiddenBrick, 0);
		this.setBlock(world, i + 14, j + 16, k + 6, KCore.ForbiddenBrick, 0);
		this.setBlock(world, i + 14, j + 16, k + 7, KCore.ForbiddenBrick, 0);
		this.setBlock(world, i + 14, j + 16, k + 15, KCore.ForbiddenBrick, 0);
		this.setBlock(world, i + 14, j + 16, k + 36, KCore.ForbiddenBrick, 0);
		this.setBlock(world, i + 14, j + 16, k + 37, KCore.ForbiddenBrick, 0);
		this.setBlock(world, i + 14, j + 16, k + 38, KCore.ForbiddenBrick, 0);
		this.setBlock(world, i + 14, j + 17, k + 3, KCore.ForbiddenBrick, 0);
		this.setBlock(world, i + 14, j + 17, k + 4, KCore.ForbiddenBrick, 0);
		this.setBlock(world, i + 14, j + 17, k + 5, KCore.ForbiddenBrick, 0);
		this.setBlock(world, i + 14, j + 17, k + 6, KCore.ForbiddenBrick, 0);
		this.setBlock(world, i + 14, j + 17, k + 15, KCore.ForbiddenBrick, 0);
		this.setBlock(world, i + 14, j + 17, k + 36, KCore.ForbiddenBrick, 0);
		this.setBlock(world, i + 14, j + 17, k + 37, KCore.ForbiddenBrick, 0);
		this.setBlock(world, i + 14, j + 17, k + 38, KCore.ForbiddenBrick, 0);
		this.setBlock(world, i + 14, j + 18, k + 3, KCore.ForbiddenBrick, 0);
		this.setBlock(world, i + 14, j + 18, k + 15, KCore.ForbiddenBrick, 0);
		this.setBlock(world, i + 14, j + 18, k + 36, KCore.ForbiddenBrick, 0);
		this.setBlock(world, i + 14, j + 18, k + 37, KCore.ForbiddenBrick, 0);
		this.setBlock(world, i + 14, j + 18, k + 38, KCore.ForbiddenBrick, 0);
		this.setBlock(world, i + 14, j + 19, k + 3, KCore.ForbiddenBrick, 0);
		this.setBlock(world, i + 14, j + 19, k + 15, KCore.ForbiddenBrick, 0);
		this.setBlock(world, i + 14, j + 19, k + 36, KCore.ForbiddenBrick, 0);
		this.setBlock(world, i + 14, j + 19, k + 37, KCore.ForbiddenBrick, 0);
		this.setBlock(world, i + 14, j + 19, k + 38, KCore.ForbiddenBrick, 0);
		this.setBlock(world, i + 14, j + 20, k + 3, KCore.ForbiddenBrick, 0);
		this.setBlock(world, i + 14, j + 20, k + 15, KCore.ForbiddenBrick, 0);
		this.setBlock(world, i + 14, j + 20, k + 36, KCore.ForbiddenBrick, 0);
		this.setBlock(world, i + 14, j + 20, k + 37, KCore.ForbiddenBrick, 0);
		this.setBlock(world, i + 14, j + 20, k + 38, KCore.ForbiddenBrick, 0);
		this.setBlock(world, i + 14, j + 21, k + 3, KCore.ForbiddenBrick, 0);
		this.setBlock(world, i + 14, j + 21, k + 4, KCore.ForbiddenBrick, 0);
		this.setBlock(world, i + 14, j + 21, k + 5, KCore.ForbiddenBrick, 0);
		this.setBlock(world, i + 14, j + 21, k + 6, KCore.ForbiddenBrick, 0);
		this.setBlock(world, i + 14, j + 21, k + 7, KCore.ForbiddenBrick, 0);
		this.setBlock(world, i + 14, j + 21, k + 8, KCore.ForbiddenBrick, 0);
		this.setBlock(world, i + 14, j + 21, k + 9, KCore.ForbiddenBrick, 0);
		this.setBlock(world, i + 14, j + 21, k + 10, KCore.ForbiddenBrick, 0);
		this.setBlock(world, i + 14, j + 21, k + 11, KCore.ForbiddenBrick, 0);
		this.setBlock(world, i + 14, j + 21, k + 12, KCore.ForbiddenBrick, 0);
		this.setBlock(world, i + 14, j + 21, k + 13, KCore.ForbiddenBrick, 0);
		this.setBlock(world, i + 14, j + 21, k + 14, KCore.ForbiddenBrick, 0);
		this.setBlock(world, i + 14, j + 21, k + 15, KCore.ForbiddenBrick, 0);
		this.setBlock(world, i + 14, j + 21, k + 16, KCore.ForbiddenBrick, 0);
		this.setBlock(world, i + 14, j + 21, k + 17, KCore.ForbiddenBrick, 0);
		this.setBlock(world, i + 14, j + 21, k + 18, KCore.ForbiddenBrick, 0);
		this.setBlock(world, i + 14, j + 21, k + 19, KCore.ForbiddenBrick, 0);
		this.setBlock(world, i + 14, j + 21, k + 20, KCore.ForbiddenBrick, 0);
		this.setBlock(world, i + 14, j + 21, k + 21, KCore.ForbiddenBrick, 0);
		this.setBlock(world, i + 14, j + 21, k + 22, KCore.ForbiddenBrick, 0);
		this.setBlock(world, i + 14, j + 21, k + 23, KCore.ForbiddenBrick, 0);
		this.setBlock(world, i + 14, j + 21, k + 24, KCore.ForbiddenBrick, 0);
		this.setBlock(world, i + 14, j + 21, k + 25, KCore.ForbiddenBrick, 0);
		this.setBlock(world, i + 14, j + 21, k + 26, KCore.ForbiddenBrick, 0);
		this.setBlock(world, i + 14, j + 21, k + 27, KCore.ForbiddenBrick, 0);
		this.setBlock(world, i + 14, j + 21, k + 28, KCore.ForbiddenBrick, 0);
		this.setBlock(world, i + 14, j + 21, k + 29, KCore.ForbiddenBrick, 0);
		this.setBlock(world, i + 14, j + 21, k + 30, KCore.ForbiddenBrick, 0);
		this.setBlock(world, i + 14, j + 21, k + 31, KCore.ForbiddenBrick, 0);
		this.setBlock(world, i + 14, j + 21, k + 32, KCore.ForbiddenBrick, 0);
		this.setBlock(world, i + 14, j + 21, k + 33, KCore.ForbiddenBrick, 0);
		this.setBlock(world, i + 14, j + 21, k + 34, KCore.ForbiddenBrick, 0);
		this.setBlock(world, i + 14, j + 21, k + 35, KCore.ForbiddenBrick, 0);
		this.setBlock(world, i + 14, j + 21, k + 36, KCore.ForbiddenBrick, 0);
		this.setBlock(world, i + 14, j + 21, k + 37, KCore.ForbiddenBrick, 0);
		this.setBlock(world, i + 14, j + 21, k + 38, KCore.ForbiddenBrick, 0);
		this.setBlock(world, i + 15, j + 0, k + 0, KCore.ForbiddenRockStairs, 0);
		this.setBlock(world, i + 15, j + 0, k + 1, KCore.ForbiddenRock, 0);
		this.setBlock(world, i + 15, j + 0, k + 2, KCore.ForbiddenRock, 0);
		this.setBlock(world, i + 15, j + 0, k + 3, KCore.ForbiddenRock, 0);
		this.setBlock(world, i + 15, j + 0, k + 4, KCore.ForbiddenRock, 0);
		this.setBlock(world, i + 15, j + 0, k + 5, KCore.ForbiddenRock, 0);
		this.setBlock(world, i + 15, j + 0, k + 6, KCore.ForbiddenRock, 0);
		this.setBlock(world, i + 15, j + 0, k + 7, KCore.ForbiddenRock, 0);
		this.setBlock(world, i + 15, j + 0, k + 8, KCore.ForbiddenRock, 0);
		this.setBlock(world, i + 15, j + 0, k + 9, KCore.ForbiddenRock, 0);
		this.setBlock(world, i + 15, j + 0, k + 10, KCore.ForbiddenRock, 0);
		this.setBlock(world, i + 15, j + 0, k + 11, KCore.ForbiddenRock, 0);
		this.setBlock(world, i + 15, j + 0, k + 12, KCore.ForbiddenRock, 0);
		this.setBlock(world, i + 15, j + 0, k + 13, KCore.ForbiddenRock, 0);
		this.setBlock(world, i + 15, j + 0, k + 14, KCore.ForbiddenRock, 0);
		this.setBlock(world, i + 15, j + 0, k + 15, KCore.ForbiddenRock, 0);
		this.setBlock(world, i + 15, j + 0, k + 16, KCore.ForbiddenRock, 0);
		this.setBlock(world, i + 15, j + 0, k + 17, KCore.ForbiddenRock, 0);
		this.setBlock(world, i + 15, j + 0, k + 18, KCore.ForbiddenRock, 0);
		this.setBlock(world, i + 15, j + 0, k + 19, KCore.ForbiddenRock, 0);
		this.setBlock(world, i + 15, j + 0, k + 20, KCore.ForbiddenRock, 0);
		this.setBlock(world, i + 15, j + 0, k + 21, KCore.ForbiddenRock, 0);
		this.setBlock(world, i + 15, j + 0, k + 22, KCore.ForbiddenRock, 0);
		this.setBlock(world, i + 15, j + 0, k + 23, KCore.ForbiddenRock, 0);
		this.setBlock(world, i + 15, j + 0, k + 24, KCore.ForbiddenRock, 0);
		this.setBlock(world, i + 15, j + 0, k + 25, KCore.ForbiddenRock, 0);
		this.setBlock(world, i + 15, j + 0, k + 26, KCore.ForbiddenRock, 0);
		this.setBlock(world, i + 15, j + 0, k + 27, KCore.ForbiddenRock, 0);
		this.setBlock(world, i + 15, j + 0, k + 28, KCore.ForbiddenRock, 0);
		this.setBlock(world, i + 15, j + 0, k + 29, KCore.ForbiddenRock, 0);
		this.setBlock(world, i + 15, j + 0, k + 30, KCore.ForbiddenRock, 0);
		this.setBlock(world, i + 15, j + 0, k + 31, KCore.ForbiddenRock, 0);
		this.setBlock(world, i + 15, j + 0, k + 32, KCore.ForbiddenRock, 0);
		this.setBlock(world, i + 15, j + 0, k + 33, KCore.ForbiddenRock, 0);
		this.setBlock(world, i + 15, j + 0, k + 34, KCore.ForbiddenRock, 0);
		this.setBlock(world, i + 15, j + 0, k + 35, KCore.ForbiddenRock, 0);
		this.setBlock(world, i + 15, j + 0, k + 36, KCore.ForbiddenRock, 0);
		this.setBlock(world, i + 15, j + 0, k + 37, KCore.ForbiddenRock, 0);
		this.setBlock(world, i + 15, j + 0, k + 38, KCore.ForbiddenRock, 0);
		this.setBlock(world, i + 15, j + 1, k + 1, KCore.ForbiddenRockStairs, 0);
		this.setBlock(world, i + 15, j + 1, k + 2, KCore.ForbiddenRock, 0);
		this.setBlock(world, i + 15, j + 1, k + 3, KCore.ForbiddenRock, 0);
		this.setBlock(world, i + 15, j + 1, k + 4, KCore.ForbiddenRock, 0);
		this.setBlock(world, i + 15, j + 1, k + 5, KCore.ForbiddenRock, 0);
		this.setBlock(world, i + 15, j + 1, k + 6, KCore.ForbiddenRock, 0);
		this.setBlock(world, i + 15, j + 1, k + 7, KCore.ForbiddenRock, 0);
		this.setBlock(world, i + 15, j + 1, k + 8, KCore.ForbiddenRock, 0);
		this.setBlock(world, i + 15, j + 1, k + 9, KCore.ForbiddenRock, 0);
		this.setBlock(world, i + 15, j + 1, k + 10, KCore.ForbiddenRock, 0);
		this.setBlock(world, i + 15, j + 1, k + 11, KCore.ForbiddenRock, 0);
		this.setBlock(world, i + 15, j + 1, k + 12, KCore.ForbiddenRock, 0);
		this.setBlock(world, i + 15, j + 1, k + 13, KCore.ForbiddenRock, 0);
		this.setBlock(world, i + 15, j + 1, k + 14, KCore.ForbiddenRock, 0);
		this.setBlock(world, i + 15, j + 1, k + 15, KCore.ForbiddenRock, 0);
		this.setBlock(world, i + 15, j + 1, k + 16, KCore.ForbiddenRock, 0);
		this.setBlock(world, i + 15, j + 1, k + 17, KCore.ForbiddenRock, 0);
		this.setBlock(world, i + 15, j + 1, k + 18, KCore.ForbiddenRock, 0);
		this.setBlock(world, i + 15, j + 1, k + 19, KCore.ForbiddenRock, 0);
		this.setBlock(world, i + 15, j + 1, k + 20, KCore.ForbiddenRock, 0);
		this.setBlock(world, i + 15, j + 1, k + 21, KCore.ForbiddenRock, 0);
		this.setBlock(world, i + 15, j + 1, k + 22, KCore.ForbiddenRock, 0);
		this.setBlock(world, i + 15, j + 1, k + 23, KCore.ForbiddenRock, 0);
		this.setBlock(world, i + 15, j + 1, k + 24, KCore.ForbiddenRock, 0);
		this.setBlock(world, i + 15, j + 1, k + 25, KCore.ForbiddenRock, 0);
		this.setBlock(world, i + 15, j + 1, k + 26, KCore.ForbiddenRock, 0);
		this.setBlock(world, i + 15, j + 1, k + 27, KCore.ForbiddenRock, 0);
		this.setBlock(world, i + 15, j + 1, k + 28, KCore.ForbiddenRock, 0);
		this.setBlock(world, i + 15, j + 1, k + 29, KCore.ForbiddenRock, 0);
		this.setBlock(world, i + 15, j + 1, k + 30, KCore.ForbiddenRock, 0);
		this.setBlock(world, i + 15, j + 1, k + 31, KCore.ForbiddenRock, 0);
		this.setBlock(world, i + 15, j + 1, k + 32, KCore.ForbiddenRock, 0);
		this.setBlock(world, i + 15, j + 1, k + 33, KCore.ForbiddenRock, 0);
		this.setBlock(world, i + 15, j + 1, k + 34, KCore.ForbiddenRock, 0);
		this.setBlock(world, i + 15, j + 1, k + 35, KCore.ForbiddenRock, 0);
		this.setBlock(world, i + 15, j + 1, k + 36, KCore.ForbiddenRock, 0);
		this.setBlock(world, i + 15, j + 1, k + 37, KCore.ForbiddenRock, 0);
		this.setBlock(world, i + 15, j + 1, k + 38, KCore.ForbiddenRock, 0);
		this.setBlock(world, i + 15, j + 2, k + 2, KCore.ForbiddenRockStairs, 0);
		this.setBlock(world, i + 15, j + 2, k + 3, KCore.ForbiddenBrick, 0);
		this.setBlock(world, i + 15, j + 2, k + 4, KCore.ForbiddenRock, 0);
		this.setBlock(world, i + 15, j + 2, k + 5, KCore.ForbiddenLightBrick, 0);
		this.setBlock(world, i + 15, j + 2, k + 6, KCore.ForbiddenRock, 0);
		this.setBlock(world, i + 15, j + 2, k + 7, KCore.ForbiddenRock, 0);
		this.setBlock(world, i + 15, j + 2, k + 8, KCore.ForbiddenRock, 0);
		this.setBlock(world, i + 15, j + 2, k + 9, KCore.ForbiddenRock, 0);
		this.setBlock(world, i + 15, j + 2, k + 10, KCore.ForbiddenRock, 0);
		this.setBlock(world, i + 15, j + 2, k + 11, KCore.ForbiddenRock, 0);
		this.setBlock(world, i + 15, j + 2, k + 12, KCore.ForbiddenRock, 0);
		this.setBlock(world, i + 15, j + 2, k + 13, KCore.ForbiddenRock, 0);
		this.setBlock(world, i + 15, j + 2, k + 14, KCore.ForbiddenLightBrick, 0);
		this.setBlock(world, i + 15, j + 2, k + 15, KCore.ForbiddenRock, 0);
		this.setBlock(world, i + 15, j + 2, k + 16, KCore.ForbiddenRock, 0);
		this.setBlock(world, i + 15, j + 2, k + 17, KCore.ForbiddenRock, 0);
		this.setBlock(world, i + 15, j + 2, k + 18, KCore.ForbiddenRock, 0);
		this.setBlock(world, i + 15, j + 2, k + 19, KCore.ForbiddenRock, 0);
		this.setBlock(world, i + 15, j + 2, k + 20, KCore.ForbiddenRock, 0);
		this.setBlock(world, i + 15, j + 2, k + 21, KCore.ForbiddenRock, 0);
		this.setBlock(world, i + 15, j + 2, k + 22, KCore.ForbiddenRock, 0);
		this.setBlock(world, i + 15, j + 2, k + 23, KCore.ForbiddenRock, 0);
		this.setBlock(world, i + 15, j + 2, k + 24, KCore.ForbiddenRock, 0);
		this.setBlock(world, i + 15, j + 2, k + 25, KCore.ForbiddenRock, 0);
		this.setBlock(world, i + 15, j + 2, k + 26, KCore.ForbiddenRock, 0);
		this.setBlock(world, i + 15, j + 2, k + 27, KCore.ForbiddenRock, 0);
		this.setBlock(world, i + 15, j + 2, k + 28, KCore.ForbiddenRock, 0);
		this.setBlock(world, i + 15, j + 2, k + 29, KCore.ForbiddenRock, 0);
		this.setBlock(world, i + 15, j + 2, k + 30, KCore.ForbiddenRock, 0);
		this.setBlock(world, i + 15, j + 2, k + 31, KCore.ForbiddenRock, 0);
		this.setBlock(world, i + 15, j + 2, k + 32, KCore.ForbiddenRock, 0);
		this.setBlock(world, i + 15, j + 2, k + 33, KCore.ForbiddenRock, 0);
		this.setBlock(world, i + 15, j + 2, k + 34, KCore.ForbiddenRock, 0);
		this.setBlock(world, i + 15, j + 2, k + 35, KCore.ForbiddenRock, 0);
		this.setBlock(world, i + 15, j + 2, k + 36, KCore.ForbiddenRock, 0);
		this.setBlock(world, i + 15, j + 2, k + 37, KCore.ForbiddenRock, 0);
		this.setBlock(world, i + 15, j + 2, k + 38, KCore.ForbiddenRock, 0);
		this.setBlock(world, i + 15, j + 3, k + 15, KCore.ForbiddenBrick, 0);
		this.setBlock(world, i + 15, j + 3, k + 16, KCore.ForbiddenBrick, 0);
		this.setBlock(world, i + 15, j + 3, k + 17, KCore.ForbiddenBrick, 0);
		this.setBlock(world, i + 15, j + 3, k + 27, KCore.ForbiddenBrick, 0);
		this.setBlock(world, i + 15, j + 3, k + 28, KCore.ForbiddenBrick, 0);
		this.setBlock(world, i + 15, j + 3, k + 29, KCore.ForbiddenBrick, 0);
		this.setBlock(world, i + 15, j + 3, k + 30, KCore.ForbiddenBrick, 0);
		this.setBlock(world, i + 15, j + 3, k + 31, KCore.ForbiddenBrick, 0);
		this.setBlock(world, i + 15, j + 3, k + 32, KCore.ForbiddenBrick, 0);
		this.setBlock(world, i + 15, j + 3, k + 33, KCore.ForbiddenBrick, 0);
		this.setBlock(world, i + 15, j + 3, k + 34, KCore.ForbiddenBrick, 0);
		this.setBlock(world, i + 15, j + 3, k + 35, KCore.ForbiddenBrick, 0);
		this.setBlock(world, i + 15, j + 3, k + 36, KCore.ForbiddenBrick, 0);
		this.setBlock(world, i + 15, j + 3, k + 37, KCore.ForbiddenBrick, 0);
		this.setBlock(world, i + 15, j + 3, k + 38, KCore.ForbiddenBrick, 0);
		this.setBlock(world, i + 15, j + 4, k + 15, KCore.ForbiddenBrick, 0);
		this.setBlock(world, i + 15, j + 4, k + 16, KCore.ForbiddenBrick, 0);
		this.setBlock(world, i + 15, j + 4, k + 17, KCore.ForbiddenBrick, 0);
		this.setBlock(world, i + 15, j + 4, k + 27, KCore.ForbiddenBrick, 0);
		this.setBlock(world, i + 15, j + 4, k + 28, KCore.ForbiddenBrick, 0);
		this.setBlock(world, i + 15, j + 4, k + 29, KCore.ForbiddenBrick, 0);
		this.setBlock(world, i + 15, j + 4, k + 30, KCore.ForbiddenBrick, 0);
		this.setBlock(world, i + 15, j + 4, k + 31, KCore.ForbiddenBrick, 0);
		this.setBlock(world, i + 15, j + 4, k + 32, KCore.ForbiddenBrick, 0);
		this.setBlock(world, i + 15, j + 4, k + 33, KCore.ForbiddenBrick, 0);
		this.setBlock(world, i + 15, j + 4, k + 34, KCore.ForbiddenBrick, 0);
		this.setBlock(world, i + 15, j + 4, k + 35, KCore.ForbiddenBrick, 0);
		this.setBlock(world, i + 15, j + 4, k + 36, KCore.ForbiddenBrick, 0);
		this.setBlock(world, i + 15, j + 4, k + 37, KCore.ForbiddenBrick, 0);
		this.setBlock(world, i + 15, j + 4, k + 38, KCore.ForbiddenBrick, 0);
		this.setBlock(world, i + 15, j + 5, k + 3, KCore.ForbiddenLightBrick, 0);
		this.setBlock(world, i + 15, j + 5, k + 15, KCore.ForbiddenBrick, 0);
		this.setBlock(world, i + 15, j + 5, k + 16, KCore.ForbiddenBrick, 0);
		this.setBlock(world, i + 15, j + 5, k + 17, KCore.ForbiddenBrick, 0);
		this.setBlock(world, i + 15, j + 5, k + 27, KCore.ForbiddenBrick, 0);
		this.setBlock(world, i + 15, j + 5, k + 28, KCore.ForbiddenBrick, 0);
		this.setBlock(world, i + 15, j + 5, k + 29, KCore.ForbiddenBrick, 0);
		this.setBlock(world, i + 15, j + 5, k + 30, KCore.ForbiddenBrick, 0);
		this.setBlock(world, i + 15, j + 5, k + 31, KCore.ForbiddenBrick, 0);
		this.setBlock(world, i + 15, j + 5, k + 32, KCore.ForbiddenBrick, 0);
		this.setBlock(world, i + 15, j + 5, k + 33, KCore.ForbiddenBrick, 0);
		this.setBlock(world, i + 15, j + 5, k + 34, KCore.ForbiddenBrick, 0);
		this.setBlock(world, i + 15, j + 5, k + 35, KCore.ForbiddenBrick, 0);
		this.setBlock(world, i + 15, j + 5, k + 36, KCore.ForbiddenBrick, 0);
		this.setBlock(world, i + 15, j + 5, k + 37, KCore.ForbiddenBrick, 0);
		this.setBlock(world, i + 15, j + 5, k + 38, KCore.ForbiddenBrick, 0);
		this.setBlock(world, i + 15, j + 6, k + 3, KCore.ForbiddenBrick, 0);
		this.setBlock(world, i + 15, j + 6, k + 4, KCore.ForbiddenBrick, 0);
		this.setBlock(world, i + 15, j + 6, k + 5, KCore.ForbiddenBrick, 0);
		this.setBlock(world, i + 15, j + 6, k + 6, KCore.ForbiddenBrick, 0);
		this.setBlock(world, i + 15, j + 6, k + 7, KCore.ForbiddenBrick, 0);
		this.setBlock(world, i + 15, j + 6, k + 8, KCore.ForbiddenBrick, 0);
		this.setBlock(world, i + 15, j + 6, k + 9, KCore.ForbiddenBrick, 0);
		this.setBlock(world, i + 15, j + 6, k + 10, KCore.ForbiddenBrick, 0);
		this.setBlock(world, i + 15, j + 6, k + 11, KCore.ForbiddenBrick, 0);
		this.setBlock(world, i + 15, j + 6, k + 12, KCore.ForbiddenBrick, 0);
		this.setBlock(world, i + 15, j + 6, k + 13, KCore.ForbiddenBrick, 0);
		this.setBlock(world, i + 15, j + 6, k + 14, KCore.ForbiddenBrick, 0);
		this.setBlock(world, i + 15, j + 6, k + 15, KCore.ForbiddenBrick, 0);
		this.setBlock(world, i + 15, j + 6, k + 16, KCore.ForbiddenBrick, 0);
		this.setBlock(world, i + 15, j + 6, k + 17, KCore.ForbiddenBrick, 0);
		this.setBlock(world, i + 15, j + 6, k + 27, KCore.ForbiddenBrick, 0);
		this.setBlock(world, i + 15, j + 6, k + 28, KCore.ForbiddenBrick, 0);
		this.setBlock(world, i + 15, j + 6, k + 29, KCore.ForbiddenBrick, 0);
		this.setBlock(world, i + 15, j + 6, k + 30, KCore.ForbiddenBrick, 0);
		this.setBlock(world, i + 15, j + 6, k + 31, KCore.ForbiddenBrick, 0);
		this.setBlock(world, i + 15, j + 6, k + 32, KCore.ForbiddenBrick, 0);
		this.setBlock(world, i + 15, j + 6, k + 33, KCore.ForbiddenBrick, 0);
		this.setBlock(world, i + 15, j + 6, k + 34, KCore.ForbiddenBrick, 0);
		this.setBlock(world, i + 15, j + 6, k + 35, KCore.ForbiddenBrick, 0);
		this.setBlock(world, i + 15, j + 6, k + 36, KCore.ForbiddenBrick, 0);
		this.setBlock(world, i + 15, j + 6, k + 37, KCore.ForbiddenBrick, 0);
		this.setBlock(world, i + 15, j + 6, k + 38, KCore.ForbiddenBrick, 0);
		this.setBlock(world, i + 15, j + 7, k + 3, KCore.ForbiddenBrick, 0);
		this.setBlock(world, i + 15, j + 7, k + 4, KCore.ForbiddenBrick, 0);
		this.setBlock(world, i + 15, j + 7, k + 5, KCore.ForbiddenRock, 0);
		this.setBlock(world, i + 15, j + 7, k + 6, KCore.ForbiddenRock, 0);
		this.setBlock(world, i + 15, j + 7, k + 7, KCore.ForbiddenBrick, 0);
		this.setBlock(world, i + 15, j + 7, k + 8, KCore.ForbiddenBrick, 0);
		this.setBlock(world, i + 15, j + 7, k + 9, KCore.ForbiddenBrick, 0);
		this.setBlock(world, i + 15, j + 7, k + 10, KCore.ForbiddenBrick, 0);
		this.setBlock(world, i + 15, j + 7, k + 11, KCore.ForbiddenBrick, 0);
		this.setBlock(world, i + 15, j + 7, k + 12, KCore.ForbiddenBrick, 0);
		this.setBlock(world, i + 15, j + 7, k + 13, KCore.ForbiddenBrick, 0);
		this.setBlock(world, i + 15, j + 7, k + 16, KCore.ForbiddenBrick, 0);
		this.setBlock(world, i + 15, j + 7, k + 17, KCore.ForbiddenBrick, 0);
		this.setBlock(world, i + 15, j + 7, k + 27, KCore.ForbiddenBrick, 0);
		this.setBlock(world, i + 15, j + 7, k + 28, KCore.ForbiddenBrick, 0);
		this.setBlock(world, i + 15, j + 7, k + 29, KCore.ForbiddenBrick, 0);
		this.setBlock(world, i + 15, j + 7, k + 30, KCore.ForbiddenBrick, 0);
		this.setBlock(world, i + 15, j + 7, k + 31, KCore.ForbiddenBrick, 0);
		this.setBlock(world, i + 15, j + 7, k + 32, KCore.ForbiddenBrick, 0);
		this.setBlock(world, i + 15, j + 7, k + 33, KCore.ForbiddenBrick, 0);
		this.setBlock(world, i + 15, j + 7, k + 34, KCore.ForbiddenBrick, 0);
		this.setBlock(world, i + 15, j + 7, k + 35, KCore.ForbiddenBrick, 0);
		this.setBlock(world, i + 15, j + 7, k + 36, KCore.ForbiddenBrick, 0);
		this.setBlock(world, i + 15, j + 7, k + 37, KCore.ForbiddenBrick, 0);
		this.setBlock(world, i + 15, j + 7, k + 38, KCore.ForbiddenBrick, 0);
		this.setBlock(world, i + 15, j + 8, k + 3, KCore.ForbiddenBrick, 0);
		this.setBlock(world, i + 15, j + 8, k + 4, KCore.ForbiddenBrick, 0);
		this.setBlock(world, i + 15, j + 8, k + 5, KCore.ForbiddenRock, 0);
		this.setBlock(world, i + 15, j + 8, k + 6, KCore.ForbiddenRock, 0);
		this.setBlock(world, i + 15, j + 8, k + 7, KCore.ForbiddenBrick, 0);
		this.setBlock(world, i + 15, j + 8, k + 8, KCore.ForbiddenBrick, 0);
		this.setBlock(world, i + 15, j + 8, k + 9, KCore.ForbiddenBrick, 0);
		this.setBlock(world, i + 15, j + 8, k + 10, KCore.ForbiddenBrick, 0);
		this.setBlock(world, i + 15, j + 8, k + 11, KCore.ForbiddenBrick, 0);
		this.setBlock(world, i + 15, j + 8, k + 12, KCore.ForbiddenBrick, 0);
		this.setBlock(world, i + 15, j + 8, k + 13, KCore.ForbiddenBrick, 0);
		this.setBlock(world, i + 15, j + 8, k + 16, KCore.ForbiddenBrick, 0);
		this.setBlock(world, i + 15, j + 8, k + 17, KCore.ForbiddenBrick, 0);
		this.setBlock(world, i + 15, j + 8, k + 18, KCore.ForbiddenBrick, 0);
		this.setBlock(world, i + 15, j + 8, k + 19, KCore.ForbiddenBrick, 0);
		this.setBlock(world, i + 15, j + 8, k + 20, KCore.ForbiddenBrick, 0);
		this.setBlock(world, i + 15, j + 8, k + 21, KCore.ForbiddenBrick, 0);
		this.setBlock(world, i + 15, j + 8, k + 22, KCore.ForbiddenBrick, 0);
		this.setBlock(world, i + 15, j + 8, k + 23, KCore.ForbiddenBrick, 0);
		this.setBlock(world, i + 15, j + 8, k + 24, KCore.ForbiddenBrick, 0);
		this.setBlock(world, i + 15, j + 8, k + 25, KCore.ForbiddenBrick, 0);
		this.setBlock(world, i + 15, j + 8, k + 26, KCore.ForbiddenBrick, 0);
		this.setBlock(world, i + 15, j + 8, k + 27, KCore.ForbiddenBrick, 0);
		this.setBlock(world, i + 15, j + 8, k + 28, KCore.ForbiddenBrick, 0);
		this.setBlock(world, i + 15, j + 8, k + 29, KCore.ForbiddenBrick, 0);
		this.setBlock(world, i + 15, j + 8, k + 30, KCore.ForbiddenBrick, 0);
		this.setBlock(world, i + 15, j + 8, k + 31, KCore.ForbiddenBrick, 0);
		this.setBlock(world, i + 15, j + 8, k + 32, KCore.ForbiddenBrick, 0);
		this.setBlock(world, i + 15, j + 8, k + 33, KCore.ForbiddenBrick, 0);
		this.setBlock(world, i + 15, j + 8, k + 34, KCore.ForbiddenBrick, 0);
		this.setBlock(world, i + 15, j + 8, k + 35, KCore.ForbiddenBrick, 0);
		this.setBlock(world, i + 15, j + 8, k + 36, KCore.ForbiddenBrick, 0);
		this.setBlock(world, i + 15, j + 8, k + 37, KCore.ForbiddenBrick, 0);
		this.setBlock(world, i + 15, j + 8, k + 38, KCore.ForbiddenBrick, 0);
		this.setBlock(world, i + 15, j + 9, k + 3, KCore.ForbiddenBrick, 0);
		this.setBlock(world, i + 15, j + 9, k + 4, KCore.ForbiddenBrick, 0);
		this.setBlock(world, i + 15, j + 9, k + 5, KCore.ForbiddenRock, 0);
		this.setBlock(world, i + 15, j + 9, k + 6, KCore.ForbiddenRock, 0);
		this.setBlock(world, i + 15, j + 9, k + 7, KCore.ForbiddenBrick, 0);
		this.setBlock(world, i + 15, j + 9, k + 8, KCore.ForbiddenBrick, 0);
		this.setBlock(world, i + 15, j + 9, k + 9, KCore.ForbiddenBrick, 0);
		this.setBlock(world, i + 15, j + 9, k + 10, KCore.ForbiddenBrick, 0);
		this.setBlock(world, i + 15, j + 9, k + 11, KCore.ForbiddenBrick, 0);
		this.setBlock(world, i + 15, j + 9, k + 12, KCore.ForbiddenBrick, 0);
		this.setBlock(world, i + 15, j + 9, k + 13, KCore.ForbiddenBrick, 0);
		this.setBlock(world, i + 15, j + 9, k + 14, KCore.ForbiddenRock, 0);
		this.setBlock(world, i + 15, j + 9, k + 15, KCore.ForbiddenRock, 0);
		this.setBlock(world, i + 15, j + 9, k + 16, KCore.ForbiddenBrick, 0);
		this.setBlock(world, i + 15, j + 9, k + 28, KCore.ForbiddenBrick, 0);
		this.setBlock(world, i + 15, j + 9, k + 29, KCore.ForbiddenBrick, 0);
		this.setBlock(world, i + 15, j + 9, k + 30, KCore.ForbiddenBrick, 0);
		this.setBlock(world, i + 15, j + 9, k + 31, KCore.ForbiddenBrick, 0);
		this.setBlock(world, i + 15, j + 9, k + 32, KCore.ForbiddenBrick, 0);
		this.setBlock(world, i + 15, j + 9, k + 33, KCore.ForbiddenBrick, 0);
		this.setBlock(world, i + 15, j + 9, k + 34, KCore.ForbiddenBrick, 0);
		this.setBlock(world, i + 15, j + 9, k + 35, KCore.ForbiddenBrick, 0);
		this.setBlock(world, i + 15, j + 9, k + 36, KCore.ForbiddenBrick, 0);
		this.setBlock(world, i + 15, j + 9, k + 37, KCore.ForbiddenBrick, 0);
		this.setBlock(world, i + 15, j + 9, k + 38, KCore.ForbiddenBrick, 0);
		this.setBlock(world, i + 15, j + 10, k + 3, KCore.ForbiddenBrick, 0);
		this.setBlock(world, i + 15, j + 10, k + 4, KCore.ForbiddenBrick, 0);
		this.setBlock(world, i + 15, j + 10, k + 5, KCore.ForbiddenRock, 0);
		this.setBlock(world, i + 15, j + 10, k + 6, KCore.ForbiddenRock, 0);
		this.setBlock(world, i + 15, j + 10, k + 7, KCore.ForbiddenBrick, 0);
		this.setBlock(world, i + 15, j + 10, k + 8, KCore.ForbiddenBrick, 0);
		this.setBlock(world, i + 15, j + 10, k + 9, KCore.ForbiddenBrick, 0);
		this.setBlock(world, i + 15, j + 10, k + 10, KCore.ForbiddenBrick, 0);
		this.setBlock(world, i + 15, j + 10, k + 11, KCore.ForbiddenBrick, 0);
		this.setBlock(world, i + 15, j + 10, k + 12, KCore.ForbiddenBrick, 0);
		this.setBlock(world, i + 15, j + 10, k + 13, KCore.ForbiddenBrick, 0);
		this.setBlock(world, i + 15, j + 10, k + 16, KCore.ForbiddenBrick, 0);
		this.setBlock(world, i + 15, j + 10, k + 28, KCore.ForbiddenBrick, 0);
		this.setBlock(world, i + 15, j + 10, k + 29, KCore.ForbiddenBrick, 0);
		this.setBlock(world, i + 15, j + 10, k + 30, KCore.ForbiddenBrick, 0);
		this.setBlock(world, i + 15, j + 10, k + 31, KCore.ForbiddenBrick, 0);
		this.setBlock(world, i + 15, j + 10, k + 32, KCore.ForbiddenBrick, 0);
		this.setBlock(world, i + 15, j + 10, k + 33, KCore.ForbiddenBrick, 0);
		this.setBlock(world, i + 15, j + 10, k + 34, KCore.ForbiddenBrick, 0);
		this.setBlock(world, i + 15, j + 10, k + 35, KCore.ForbiddenBrick, 0);
		this.setBlock(world, i + 15, j + 10, k + 36, KCore.ForbiddenBrick, 0);
		this.setBlock(world, i + 15, j + 10, k + 37, KCore.ForbiddenBrick, 0);
		this.setBlock(world, i + 15, j + 10, k + 38, KCore.ForbiddenBrick, 0);
		this.setBlock(world, i + 15, j + 11, k + 3, KCore.ForbiddenBrick, 0);
		this.setBlock(world, i + 15, j + 11, k + 4, KCore.ForbiddenBrick, 0);
		this.setBlock(world, i + 15, j + 11, k + 5, KCore.ForbiddenRock, 0);
		this.setBlock(world, i + 15, j + 11, k + 6, KCore.ForbiddenRock, 0);
		this.setBlock(world, i + 15, j + 11, k + 7, KCore.ForbiddenBrick, 0);
		this.setBlock(world, i + 15, j + 11, k + 8, KCore.ForbiddenBrick, 0);
		this.setBlock(world, i + 15, j + 11, k + 9, KCore.ForbiddenBrick, 0);
		this.setBlock(world, i + 15, j + 11, k + 10, KCore.ForbiddenBrick, 0);
		this.setBlock(world, i + 15, j + 11, k + 11, KCore.ForbiddenBrick, 0);
		this.setBlock(world, i + 15, j + 11, k + 12, KCore.ForbiddenBrick, 0);
		this.setBlock(world, i + 15, j + 11, k + 13, KCore.ForbiddenBrick, 0);
		this.setBlock(world, i + 15, j + 11, k + 16, KCore.ForbiddenBrick, 0);
		this.setBlock(world, i + 15, j + 11, k + 28, KCore.ForbiddenBrick, 0);
		this.setBlock(world, i + 15, j + 11, k + 29, KCore.ForbiddenBrick, 0);
		this.setBlock(world, i + 15, j + 11, k + 30, KCore.ForbiddenBrick, 0);
		this.setBlock(world, i + 15, j + 11, k + 31, KCore.ForbiddenBrick, 0);
		this.setBlock(world, i + 15, j + 11, k + 32, KCore.ForbiddenBrick, 0);
		this.setBlock(world, i + 15, j + 11, k + 33, KCore.ForbiddenBrick, 0);
		this.setBlock(world, i + 15, j + 11, k + 34, KCore.ForbiddenBrick, 0);
		this.setBlock(world, i + 15, j + 11, k + 35, KCore.ForbiddenBrick, 0);
		this.setBlock(world, i + 15, j + 11, k + 36, KCore.ForbiddenBrick, 0);
		this.setBlock(world, i + 15, j + 11, k + 37, KCore.ForbiddenBrick, 0);
		this.setBlock(world, i + 15, j + 11, k + 38, KCore.ForbiddenBrick, 0);
		this.setBlock(world, i + 15, j + 12, k + 3, KCore.ForbiddenBrick, 0);
		this.setBlock(world, i + 15, j + 12, k + 4, KCore.ForbiddenBrick, 0);
		this.setBlock(world, i + 15, j + 12, k + 5, KCore.ForbiddenRock, 0);
		this.setBlock(world, i + 15, j + 12, k + 6, KCore.ForbiddenRock, 0);
		this.setBlock(world, i + 15, j + 12, k + 7, KCore.ForbiddenBrick, 0);
		this.setBlock(world, i + 15, j + 12, k + 8, KCore.ForbiddenBrick, 0);
		this.setBlock(world, i + 15, j + 12, k + 9, KCore.ForbiddenBrick, 0);
		this.setBlock(world, i + 15, j + 12, k + 10, KCore.ForbiddenBrick, 0);
		this.setBlock(world, i + 15, j + 12, k + 11, KCore.ForbiddenBrick, 0);
		this.setBlock(world, i + 15, j + 12, k + 12, KCore.ForbiddenBrick, 0);
		this.setBlock(world, i + 15, j + 12, k + 13, KCore.ForbiddenBrick, 0);
		this.setBlock(world, i + 15, j + 12, k + 14, KCore.ForbiddenBrick, 0);
		this.setBlock(world, i + 15, j + 12, k + 15, KCore.ForbiddenBrick, 0);
		this.setBlock(world, i + 15, j + 12, k + 16, KCore.ForbiddenBrick, 0);
		this.setBlock(world, i + 15, j + 12, k + 28, KCore.ForbiddenBrick, 0);
		this.setBlock(world, i + 15, j + 12, k + 29, KCore.ForbiddenBrick, 0);
		this.setBlock(world, i + 15, j + 12, k + 30, KCore.ForbiddenBrick, 0);
		this.setBlock(world, i + 15, j + 12, k + 31, KCore.ForbiddenBrick, 0);
		this.setBlock(world, i + 15, j + 12, k + 32, KCore.ForbiddenBrick, 0);
		this.setBlock(world, i + 15, j + 12, k + 33, KCore.ForbiddenBrick, 0);
		this.setBlock(world, i + 15, j + 12, k + 34, KCore.ForbiddenBrick, 0);
		this.setBlock(world, i + 15, j + 12, k + 35, KCore.ForbiddenBrick, 0);
		this.setBlock(world, i + 15, j + 12, k + 36, KCore.ForbiddenBrick, 0);
		this.setBlock(world, i + 15, j + 12, k + 37, KCore.ForbiddenBrick, 0);
		this.setBlock(world, i + 15, j + 12, k + 38, KCore.ForbiddenBrick, 0);
		this.setBlock(world, i + 15, j + 13, k + 3, KCore.ForbiddenBrick, 0);
		this.setBlock(world, i + 15, j + 13, k + 4, KCore.ForbiddenBrick, 0);
		this.setBlock(world, i + 15, j + 13, k + 5, KCore.ForbiddenBrickStairs, 0);
		this.setBlock(world, i + 15, j + 13, k + 6, KCore.ForbiddenBrickStairs, 0);
		this.setBlock(world, i + 15, j + 13, k + 7, KCore.ForbiddenBrick, 0);
		this.setBlock(world, i + 15, j + 13, k + 28, KCore.ForbiddenBrick, 0);
		this.setBlock(world, i + 15, j + 13, k + 29, KCore.ForbiddenBrick, 0);
		this.setBlock(world, i + 15, j + 13, k + 30, KCore.ForbiddenBrick, 0);
		this.setBlock(world, i + 15, j + 13, k + 31, KCore.ForbiddenBrick, 0);
		this.setBlock(world, i + 15, j + 13, k + 32, KCore.ForbiddenBrick, 0);
		this.setBlock(world, i + 15, j + 13, k + 33, KCore.ForbiddenBrick, 0);
		this.setBlock(world, i + 15, j + 13, k + 34, KCore.ForbiddenBrick, 0);
		this.setBlock(world, i + 15, j + 13, k + 35, KCore.ForbiddenBrick, 0);
		this.setBlock(world, i + 15, j + 13, k + 36, KCore.ForbiddenBrick, 0);
		this.setBlock(world, i + 15, j + 13, k + 37, KCore.ForbiddenBrick, 0);
		this.setBlock(world, i + 15, j + 13, k + 38, KCore.ForbiddenBrick, 0);
		this.setBlock(world, i + 15, j + 14, k + 3, KCore.ForbiddenBrick, 0);
		this.setBlock(world, i + 15, j + 14, k + 4, KCore.ForbiddenBrick, 0);
		this.setBlock(world, i + 15, j + 14, k + 7, KCore.ForbiddenBrick, 0);
		this.setBlock(world, i + 15, j + 14, k + 15, KCore.ForbiddenBrick, 0);
		this.setBlock(world, i + 15, j + 14, k + 16, KCore.ForbiddenBrick, 0);
		this.setBlock(world, i + 15, j + 14, k + 17, KCore.ForbiddenBrick, 0);
		this.setBlock(world, i + 15, j + 14, k + 18, KCore.ForbiddenBrick, 0);
		this.setBlock(world, i + 15, j + 14, k + 19, KCore.ForbiddenBrick, 0);
		this.setBlock(world, i + 15, j + 14, k + 20, KCore.ForbiddenBrick, 0);
		this.setBlock(world, i + 15, j + 14, k + 21, KCore.ForbiddenBrick, 0);
		this.setBlock(world, i + 15, j + 14, k + 22, KCore.ForbiddenBrick, 0);
		this.setBlock(world, i + 15, j + 14, k + 23, KCore.ForbiddenBrick, 0);
		this.setBlock(world, i + 15, j + 14, k + 24, KCore.ForbiddenBrick, 0);
		this.setBlock(world, i + 15, j + 14, k + 25, KCore.ForbiddenBrick, 0);
		this.setBlock(world, i + 15, j + 14, k + 26, KCore.ForbiddenBrick, 0);
		this.setBlock(world, i + 15, j + 14, k + 27, KCore.ForbiddenBrick, 0);
		this.setBlock(world, i + 15, j + 14, k + 28, KCore.ForbiddenBrick, 0);
		this.setBlock(world, i + 15, j + 14, k + 29, KCore.ForbiddenBrick, 0);
		this.setBlock(world, i + 15, j + 14, k + 30, KCore.ForbiddenBrick, 0);
		this.setBlock(world, i + 15, j + 14, k + 31, KCore.ForbiddenBrick, 0);
		this.setBlock(world, i + 15, j + 14, k + 32, KCore.ForbiddenBrick, 0);
		this.setBlock(world, i + 15, j + 14, k + 33, KCore.ForbiddenBrick, 0);
		this.setBlock(world, i + 15, j + 14, k + 34, KCore.ForbiddenBrick, 0);
		this.setBlock(world, i + 15, j + 14, k + 35, KCore.ForbiddenBrick, 0);
		this.setBlock(world, i + 15, j + 14, k + 36, KCore.ForbiddenBrick, 0);
		this.setBlock(world, i + 15, j + 14, k + 37, KCore.ForbiddenBrick, 0);
		this.setBlock(world, i + 15, j + 14, k + 38, KCore.ForbiddenBrick, 0);
		this.setBlock(world, i + 15, j + 15, k + 3, KCore.ForbiddenBrick, 0);
		this.setBlock(world, i + 15, j + 15, k + 4, KCore.ForbiddenBrick, 0);
		this.setBlock(world, i + 15, j + 15, k + 7, KCore.ForbiddenBrick, 0);
		this.setBlock(world, i + 15, j + 15, k + 15, KCore.ForbiddenBrick, 0);
		this.setBlock(world, i + 15, j + 15, k + 36, KCore.ForbiddenBrick, 0);
		this.setBlock(world, i + 15, j + 15, k + 37, KCore.ForbiddenBrick, 0);
		this.setBlock(world, i + 15, j + 15, k + 38, KCore.ForbiddenBrick, 0);
		this.setBlock(world, i + 15, j + 16, k + 3, KCore.ForbiddenBrick, 0);
		this.setBlock(world, i + 15, j + 16, k + 4, KCore.ForbiddenBrick, 0);
		this.setBlock(world, i + 15, j + 16, k + 7, KCore.ForbiddenBrick, 0);
		this.setBlock(world, i + 15, j + 16, k + 15, KCore.ForbiddenBrick, 0);
		this.setBlock(world, i + 15, j + 16, k + 36, KCore.ForbiddenBrick, 0);
		this.setBlock(world, i + 15, j + 16, k + 37, KCore.ForbiddenBrick, 0);
		this.setBlock(world, i + 15, j + 16, k + 38, KCore.ForbiddenBrick, 0);
		this.setBlock(world, i + 15, j + 17, k + 3, KCore.ForbiddenBrick, 0);
		this.setBlock(world, i + 15, j + 17, k + 4, KCore.ForbiddenBrick, 0);
		this.setBlock(world, i + 15, j + 17, k + 5, KCore.ForbiddenBrick, 0);
		this.setBlock(world, i + 15, j + 17, k + 6, KCore.ForbiddenBrick, 0);
		this.setBlock(world, i + 15, j + 17, k + 7, KCore.ForbiddenBrick, 0);
		this.setBlock(world, i + 15, j + 17, k + 15, KCore.ForbiddenBrick, 0);
		this.setBlock(world, i + 15, j + 17, k + 36, KCore.ForbiddenBrick, 0);
		this.setBlock(world, i + 15, j + 17, k + 37, KCore.ForbiddenBrick, 0);
		this.setBlock(world, i + 15, j + 17, k + 38, KCore.ForbiddenBrick, 0);
		this.setBlock(world, i + 15, j + 18, k + 3, KCore.ForbiddenBrick, 0);
		this.setBlock(world, i + 15, j + 18, k + 5, KCore.ForbiddenBrick, 0);
		this.setBlock(world, i + 15, j + 18, k + 6, KCore.ForbiddenBrick, 0);
		this.setBlock(world, i + 15, j + 18, k + 15, KCore.ForbiddenBrick, 0);
		this.setBlock(world, i + 15, j + 18, k + 36, KCore.ForbiddenBrick, 0);
		this.setBlock(world, i + 15, j + 18, k + 37, KCore.ForbiddenBrick, 0);
		this.setBlock(world, i + 15, j + 18, k + 38, KCore.ForbiddenBrick, 0);
		this.setBlock(world, i + 15, j + 19, k + 3, KCore.ForbiddenBrick, 0);
		this.setBlock(world, i + 15, j + 19, k + 15, KCore.ForbiddenBrick, 0);
		this.setBlock(world, i + 15, j + 19, k + 36, KCore.ForbiddenBrick, 0);
		this.setBlock(world, i + 15, j + 19, k + 37, KCore.ForbiddenBrick, 0);
		this.setBlock(world, i + 15, j + 19, k + 38, KCore.ForbiddenBrick, 0);
		this.setBlock(world, i + 15, j + 20, k + 3, KCore.ForbiddenBrick, 0);
		this.setBlock(world, i + 15, j + 20, k + 15, KCore.ForbiddenBrick, 0);
		this.setBlock(world, i + 15, j + 20, k + 36, KCore.ForbiddenBrick, 0);
		this.setBlock(world, i + 15, j + 20, k + 37, KCore.ForbiddenBrick, 0);
		this.setBlock(world, i + 15, j + 20, k + 38, KCore.ForbiddenBrick, 0);
		this.setBlock(world, i + 15, j + 21, k + 3, KCore.ForbiddenBrick, 0);
		this.setBlock(world, i + 15, j + 21, k + 4, KCore.ForbiddenBrick, 0);
		this.setBlock(world, i + 15, j + 21, k + 5, KCore.ForbiddenBrick, 0);
		this.setBlock(world, i + 15, j + 21, k + 6, KCore.ForbiddenBrick, 0);
		this.setBlock(world, i + 15, j + 21, k + 7, KCore.ForbiddenBrick, 0);
		this.setBlock(world, i + 15, j + 21, k + 8, KCore.ForbiddenBrick, 0);
		this.setBlock(world, i + 15, j + 21, k + 9, KCore.ForbiddenBrick, 0);
		this.setBlock(world, i + 15, j + 21, k + 10, KCore.ForbiddenBrick, 0);
		this.setBlock(world, i + 15, j + 21, k + 11, KCore.ForbiddenBrick, 0);
		this.setBlock(world, i + 15, j + 21, k + 12, KCore.ForbiddenBrick, 0);
		this.setBlock(world, i + 15, j + 21, k + 13, KCore.ForbiddenBrick, 0);
		this.setBlock(world, i + 15, j + 21, k + 14, KCore.ForbiddenBrick, 0);
		this.setBlock(world, i + 15, j + 21, k + 15, KCore.ForbiddenBrick, 0);
		this.setBlock(world, i + 15, j + 21, k + 16, KCore.ForbiddenBrick, 0);
		this.setBlock(world, i + 15, j + 21, k + 17, KCore.ForbiddenBrick, 0);
		this.setBlock(world, i + 15, j + 21, k + 18, KCore.ForbiddenBrick, 0);
		this.setBlock(world, i + 15, j + 21, k + 19, KCore.ForbiddenBrick, 0);
		this.setBlock(world, i + 15, j + 21, k + 20, KCore.ForbiddenBrick, 0);
		this.setBlock(world, i + 15, j + 21, k + 21, KCore.ForbiddenBrick, 0);
		this.setBlock(world, i + 15, j + 21, k + 22, KCore.ForbiddenBrick, 0);
		this.setBlock(world, i + 15, j + 21, k + 23, KCore.ForbiddenBrick, 0);
		this.setBlock(world, i + 15, j + 21, k + 24, KCore.ForbiddenBrick, 0);
		this.setBlock(world, i + 15, j + 21, k + 25, KCore.ForbiddenBrick, 0);
		this.setBlock(world, i + 15, j + 21, k + 26, KCore.ForbiddenBrick, 0);
		this.setBlock(world, i + 15, j + 21, k + 27, KCore.ForbiddenBrick, 0);
		this.setBlock(world, i + 15, j + 21, k + 28, KCore.ForbiddenBrick, 0);
		this.setBlock(world, i + 15, j + 21, k + 29, KCore.ForbiddenBrick, 0);
		this.setBlock(world, i + 15, j + 21, k + 30, KCore.ForbiddenBrick, 0);
		this.setBlock(world, i + 15, j + 21, k + 31, KCore.ForbiddenBrick, 0);
		this.setBlock(world, i + 15, j + 21, k + 32, KCore.ForbiddenBrick, 0);
		this.setBlock(world, i + 15, j + 21, k + 33, KCore.ForbiddenBrick, 0);
		this.setBlock(world, i + 15, j + 21, k + 34, KCore.ForbiddenBrick, 0);
		this.setBlock(world, i + 15, j + 21, k + 35, KCore.ForbiddenBrick, 0);
		this.setBlock(world, i + 15, j + 21, k + 36, KCore.ForbiddenBrick, 0);
		this.setBlock(world, i + 15, j + 21, k + 37, KCore.ForbiddenBrick, 0);
		this.setBlock(world, i + 15, j + 21, k + 38, KCore.ForbiddenBrick, 0);
		this.setBlock(world, i + 16, j + 0, k + 0, KCore.ForbiddenRockStairs, 0);
		this.setBlock(world, i + 16, j + 0, k + 1, KCore.ForbiddenRock, 0);
		this.setBlock(world, i + 16, j + 0, k + 2, KCore.ForbiddenRock, 0);
		this.setBlock(world, i + 16, j + 0, k + 3, KCore.ForbiddenRock, 0);
		this.setBlock(world, i + 16, j + 0, k + 4, KCore.ForbiddenRock, 0);
		this.setBlock(world, i + 16, j + 0, k + 5, KCore.ForbiddenRock, 0);
		this.setBlock(world, i + 16, j + 0, k + 6, KCore.ForbiddenRock, 0);
		this.setBlock(world, i + 16, j + 0, k + 7, KCore.ForbiddenRock, 0);
		this.setBlock(world, i + 16, j + 0, k + 8, KCore.ForbiddenRock, 0);
		this.setBlock(world, i + 16, j + 0, k + 9, KCore.ForbiddenRock, 0);
		this.setBlock(world, i + 16, j + 0, k + 10, KCore.ForbiddenRock, 0);
		this.setBlock(world, i + 16, j + 0, k + 11, KCore.ForbiddenRock, 0);
		this.setBlock(world, i + 16, j + 0, k + 12, KCore.ForbiddenRock, 0);
		this.setBlock(world, i + 16, j + 0, k + 13, KCore.ForbiddenRock, 0);
		this.setBlock(world, i + 16, j + 0, k + 14, KCore.ForbiddenRock, 0);
		this.setBlock(world, i + 16, j + 0, k + 15, KCore.ForbiddenRock, 0);
		this.setBlock(world, i + 16, j + 0, k + 16, KCore.ForbiddenRock, 0);
		this.setBlock(world, i + 16, j + 0, k + 17, KCore.ForbiddenRock, 0);
		this.setBlock(world, i + 16, j + 0, k + 18, KCore.ForbiddenRock, 0);
		this.setBlock(world, i + 16, j + 0, k + 19, KCore.ForbiddenRock, 0);
		this.setBlock(world, i + 16, j + 0, k + 20, KCore.ForbiddenRock, 0);
		this.setBlock(world, i + 16, j + 0, k + 21, KCore.ForbiddenRock, 0);
		this.setBlock(world, i + 16, j + 0, k + 22, KCore.ForbiddenRock, 0);
		this.setBlock(world, i + 16, j + 0, k + 23, KCore.ForbiddenRock, 0);
		this.setBlock(world, i + 16, j + 0, k + 24, KCore.ForbiddenRock, 0);
		this.setBlock(world, i + 16, j + 0, k + 25, KCore.ForbiddenRock, 0);
		this.setBlock(world, i + 16, j + 0, k + 26, KCore.ForbiddenRock, 0);
		this.setBlock(world, i + 16, j + 0, k + 27, KCore.ForbiddenRock, 0);
		this.setBlock(world, i + 16, j + 0, k + 28, KCore.ForbiddenRock, 0);
		this.setBlock(world, i + 16, j + 0, k + 29, KCore.ForbiddenRock, 0);
		this.setBlock(world, i + 16, j + 0, k + 30, KCore.ForbiddenRock, 0);
		this.setBlock(world, i + 16, j + 0, k + 31, KCore.ForbiddenRock, 0);
		this.setBlock(world, i + 16, j + 0, k + 32, KCore.ForbiddenRock, 0);
		this.setBlock(world, i + 16, j + 0, k + 33, KCore.ForbiddenRock, 0);
		this.setBlock(world, i + 16, j + 0, k + 34, KCore.ForbiddenRock, 0);
		this.setBlock(world, i + 16, j + 0, k + 35, KCore.ForbiddenRock, 0);
		this.setBlock(world, i + 16, j + 0, k + 36, KCore.ForbiddenRock, 0);
		this.setBlock(world, i + 16, j + 0, k + 37, KCore.ForbiddenRock, 0);
		this.setBlock(world, i + 16, j + 0, k + 38, KCore.ForbiddenRock, 0);
		this.setBlock(world, i + 16, j + 1, k + 1, KCore.ForbiddenRockStairs, 0);
		this.setBlock(world, i + 16, j + 1, k + 2, KCore.ForbiddenRock, 0);
		this.setBlock(world, i + 16, j + 1, k + 3, KCore.ForbiddenRock, 0);
		this.setBlock(world, i + 16, j + 1, k + 4, KCore.ForbiddenRock, 0);
		this.setBlock(world, i + 16, j + 1, k + 5, KCore.ForbiddenRock, 0);
		this.setBlock(world, i + 16, j + 1, k + 6, KCore.ForbiddenRock, 0);
		this.setBlock(world, i + 16, j + 1, k + 7, KCore.ForbiddenRock, 0);
		this.setBlock(world, i + 16, j + 1, k + 8, KCore.ForbiddenRock, 0);
		this.setBlock(world, i + 16, j + 1, k + 9, KCore.ForbiddenRock, 0);
		this.setBlock(world, i + 16, j + 1, k + 10, KCore.ForbiddenRock, 0);
		this.setBlock(world, i + 16, j + 1, k + 11, KCore.ForbiddenRock, 0);
		this.setBlock(world, i + 16, j + 1, k + 12, KCore.ForbiddenRock, 0);
		this.setBlock(world, i + 16, j + 1, k + 13, KCore.ForbiddenRock, 0);
		this.setBlock(world, i + 16, j + 1, k + 14, KCore.ForbiddenRock, 0);
		this.setBlock(world, i + 16, j + 1, k + 15, KCore.ForbiddenRock, 0);
		this.setBlock(world, i + 16, j + 1, k + 16, KCore.ForbiddenRock, 0);
		this.setBlock(world, i + 16, j + 1, k + 17, KCore.ForbiddenRock, 0);
		this.setBlock(world, i + 16, j + 1, k + 18, KCore.ForbiddenRock, 0);
		this.setBlock(world, i + 16, j + 1, k + 19, KCore.ForbiddenRock, 0);
		this.setBlock(world, i + 16, j + 1, k + 20, KCore.ForbiddenRock, 0);
		this.setBlock(world, i + 16, j + 1, k + 21, KCore.ForbiddenRock, 0);
		this.setBlock(world, i + 16, j + 1, k + 22, KCore.ForbiddenRock, 0);
		this.setBlock(world, i + 16, j + 1, k + 23, KCore.ForbiddenRock, 0);
		this.setBlock(world, i + 16, j + 1, k + 24, KCore.ForbiddenRock, 0);
		this.setBlock(world, i + 16, j + 1, k + 25, KCore.ForbiddenRock, 0);
		this.setBlock(world, i + 16, j + 1, k + 26, KCore.ForbiddenRock, 0);
		this.setBlock(world, i + 16, j + 1, k + 27, KCore.ForbiddenRock, 0);
		this.setBlock(world, i + 16, j + 1, k + 28, KCore.ForbiddenRock, 0);
		this.setBlock(world, i + 16, j + 1, k + 29, KCore.ForbiddenRock, 0);
		this.setBlock(world, i + 16, j + 1, k + 30, KCore.ForbiddenRock, 0);
		this.setBlock(world, i + 16, j + 1, k + 31, KCore.ForbiddenRock, 0);
		this.setBlock(world, i + 16, j + 1, k + 32, KCore.ForbiddenRock, 0);
		this.setBlock(world, i + 16, j + 1, k + 33, KCore.ForbiddenRock, 0);
		this.setBlock(world, i + 16, j + 1, k + 34, KCore.ForbiddenRock, 0);
		this.setBlock(world, i + 16, j + 1, k + 35, KCore.ForbiddenRock, 0);
		this.setBlock(world, i + 16, j + 1, k + 36, KCore.ForbiddenRock, 0);
		this.setBlock(world, i + 16, j + 1, k + 37, KCore.ForbiddenRock, 0);
		this.setBlock(world, i + 16, j + 1, k + 38, KCore.ForbiddenRock, 0);
		this.setBlock(world, i + 16, j + 2, k + 2, KCore.ForbiddenRockStairs, 0);
		this.setBlock(world, i + 16, j + 2, k + 3, KCore.ForbiddenBrick, 0);
		this.setBlock(world, i + 16, j + 2, k + 4, KCore.ForbiddenRock, 0);
		this.setBlock(world, i + 16, j + 2, k + 5, KCore.ForbiddenRock, 0);
		this.setBlock(world, i + 16, j + 2, k + 6, KCore.ForbiddenRock, 0);
		this.setBlock(world, i + 16, j + 2, k + 7, KCore.ForbiddenRock, 0);
		this.setBlock(world, i + 16, j + 2, k + 8, KCore.ForbiddenRock, 0);
		this.setBlock(world, i + 16, j + 2, k + 9, KCore.ForbiddenRock, 0);
		this.setBlock(world, i + 16, j + 2, k + 10, KCore.ForbiddenLightBrick, 0);
		this.setBlock(world, i + 16, j + 2, k + 11, KCore.ForbiddenRock, 0);
		this.setBlock(world, i + 16, j + 2, k + 12, KCore.ForbiddenTrap, 0);
		this.setBlock(world, i + 16, j + 2, k + 13, KCore.ForbiddenRock, 0);
		this.setBlock(world, i + 16, j + 2, k + 14, KCore.ForbiddenRock, 0);
		this.setBlock(world, i + 16, j + 2, k + 15, KCore.ForbiddenRock, 0);
		this.setBlock(world, i + 16, j + 2, k + 16, KCore.ForbiddenRock, 0);
		this.setBlock(world, i + 16, j + 2, k + 17, KCore.ForbiddenRock, 0);
		this.setBlock(world, i + 16, j + 2, k + 18, KCore.ForbiddenRock, 0);
		this.setBlock(world, i + 16, j + 2, k + 19, KCore.ForbiddenRock, 0);
		this.setBlock(world, i + 16, j + 2, k + 20, KCore.ForbiddenTrap, 0);
		this.setBlock(world, i + 16, j + 2, k + 21, KCore.ForbiddenRock, 0);
		this.setBlock(world, i + 16, j + 2, k + 22, KCore.ForbiddenTrap, 0);
		this.setBlock(world, i + 16, j + 2, k + 23, KCore.ForbiddenRock, 0);
		this.setBlock(world, i + 16, j + 2, k + 24, KCore.ForbiddenTrap, 0);
		this.setBlock(world, i + 16, j + 2, k + 25, KCore.ForbiddenRock, 0);
		this.setBlock(world, i + 16, j + 2, k + 26, KCore.ForbiddenRock, 0);
		this.setBlock(world, i + 16, j + 2, k + 27, KCore.ForbiddenRock, 0);
		this.setBlock(world, i + 16, j + 2, k + 28, KCore.ForbiddenRock, 0);
		this.setBlock(world, i + 16, j + 2, k + 29, KCore.ForbiddenRock, 0);
		this.setBlock(world, i + 16, j + 2, k + 30, KCore.ForbiddenRock, 0);
		this.setBlock(world, i + 16, j + 2, k + 31, KCore.ForbiddenRock, 0);
		this.setBlock(world, i + 16, j + 2, k + 32, KCore.ForbiddenRock, 0);
		this.setBlock(world, i + 16, j + 2, k + 33, KCore.ForbiddenRock, 0);
		this.setBlock(world, i + 16, j + 2, k + 34, KCore.ForbiddenRock, 0);
		this.setBlock(world, i + 16, j + 2, k + 35, KCore.ForbiddenRock, 0);
		this.setBlock(world, i + 16, j + 2, k + 36, KCore.ForbiddenRock, 0);
		this.setBlock(world, i + 16, j + 2, k + 37, KCore.ForbiddenRock, 0);
		this.setBlock(world, i + 16, j + 2, k + 38, KCore.ForbiddenRock, 0);
		this.setBlock(world, i + 16, j + 3, k + 15, KCore.ForbiddenBrick, 0);
		this.setBlock(world, i + 16, j + 3, k + 16, KCore.ForbiddenBrick, 0);
		this.setBlock(world, i + 16, j + 3, k + 17, KCore.ForbiddenBrick, 0);
		this.setBlock(world, i + 16, j + 3, k + 27, KCore.ForbiddenBrick, 0);
		this.setBlock(world, i + 16, j + 3, k + 28, KCore.ForbiddenBrick, 0);
		this.setBlock(world, i + 16, j + 3, k + 29, KCore.ForbiddenBrick, 0);
		this.setBlock(world, i + 16, j + 3, k + 30, KCore.ForbiddenBrick, 0);
		this.setBlock(world, i + 16, j + 3, k + 31, KCore.ForbiddenBrick, 0);
		this.setBlock(world, i + 16, j + 3, k + 32, KCore.ForbiddenBrick, 0);
		this.setBlock(world, i + 16, j + 3, k + 33, KCore.ForbiddenBrick, 0);
		this.setBlock(world, i + 16, j + 3, k + 34, KCore.ForbiddenBrick, 0);
		this.setBlock(world, i + 16, j + 3, k + 35, KCore.ForbiddenBrick, 0);
		this.setBlock(world, i + 16, j + 3, k + 36, KCore.ForbiddenBrick, 0);
		this.setBlock(world, i + 16, j + 3, k + 37, KCore.ForbiddenBrick, 0);
		this.setBlock(world, i + 16, j + 3, k + 38, KCore.ForbiddenBrick, 0);
		this.setBlock(world, i + 16, j + 4, k + 15, KCore.ForbiddenBrick, 0);
		this.setBlock(world, i + 16, j + 4, k + 16, KCore.ForbiddenBrick, 0);
		this.setBlock(world, i + 16, j + 4, k + 17, KCore.ForbiddenBrick, 0);
		this.setBlock(world, i + 16, j + 4, k + 27, KCore.ForbiddenBrick, 0);
		this.setBlock(world, i + 16, j + 4, k + 28, KCore.ForbiddenBrick, 0);
		this.setBlock(world, i + 16, j + 4, k + 29, KCore.ForbiddenBrick, 0);
		this.setBlock(world, i + 16, j + 4, k + 30, KCore.ForbiddenBrick, 0);
		this.setBlock(world, i + 16, j + 4, k + 31, KCore.ForbiddenBrick, 0);
		this.setBlock(world, i + 16, j + 4, k + 32, KCore.ForbiddenBrick, 0);
		this.setBlock(world, i + 16, j + 4, k + 33, KCore.ForbiddenBrick, 0);
		this.setBlock(world, i + 16, j + 4, k + 34, KCore.ForbiddenBrick, 0);
		this.setBlock(world, i + 16, j + 4, k + 35, KCore.ForbiddenBrick, 0);
		this.setBlock(world, i + 16, j + 4, k + 36, KCore.ForbiddenBrick, 0);
		this.setBlock(world, i + 16, j + 4, k + 37, KCore.ForbiddenBrick, 0);
		this.setBlock(world, i + 16, j + 4, k + 38, KCore.ForbiddenBrick, 0);
		this.setBlock(world, i + 16, j + 5, k + 15, KCore.ForbiddenBrick, 0);
		this.setBlock(world, i + 16, j + 5, k + 16, KCore.ForbiddenBrick, 0);
		this.setBlock(world, i + 16, j + 5, k + 17, KCore.ForbiddenBrick, 0);
		this.setBlock(world, i + 16, j + 5, k + 27, KCore.ForbiddenBrick, 0);
		this.setBlock(world, i + 16, j + 5, k + 28, KCore.ForbiddenBrick, 0);
		this.setBlock(world, i + 16, j + 5, k + 29, KCore.ForbiddenBrick, 0);
		this.setBlock(world, i + 16, j + 5, k + 30, KCore.ForbiddenBrick, 0);
		this.setBlock(world, i + 16, j + 5, k + 31, KCore.ForbiddenBrick, 0);
		this.setBlock(world, i + 16, j + 5, k + 32, KCore.ForbiddenBrick, 0);
		this.setBlock(world, i + 16, j + 5, k + 33, KCore.ForbiddenBrick, 0);
		this.setBlock(world, i + 16, j + 5, k + 34, KCore.ForbiddenBrick, 0);
		this.setBlock(world, i + 16, j + 5, k + 35, KCore.ForbiddenBrick, 0);
		this.setBlock(world, i + 16, j + 5, k + 36, KCore.ForbiddenBrick, 0);
		this.setBlock(world, i + 16, j + 5, k + 37, KCore.ForbiddenBrick, 0);
		this.setBlock(world, i + 16, j + 5, k + 38, KCore.ForbiddenBrick, 0);
		this.setBlock(world, i + 16, j + 6, k + 3, KCore.ForbiddenLightBrick, 0);
		this.setBlock(world, i + 16, j + 6, k + 4, KCore.ForbiddenBrick, 0);
		this.setBlock(world, i + 16, j + 6, k + 5, KCore.ForbiddenBrick, 0);
		this.setBlock(world, i + 16, j + 6, k + 6, KCore.ForbiddenBrick, 0);
		this.setBlock(world, i + 16, j + 6, k + 7, KCore.ForbiddenBrick, 0);
		this.setBlock(world, i + 16, j + 6, k + 8, KCore.ForbiddenBrick, 0);
		this.setBlock(world, i + 16, j + 6, k + 9, KCore.ForbiddenBrick, 0);
		this.setBlock(world, i + 16, j + 6, k + 10, KCore.ForbiddenBrick, 0);
		this.setBlock(world, i + 16, j + 6, k + 11, KCore.ForbiddenBrick, 0);
		this.setBlock(world, i + 16, j + 6, k + 12, KCore.ForbiddenBrick, 0);
		this.setBlock(world, i + 16, j + 6, k + 13, KCore.ForbiddenBrick, 0);
		this.setBlock(world, i + 16, j + 6, k + 14, KCore.ForbiddenBrick, 0);
		this.setBlock(world, i + 16, j + 6, k + 15, KCore.ForbiddenBrick, 0);
		this.setBlock(world, i + 16, j + 6, k + 16, KCore.ForbiddenBrick, 0);
		this.setBlock(world, i + 16, j + 6, k + 17, KCore.ForbiddenBrick, 0);
		this.setBlock(world, i + 16, j + 6, k + 27, KCore.ForbiddenBrick, 0);
		this.setBlock(world, i + 16, j + 6, k + 28, KCore.ForbiddenBrick, 0);
		this.setBlock(world, i + 16, j + 6, k + 29, KCore.ForbiddenBrick, 0);
		this.setBlock(world, i + 16, j + 6, k + 30, KCore.ForbiddenBrick, 0);
		this.setBlock(world, i + 16, j + 6, k + 31, KCore.ForbiddenBrick, 0);
		this.setBlock(world, i + 16, j + 6, k + 32, KCore.ForbiddenBrick, 0);
		this.setBlock(world, i + 16, j + 6, k + 33, KCore.ForbiddenBrick, 0);
